Workbook

Sheet Executive Dashboard
A1: EXECUTIVE BUSINESS CASE DASHBOARD — FWA 5G n50 (1,000 Sites in Year 1)
A2: Strategic Decision Framework: 1,000 Sites Day-1 Rollout · 1,000,000 Capacity · Leased vs Owned · FOC vs Starlink · Deferred vs Non-Deferred
A4: RECOMMENDED OPTIMIZED SCENARIO (Scenario 4: Leased + Starlink + Deferred)
A5: 10-Year Project NPV (@12%) | C5: 10-Year Project IRR | E5: Simple Payback Period | G5: Peak Funding Requirement | I5: 10-Year EBITDA Margin | K5: Return on Capital (ROI)
A6: ='Master Comparison (8 Scenarios)'!L8 | C6: ='Master Comparison (8 Scenarios)'!M8 | E6: ='Master Comparison (8 Scenarios)'!N8 | G6: ='Master Comparison (8 Scenarios)'!K8 | I6: ='Master Comparison (8 Scenarios)'!I8 | K6: ='Master Comparison (8 Scenarios)'!O8
A7: Net Economic Value Created | C7: Unlevered Rate of Return | E7: Capital Recovery Timeline | G7: Maximum Cash Drawdown | I7: Operational Profitability | K7: Cash Multiple on Peak Invested
A9: EXECUTIVE SUMMARY: ALL 8 SCENARIOS AT A GLANCE (1,000 SITES IN YEAR 1)
A10: ID | B10: Scenario Description | C10: Tower Model | D10: Backhaul | E10: Payment Terms | F10: 10-Yr NPV ($M) | G10: IRR (%) | H10: Payback (Yrs) | I10: Peak Funding ($M) | J10: 10-Yr FCF ($M) | K10: Decision Verdict
A11: ='Master Comparison (8 Scenarios)'!A5 | C11: ='Master Comparison (8 Scenarios)'!B5 | D11: ='Master Comparison (8 Scenarios)'!C5 | E11: ='Master Comparison (8 Scenarios)'!D5 | F11: ='Master Comparison (8 Scenarios)'!L5 | G11: ='Master Comparison (8 Scenarios)'!M5 | H11: ='Master Comparison (8 Scenarios)'!N5 | I11: ='Master Comparison (8 Scenarios)'!K5 | J11: ='Master Comparison (8 Scenarios)'!J5 | K11: ='Master Comparison (8 Scenarios)'!P5
A12: ='Master Comparison (8 Scenarios)'!A6 | C12: ='Master Comparison (8 Scenarios)'!B6 | D12: ='Master Comparison (8 Scenarios)'!C6 | E12: ='Master Comparison (8 Scenarios)'!D6 | F12: ='Master Comparison (8 Scenarios)'!L6 | G12: ='Master Comparison (8 Scenarios)'!M6 | H12: ='Master Comparison (8 Scenarios)'!N6 | I12: ='Master Comparison (8 Scenarios)'!K6 | J12: ='Master Comparison (8 Scenarios)'!J6 | K12: ='Master Comparison (8 Scenarios)'!P6
A13: ='Master Comparison (8 Scenarios)'!A7 | C13: ='Master Comparison (8 Scenarios)'!B7 | D13: ='Master Comparison (8 Scenarios)'!C7 | E13: ='Master Comparison (8 Scenarios)'!D7 | F13: ='Master Comparison (8 Scenarios)'!L7 | G13: ='Master Comparison (8 Scenarios)'!M7 | H13: ='Master Comparison (8 Scenarios)'!N7 | I13: ='Master Comparison (8 Scenarios)'!K7 | J13: ='Master Comparison (8 Scenarios)'!J7 | K13: ='Master Comparison (8 Scenarios)'!P7
A14: ='Master Comparison (8 Scenarios)'!A8 | C14: ='Master Comparison (8 Scenarios)'!B8 | D14: ='Master Comparison (8 Scenarios)'!C8 | E14: ='Master Comparison (8 Scenarios)'!D8 | F14: ='Master Comparison (8 Scenarios)'!L8 | G14: ='Master Comparison (8 Scenarios)'!M8 | H14: ='Master Comparison (8 Scenarios)'!N8 | I14: ='Master Comparison (8 Scenarios)'!K8 | J14: ='Master Comparison (8 Scenarios)'!J8 | K14: ='Master Comparison (8 Scenarios)'!P8
A15: ='Master Comparison (8 Scenarios)'!A9 | C15: ='Master Comparison (8 Scenarios)'!B9 | D15: ='Master Comparison (8 Scenarios)'!C9 | E15: ='Master Comparison (8 Scenarios)'!D9 | F15: ='Master Comparison (8 Scenarios)'!L9 | G15: ='Master Comparison (8 Scenarios)'!M9 | H15: ='Master Comparison (8 Scenarios)'!N9 | I15: ='Master Comparison (8 Scenarios)'!K9 | J15: ='Master Comparison (8 Scenarios)'!J9 | K15: ='Master Comparison (8 Scenarios)'!P9
A16: ='Master Comparison (8 Scenarios)'!A10 | C16: ='Master Comparison (8 Scenarios)'!B10 | D16: ='Master Comparison (8 Scenarios)'!C10 | E16: ='Master Comparison (8 Scenarios)'!D10 | F16: ='Master Comparison (8 Scenarios)'!L10 | G16: ='Master Comparison (8 Scenarios)'!M10 | H16: ='Master Comparison (8 Scenarios)'!N10 | I16: ='Master Comparison (8 Scenarios)'!K10 | J16: ='Master Comparison (8 Scenarios)'!J10 | K16: ='Master Comparison (8 Scenarios)'!P10
A17: ='Master Comparison (8 Scenarios)'!A11 | C17: ='Master Comparison (8 Scenarios)'!B11 | D17: ='Master Comparison (8 Scenarios)'!C11 | E17: ='Master Comparison (8 Scenarios)'!D11 | F17: ='Master Comparison (8 Scenarios)'!L11 | G17: ='Master Comparison (8 Scenarios)'!M11 | H17: ='Master Comparison (8 Scenarios)'!N11 | I17: ='Master Comparison (8 Scenarios)'!K11 | J17: ='Master Comparison (8 Scenarios)'!J11 | K17: ='Master Comparison (8 Scenarios)'!P11
A18: ='Master Comparison (8 Scenarios)'!A12 | C18: ='Master Comparison (8 Scenarios)'!B12 | D18: ='Master Comparison (8 Scenarios)'!C12 | E18: ='Master Comparison (8 Scenarios)'!D12 | F18: ='Master Comparison (8 Scenarios)'!L12 | G18: ='Master Comparison (8 Scenarios)'!M12 | H18: ='Master Comparison (8 Scenarios)'!N12 | I18: ='Master Comparison (8 Scenarios)'!K12 | J18: ='Master Comparison (8 Scenarios)'!J12 | K18: ='Master Comparison (8 Scenarios)'!P12

Sheet Table 3 - 8-Scenario Matrix
A1: FWA 5G n50 (80 MHz) — Table 3: 8-Scenario Financial Matrix (10,000 Sites at Maturity)
A2: Full 10-Year Lifecycle Comparison across Tower Model, Backhaul Technology, and Equipment/SUF Payment Terms (1,000 Sites Y1 + 1,000 Sites/Yr Y2-Y10)
A4: Total Network Footprint | D4: Total Network Capacity | G4: Spectrum User Fee (SUF) | J4: Incremental IT CAPEX | M4: Recommended Strategy
A5: 10,000 Sites | D5: 10,000,000 Subs | G5: ₱400M / year | J5: $14,000 / site | M5: Scenario 4 (S4)
A6: 1,000 Y1 + 1,000/yr Y2-10 | D6: 1,000 subs/site design capacity | G6: $7,272,727 USD/yr unphased | J6: $8k Core + $6k BSS; 15% AMC | M6: Leased + Starlink + Deferred
A8: Scenario ID | B8: Tower Infrastructure | C8: Backhaul Technology | D8: Payment Terms | E8: 10-Yr Total Revenue ($M) | F8: 10-Yr Total OPEX ($M) | G8: 10-Yr Total CAPEX ($M) | H8: 10-Yr EBITDA ($M) | I8: EBITDA Margin (%) | J8: 10-Yr Free Cash Flow ($M) | K8: Peak Funding Deficit ($M) | L8: 10-Yr NPV @ 12% ($M) | M8: 10-Yr Project IRR (%) | N8: Simple Payback (Yrs) | O8: ROI (Cash / Peak) | P8: Decision Verdict
A9: S1 | B9: Leased Towers | C9: FOC Backhaul | D9: Non-Deferred | E9: ='Master Comparison (8 Scenarios)'!E5 | F9: ='Master Comparison (8 Scenarios)'!F5 | G9: ='Master Comparison (8 Scenarios)'!G5 | H9: ='Master Comparison (8 Scenarios)'!H5 | I9: ='Master Comparison (8 Scenarios)'!I5 | J9: ='Master Comparison (8 Scenarios)'!J5 | K9: ='Master Comparison (8 Scenarios)'!K5 | L9: ='Master Comparison (8 Scenarios)'!L5 | ... P9: ='Master Comparison (8 Scenarios)'!P5
A10: S2 | B10: Leased Towers | C10: FOC Backhaul | D10: Deferred | E10: ='Master Comparison (8 Scenarios)'!E6 | F10: ='Master Comparison (8 Scenarios)'!F6 | G10: ='Master Comparison (8 Scenarios)'!G6 | H10: ='Master Comparison (8 Scenarios)'!H6 | I10: ='Master Comparison (8 Scenarios)'!I6 | J10: ='Master Comparison (8 Scenarios)'!J6 | K10: ='Master Comparison (8 Scenarios)'!K6 | L10: ='Master Comparison (8 Scenarios)'!L6 | ... P10: ='Master Comparison (8 Scenarios)'!P6
A11: S3 | B11: Leased Towers | C11: Starlink Backhaul | D11: Non-Deferred | E11: ='Master Comparison (8 Scenarios)'!E7 | F11: ='Master Comparison (8 Scenarios)'!F7 | G11: ='Master Comparison (8 Scenarios)'!G7 | H11: ='Master Comparison (8 Scenarios)'!H7 | I11: ='Master Comparison (8 Scenarios)'!I7 | J11: ='Master Comparison (8 Scenarios)'!J7 | K11: ='Master Comparison (8 Scenarios)'!K7 | L11: ='Master Comparison (8 Scenarios)'!L7 | ... P11: ='Master Comparison (8 Scenarios)'!P7
A12: S4 | B12: Leased Towers | C12: Starlink Backhaul | D12: Deferred | E12: ='Master Comparison (8 Scenarios)'!E8 | F12: ='Master Comparison (8 Scenarios)'!F8 | G12: ='Master Comparison (8 Scenarios)'!G8 | H12: ='Master Comparison (8 Scenarios)'!H8 | I12: ='Master Comparison (8 Scenarios)'!I8 | J12: ='Master Comparison (8 Scenarios)'!J8 | K12: ='Master Comparison (8 Scenarios)'!K8 | L12: ='Master Comparison (8 Scenarios)'!L8 | ... P12: ='Master Comparison (8 Scenarios)'!P8
A13: S5 | B13: Own Build (Monopoles) | C13: FOC Backhaul | D13: Non-Deferred | E13: ='Master Comparison (8 Scenarios)'!E9 | F13: ='Master Comparison (8 Scenarios)'!F9 | G13: ='Master Comparison (8 Scenarios)'!G9 | H13: ='Master Comparison (8 Scenarios)'!H9 | I13: ='Master Comparison (8 Scenarios)'!I9 | J13: ='Master Comparison (8 Scenarios)'!J9 | K13: ='Master Comparison (8 Scenarios)'!K9 | L13: ='Master Comparison (8 Scenarios)'!L9 | ... P13: ='Master Comparison (8 Scenarios)'!P9
A14: S6 | B14: Own Build (Monopoles) | C14: FOC Backhaul | D14: Deferred | E14: ='Master Comparison (8 Scenarios)'!E10 | F14: ='Master Comparison (8 Scenarios)'!F10 | G14: ='Master Comparison (8 Scenarios)'!G10 | H14: ='Master Comparison (8 Scenarios)'!H10 | I14: ='Master Comparison (8 Scenarios)'!I10 | J14: ='Master Comparison (8 Scenarios)'!J10 | K14: ='Master Comparison (8 Scenarios)'!K10 | L14: ='Master Comparison (8 Scenarios)'!L10 | ... P14: ='Master Comparison (8 Scenarios)'!P10
A15: S7 | B15: Own Build (Monopoles) | C15: Starlink Backhaul | D15: Non-Deferred | E15: ='Master Comparison (8 Scenarios)'!E11 | F15: ='Master Comparison (8 Scenarios)'!F11 | G15: ='Master Comparison (8 Scenarios)'!G11 | H15: ='Master Comparison (8 Scenarios)'!H11 | I15: ='Master Comparison (8 Scenarios)'!I11 | J15: ='Master Comparison (8 Scenarios)'!J11 | K15: ='Master Comparison (8 Scenarios)'!K11 | L15: ='Master Comparison (8 Scenarios)'!L11 | ... P15: ='Master Comparison (8 Scenarios)'!P11
A16: S8 | B16: Own Build (Monopoles) | C16: Starlink Backhaul | D16: Deferred | E16: ='Master Comparison (8 Scenarios)'!E12 | F16: ='Master Comparison (8 Scenarios)'!F12 | G16: ='Master Comparison (8 Scenarios)'!G12 | H16: ='Master Comparison (8 Scenarios)'!H12 | I16: ='Master Comparison (8 Scenarios)'!I12 | J16: ='Master Comparison (8 Scenarios)'!J12 | K16: ='Master Comparison (8 Scenarios)'!K12 | L16: ='Master Comparison (8 Scenarios)'!L12 | ... P16: ='Master Comparison (8 Scenarios)'!P12
A18: STRATEGIC EVALUATION & CAPITAL ALLOCATION FINDINGS
A19: 1. Starlink Transport Advantage: Starlink backhaul delivers $1,112.1 Million ($1.11 Billion) in operating savings over 10 years compared to leased FOC fiber.
A20: 2. TowerCo Colocation vs. Own Build: Colocating on existing towers saves $721.4 Million in upfront civil monopole and power plant construction capital.
A21: 3. Equipment Vendor Financing: 20% down + 4-year deferred vendor credit cuts Year 1 cash burn by 68% ($52.4M) and provides a $95.9M peak liquidity buffer.
A22: 4. Scenario 4 (S4) Standout Viability: Generates $1,737.5M in EBITDA and +$268.3M in Free Cash Flow; recommended as the primary corporate deployment model.

Sheet Table 4 - What Makes It a GO
A1: FWA 5G n50 (80 MHz) — Table 4: Commercial Viability & What Makes This a GO
A2: Single Subscriber Retail Rate Sensitivity, Breakeven Analysis & Return Expansion for Recommended Case (S4: Leased + Starlink + Deferred)
A4: 1. COST BREAKEVEN BENCHMARKS (10,000 SITES / 10,000,000 CAPACITY)
A5: Cost Benchmark Metric | B5: Derivation / Formula Basis | C5: Starlink Backhaul (PHP/mo) | D5: Leased FOC Backhaul (PHP/mo) | E5: Strategic Meaning & Economic Threshold
A6: Cash OPEX Breakeven | B6: Annual Operating Costs / (12 * Active Subs) | C6: ₱318 / month | D6: ₱418 / month | E6: Minimum cash subscription rate required to operate the network without cash burn
A7: Fully Loaded Breakeven (OPEX + Depr) | B7: (Annual OPEX + Annual Depreciation) / (12 * Active Subs) | C7: ₱412 / month | D7: ₱512 / month | E7: Zero accounting profit threshold (EBIT = 0); covers all equipment replacement costs
A8: 12% WACC Hurdle Rate | B8: OPEX + Depreciation + 12% Cost of Capital on Total Assets | C8: ₱585 / month | D8: ₱685 / month | E8: Minimum rate to clear 12.0% corporate WACC hurdle at full capacity utilization
A10: 2. SCENARIO 4 SENSITIVITY: SINGLE RETAIL RATE vs. PROJECT FINANCIAL RETURNS (10,000 SITES)
A11: Single Retail Rate (PHP) | B11: Monthly ARPU (USD) | C11: 10-Yr Total Revenue ($M) | D11: 10-Yr Total OPEX ($M) | E11: 10-Yr Total EBITDA ($M) | F11: EBITDA Margin (%) | G11: 10-Yr Free Cash Flow ($M) | H11: Peak Funding Req. ($M) | I11: 10-Yr Project NPV @ 12% ($M) | J11: 10-Yr Project IRR (%) | K11: Simple Payback (Yrs) | L11: Commercial Assessment & Decision Verdict
A12: 499 | B12: =A12/'Assumptions & Levers'!$C$5 | C12: =S4_Leased_Star_Deferred!N8*B12*12*10/1000000 | D12: =S4_Leased_Star_Deferred!N29/1000000 | E12: =C12-D12 | F12: =E12/C12 | G12: -587.7 | H12: -748 | I12: -478.6 | J12: N/A (<0%) | K12: 11 | L12: NO-GO: Below commercial viability threshold
A13: 549 | B13: =A13/'Assumptions & Levers'!$C$5 | C13: =S4_Leased_Star_Deferred!N8*B13*12*10/1000000 | D13: =S4_Leased_Star_Deferred!N29/1000000 | E13: =C13-D13 | F13: =E13/C13 | G13: -159.7 | H13: -629.5 | I13: -280.3 | J13: N/A (<0%) | K13: 11 | L13: NO-GO: Operational cash breakeven; negative equity return
A14: 599 | B14: =A14/'Assumptions & Levers'!$C$5 | C14: =S4_Leased_Star_Deferred!N8*B14*12*10/1000000 | D14: =S4_Leased_Star_Deferred!N29/1000000 | E14: =C14-D14 | F14: =E14/C14 | G14: 268.3 | H14: -511 | I14: -82.1 | J14: 0.075 | K14: 8.7 | L14: CONDITIONAL GO: Operational cash positive; sub-12% WACC hurdle
A15: 649 | B15: =A15/'Assumptions & Levers'!$C$5 | C15: =S4_Leased_Star_Deferred!N8*B15*12*10/1000000 | D15: =S4_Leased_Star_Deferred!N29/1000000 | E15: =C15-D15 | F15: =E15/C15 | G15: 653.9 | H15: -439.4 | I15: 95.3 | J15: 0.163 | K15: 7.5 | L15: GO: Clears 12% WACC Hurdle with +$95.3M NPV (+₱50 Uplift)
A16: 699 | B16: =A16/'Assumptions & Levers'!$C$5 | C16: =S4_Leased_Star_Deferred!N8*B16*12*10/1000000 | D16: =S4_Leased_Star_Deferred!N29/1000000 | E16: =C16-D16 | F16: =E16/C16 | G16: 1039.1 | H16: -387.8 | I16: 270.5 | J16: 0.252 | K16: 6.6 | L16: ★ COMPELLING GO: Target Commercial Sweet Spot (High Return)
A17: 749 | B17: =A17/'Assumptions & Levers'!$C$5 | C17: =S4_Leased_Star_Deferred!N8*B17*12*10/1000000 | D17: =S4_Leased_Star_Deferred!N29/1000000 | E17: =C17-D17 | F17: =E17/C17 | G17: 1424.4 | H17: -348 | I17: 444.2 | J17: 0.327 | K17: 6 | L17: STRONG GO: High-Return Regional Profile
A18: 799 | B18: =A18/'Assumptions & Levers'!$C$5 | C18: =S4_Leased_Star_Deferred!N8*B18*12*10/1000000 | D18: =S4_Leased_Star_Deferred!N29/1000000 | E18: =C18-D18 | F18: =E18/C18 | G18: 1809.8 | H18: -312.7 | I18: 617.9 | J18: 0.401 | K18: 5.5 | L18: EXCEPTIONAL GO: Outstanding Capital Return Profile
A19: 849 | B19: =A19/'Assumptions & Levers'!$C$5 | C19: =S4_Leased_Star_Deferred!N8*B19*12*10/1000000 | D19: =S4_Leased_Star_Deferred!N29/1000000 | E19: =C19-D19 | F19: =E19/C19 | G19: 2195.1 | H19: -284.1 | I19: 790.9 | J19: 0.471 | K19: 5.1 | L19: EXCEPTIONAL GO: Top-Tier Commercial Performance
A20: 899 | B20: =A20/'Assumptions & Levers'!$C$5 | C20: =S4_Leased_Star_Deferred!N8*B20*12*10/1000000 | D20: =S4_Leased_Star_Deferred!N29/1000000 | E20: =C20-D20 | F20: =E20/C20 | G20: 2580.5 | H20: -260.8 | I20: 963.9 | J20: 0.538 | K20: 4.8 | L20: PREMIUM GO: Enterprise / SME Focused Trajectory
A23: 3. HOW TO ACHIEVE ₱699 BLENDED ARPU WITHOUT INCREASING THE ₱599 ENTRY PRICE
A24: Product Plan Tier | B24: Target Speed | C24: Monthly Price (PHP) | D24: Customer Adoption Mix (%) | E24: Weighted Monthly ARPU (PHP) | F24: Strategic Market Role
A25: FWA Home Basic (Anchor) | B25: 25 Mbps | C25: 599 | D25: 0.5 | E25: 299.5 | F25: Mass-market anchor to rapidly capture household market share and fill base capacity
A26: FWA Home Turbo (Add-On) | B26: 50 Mbps | C26: 799 | D26: 0.4 | E26: 319.6 | F26: Upsell for multi-device streaming, gaming, and work-from-home households
A27: FWA Home Pro / SME | B27: 100 Mbps + Static IP | C27: 1299 | D27: 0.1 | E27: 129.9 | F27: High-margin tier for sari-sari stores, local businesses, schools, and barangay halls
A28: BLENDED WEIGHTED AVERAGE | B28: Tiered Product Mix | C28: 699 | D28: 1 | E28: 699 | F28: Delivers +$270.5M NPV, 25.2% Project IRR, and 6.6-Year Payback!

Sheet Assumptions & Levers
A1: FWA 5G n50 (60 MHz) — Central Model Assumptions & Levers (1,000 Sites in Year 1)
A2: Source of Truth: n50 costing_Sep14_rev 2 by OLI_OD_DL.xlsx. Full 1,000-site footprint deployed in Year 1. Yellow cells are dynamic inputs.
A4: Category | B4: Assumption / Parameter | C4: Default Value | D4: Unit | E4: Source Reference / Formula / Notes
A5: Global Financials | B5: Exchange Rate (PHP/USD) | C5: 55 | D5: PHP/USD | E5: B5: Baseline FX in Price Book / Regulatory (test 55 to 65)
A6: Global Financials | B6: Discount Rate / WACC | C6: 0.12 | D6: % | E6: B6: Nominal Weighted Average Cost of Capital
A7: Global Financials | B7: Corporate Income Tax Rate | C7: 0.25 | D7: % | E7: B7: Philippine CREATE Act corporate tax rate
A8: Global Financials | B8: Annual Cost Inflation / Escalation | C8: 0.05 | D8: % p.a. | E8: B8: Annual escalation for ongoing opex and future capex
A9: Global Financials | B9: Project Modeling Horizon | C9: 10 | D9: years | E9: B9: 10-year full deployment lifecycle
A10: Deployment & Scale | B10: Total Planned Sites (Deployed Year 1) | C10: 1000 | D10: sites | E10: B10: 1,000 sites commissioned in Year 1 (Day-1 full footprint)
A11: Deployment & Scale | B11: Sites Added per Year (Y2-Y10) | C11: 1000 | D11: sites/yr | E11: B11: 1,000 additional sites deployed per year (scaling to 10,000 sites)
A12: Deployment & Scale | B12: Design Capacity per Site | C12: 1000 | D12: subs/site | E12: B12: 1,000 subscribers per 3-sector site (n50 60MHz DDDSU)
A13: Deployment & Scale | B13: Total Network Subscriber Capacity | C13: =($C$10 + 9*$C$11)*$C$12 | D13: subs | E13: B13: Network capacity at maturity (Year 10)
A14: Deployment & Scale | B14: Monthly Gross Churn Rate | C14: 0.012 | D14: % / month | E14: B14: 1.2% monthly churn (14.4% p.a.)
A15: Deployment & Scale | B15: CPE Reclamation Success Rate | C15: 0.5 | D15: % of churn | E15: B15: 50% of churned CPEs recovered from households
A16: Deployment & Scale | B16: CPE Refurbishment Cost | C16: 0.2 | D16: % of new | E16: B16: Refurbishing recovered CPE costs 20% of new unit
A17: Commercial & ARPU | B17: Base Single Subscriber Retail Rate | C17: 599 | D17: PHP / month | E17: B17: Mass-market fixed wireless monthly subscription
A18: Commercial & ARPU | B18: Blended ARPU Uplift Multiplier | C18: 1.166945 | D18: x | E18: B18: 1.167x = blended ₱699/mo (50% @ ₱599, 40% @ ₱799, 10% @ ₱1,299 per Table 4)
A19: Commercial & ARPU | B19: Effective Blended ARPU | C19: =$C$17*$C$18 | D19: PHP / month | E19: B19: Resulting monthly revenue per active subscriber (₱699.00/mo)
A20: Commercial & ARPU | B20: Monthly Device Fee Recovery | C20: 0 | D20: PHP / month | E20: B20: Device installment fee if customer co-pays CPE
A21: Commercial & ARPU | B21: Device Fee Duration | C21: 24 | D21: months | E21: B21: Duration of device recovery fee
A22: CAPEX Unit Costs | B22: BTS (BBU x1, RRU x3, Antenna x3) | C22: 26000 | D22: USD / site | E22: B22: Price Book F3: 60 MHz n50 macro BTS
A23: CAPEX Unit Costs | B23: RAN Services (Survey, PM, I&C, Optim) | C23: 15900 | D23: USD / site | E23: B23: Price Book F19:F25: Complete turnkey rollout services
A24: CAPEX Unit Costs | B24: 5G Core HW & Integration | C24: 4480000 | D24: USD | E24: FWA_5GC_OSSBSS_Dimensioning_1M.xlsx: Core HW, DC fabric & integration (Chinese Tier-1)
A25: CAPEX Unit Costs | B25: Core Software Licenses (1M subs) | C25: 5660000 | D25: USD | E25: FWA_5GC_OSSBSS_Dimensioning_1M.xlsx: 1M sub 5GC licenses + 277Gbps UPF (Chinese Tier-1)
A26: CAPEX Unit Costs | B26: OSS / BSS Turnkey Platform | C26: 12830000 | D26: USD | E26: FWA_5GC_OSSBSS_Dimensioning_1M.xlsx: Turnkey BSS/OSS + SI + Cloud DR (Chinese Tier-1)
A27: CAPEX Unit Costs | B27: CPE Unit Purchase Price | C27: 55 | D27: USD / unit | E27: B27: Price Book F15 / Cost Tables row 21 ($55/CPE for 1M subs)
A28: Tower Infrastructure | B28: Monopole Build (30m + Compound + AC) | C28: 3500000 | D28: PHP / site | E28: B28: Price Book F6: Monopole, shelter, compound ($63,636 @ 55 FX)
A29: Tower Infrastructure | B29: 25kVA Diesel Generator & Day Tank | C29: 4000 | D29: USD / site | E29: B29: Price Book F5 / Cost Table row 10: Standby backup power
A30: Tower Infrastructure | B30: DC Power Plant (6kW Rectifier + LFP) | C30: 4500 | D30: USD / site | E30: B30: Price Book F4: 6kW rectifier + 150Ah LiFePO4 battery
A31: Tower Infrastructure | B31: TowerCo Lease Rate (incl DC & Passive O&M) | C31: 120000 | D31: PHP/site/mo | E31: B31: Price Book F38: Full turnkey macro colocation lease
... A45: Regulatory & SUF | B45: SUF Regulatory Rate per kHz | C45: 5 | D45: PHP / kHz | E45: B45: NTC mandated rate: ₱5.00 per kHz (no phasing)
A46: Regulatory & SUF | B46: Annual Spectrum User Fee (SUF) | C46: =$C$44*1000*$C$45 | D46: PHP / year | E46: B46: 80,000 kHz x ₱5.00/kHz = ₱400,000,000 PHP/year ($7.27M USD)
A47: Regulatory & SUF | B47: SUF Annual Outflow in USD | C47: =$C$46/$C$5 | D47: USD / year | E47: B47: $7,272,727 USD/year unphased across all 10 years
A48: Regulatory & SUF | B48: Administrative Station Fees (RSL + Insp + Filing) | C48: 2310 | D48: PHP/site/yr | E48: B48: Price Book F59-F68: ₱1,200 RSL + ₱480 AIF + upfront amortized
A49: Financing & Deferred Terms | B49: Equipment Vendor Financing Down Payment | C49: 0.2 | D49: % upfront | E49: B49: 20% down payment on equipment delivery in Year 1
A50: Financing & Deferred Terms | B50: Financed Equipment Portion | C50: =1-$C$49 | D50: % financed | E50: B50: 80% vendor financed
A51: Financing & Deferred Terms | B51: Vendor Financing Amortization Period | C51: 4 | D51: years | E51: B51: Equal annual principal repayments over 4 years
A52: Financing & Deferred Terms | B52: Vendor Financing Interest Rate | C52: 0.065 | D52: % p.a. | E52: B52: 6.5% annual vendor financing interest rate
A53: Financing & Deferred Terms | B53: SUF Payment Mechanism | C53: Full Flat Annual (Unphased) | D53: mode | E53: B53: Flat ₱400M/year paid across all years (no phasing)
A54: Accounting Depreciation | B54: Depreciation Life — Telecom Network & Core | C54: 7 | D54: years | E54: B54: Straight-line depreciation for RAN, Core, and backhaul hardware
...

Sheet S1_Leased_FOC_NonDef
A1: Scenario 1: Leased Towers + FOC Backhaul + Non-Deferred Payment (1,000 Sites Y1)
A2: Footprint: 1,000 Sites in Year 1 (Day-1 Full Build) | Tower: Leased (TowerCo) | Backhaul: FOC | Payment Terms: Non-Deferred (100% Upfront)
A4: Category | B4: Line Item | C4: Unit | D4: Year 1 | E4: Year 2 | F4: Year 3 | G4: Year 4 | H4: Year 5 | I4: Year 6 | J4: Year 7 | K4: Year 8 | L4: Year 9 | M4: Year 10 | N4: 10-Year Total
A5: Network Rollout | B5: Active Cumulative Sites | C5: sites | D5: ='Assumptions & Levers'!$C$10 | E5: =D5 + 'Assumptions & Levers'!$C$11 | F5: =E5 + 'Assumptions & Levers'!$C$11 | G5: =F5 + 'Assumptions & Levers'!$C$11 | H5: =G5 + 'Assumptions & Levers'!$C$11 | I5: =H5 + 'Assumptions & Levers'!$C$11 | J5: =I5 + 'Assumptions & Levers'!$C$11 | K5: =J5 + 'Assumptions & Levers'!$C$11 | L5: =K5 + 'Assumptions & Levers'!$C$11 | M5: =L5 + 'Assumptions & Levers'!$C$11 | N5: =M5
A6: Network Rollout | B6: New Sites Commissioned | C6: sites | D6: =D5 | E6: =E5 - D5 | F6: =F5 - E5 | G6: =G5 - F5 | H6: =H5 - G5 | I6: =I5 - H5 | J6: =J5 - I5 | K6: =K5 - J5 | L6: =L5 - K5 | M6: =M5 - L5 | N6: =SUM(D6:M6)
A7: Subscribers | B7: Closing Active Subscribers | C7: subs | D7: =D5*'Assumptions & Levers'!$C$12 * IF('Assumptions & Levers'!$C$57=3, 1, IF('Assumptions & Levers'!$C$57=2, 0.5, 0.25)) | E7: =E5*'Assumptions & Levers'!$C$12 * IF('Assumptions & Levers'!$C$57=3, 1, IF('Assumptions & Levers'!$C$57=2, 0.8, 0.5)) | F7: =F5*'Assumptions & Levers'!$C$12 * IF('Assumptions & Levers'!$C$57=3, 1, IF('Assumptions & Levers'!$C$57=2, 1, 0.75)) | G7: =G5*'Assumptions & Levers'!$C$12 * IF('Assumptions & Levers'!$C$57=3, 1, IF('Assumptions & Levers'!$C$57=2, 1, 0.9)) | H7: =H5*'Assumptions & Levers'!$C$12 * 1 | I7: =I5*'Assumptions & Levers'!$C$12 * 1 | J7: =J5*'Assumptions & Levers'!$C$12 * 1 | K7: =K5*'Assumptions & Levers'!$C$12 * 1 | L7: =L5*'Assumptions & Levers'!$C$12 * 1 | M7: =M5*'Assumptions & Levers'!$C$12 * 1 | N7: =M7
A8: Subscribers | B8: Average Subscribers (Billing Base) | C8: subs | D8: =IF('Assumptions & Levers'!$C$57=3, D7, D7/2) | E8: =(D7+E7)/2 | F8: =(E7+F7)/2 | G8: =(F7+G7)/2 | H8: =(G7+H7)/2 | I8: =(H7+I7)/2 | J8: =(I7+J7)/2 | K8: =(J7+K7)/2 | L8: =(K7+L7)/2 | M8: =(L7+M7)/2 | N8: =AVERAGE(D8:M8)
A9: Subscribers | B9: Net Subscriber Additions | C9: subs | D9: =D7 | E9: =MAX(0, E7-D7) | F9: =MAX(0, F7-E7) | G9: =MAX(0, G7-F7) | H9: =MAX(0, H7-G7) | I9: =MAX(0, I7-H7) | J9: =MAX(0, J7-I7) | K9: =MAX(0, K7-J7) | L9: =MAX(0, L7-K7) | M9: =MAX(0, M7-L7) | N9: =SUM(D9:M9)
A10: Subscribers | B10: Churned Subscribers | C10: subs | D10: =D8*'Assumptions & Levers'!$C$14*12 | E10: =E8*'Assumptions & Levers'!$C$14*12 | F10: =F8*'Assumptions & Levers'!$C$14*12 | G10: =G8*'Assumptions & Levers'!$C$14*12 | H10: =H8*'Assumptions & Levers'!$C$14*12 | I10: =I8*'Assumptions & Levers'!$C$14*12 | J10: =J8*'Assumptions & Levers'!$C$14*12 | K10: =K8*'Assumptions & Levers'!$C$14*12 | ... M10: =M8*'Assumptions & Levers'!$C$14*12 | N10: =SUM(D10:M10)
A11: Subscribers | B11: CPE Units Procured (Net + Replacement) | C11: units | D11: =D9 + D10*(1 - 'Assumptions & Levers'!$C$15*(1 - 'Assumptions & Levers'!$C$16)) | E11: =E9 + E10*(1 - 'Assumptions & Levers'!$C$15*(1 - 'Assumptions & Levers'!$C$16)) | F11: =F9 + F10*(1 - 'Assumptions & Levers'!$C$15*(1 - 'Assumptions & Levers'!$C$16)) | G11: =G9 + G10*(1 - 'Assumptions & Levers'!$C$15*(1 - 'Assumptions & Levers'!$C$16)) | H11: =H9 + H10*(1 - 'Assumptions & Levers'!$C$15*(1 - 'Assumptions & Levers'!$C$16)) | I11: =I9 + I10*(1 - 'Assumptions & Levers'!$C$15*(1 - 'Assumptions & Levers'!$C$16)) | J11: =J9 + J10*(1 - 'Assumptions & Levers'!$C$15*(1 - 'Assumptions & Levers'!$C$16)) | K11: =K9 + K10*(1 - 'Assumptions & Levers'!$C$15*(1 - 'Assumptions & Levers'!$C$16)) | ... M11: =M9 + M10*(1 - 'Assumptions & Levers'!$C$15*(1 - 'Assumptions & Levers'!$C$16)) | N11: =SUM(D11:M11)
A13: Revenue | B13: Blended Monthly ARPU | C13: USD/sub/mo | D13: ='Assumptions & Levers'!$C$19/'Assumptions & Levers'!$C$5 | E13: ='Assumptions & Levers'!$C$19/'Assumptions & Levers'!$C$5 | F13: ='Assumptions & Levers'!$C$19/'Assumptions & Levers'!$C$5 | G13: ='Assumptions & Levers'!$C$19/'Assumptions & Levers'!$C$5 | H13: ='Assumptions & Levers'!$C$19/'Assumptions & Levers'!$C$5 | I13: ='Assumptions & Levers'!$C$19/'Assumptions & Levers'!$C$5 | J13: ='Assumptions & Levers'!$C$19/'Assumptions & Levers'!$C$5 | K13: ='Assumptions & Levers'!$C$19/'Assumptions & Levers'!$C$5 | ... M13: ='Assumptions & Levers'!$C$19/'Assumptions & Levers'!$C$5 | N13: =M13
A14: Revenue | B14: Annual Service Revenue | C14: USD | D14: =D8*D13*12 | E14: =E8*E13*12 | F14: =F8*F13*12 | G14: =G8*G13*12 | H14: =H8*H13*12 | I14: =I8*I13*12 | J14: =J8*J13*12 | K14: =K8*K13*12 | ... M14: =M8*M13*12 | N14: =SUM(D14:M14)
A15: Revenue | B15: Device Fee Revenue | C15: USD | D15: =D8*'Assumptions & Levers'!$C$20*12/'Assumptions & Levers'!$C$5 | E15: =E8*'Assumptions & Levers'!$C$20*12/'Assumptions & Levers'!$C$5 | F15: =F8*'Assumptions & Levers'!$C$20*12/'Assumptions & Levers'!$C$5 | G15: =G8*'Assumptions & Levers'!$C$20*12/'Assumptions & Levers'!$C$5 | H15: =H8*'Assumptions & Levers'!$C$20*12/'Assumptions & Levers'!$C$5 | I15: =I8*'Assumptions & Levers'!$C$20*12/'Assumptions & Levers'!$C$5 | J15: =J8*'Assumptions & Levers'!$C$20*12/'Assumptions & Levers'!$C$5 | K15: =K8*'Assumptions & Levers'!$C$20*12/'Assumptions & Levers'!$C$5 | ... M15: =M8*'Assumptions & Levers'!$C$20*12/'Assumptions & Levers'!$C$5 | N15: =SUM(D15:M15)
A16: Revenue | B16: TOTAL REVENUE | C16: USD | D16: =D14+D15 | E16: =E14+E15 | F16: =F14+F15 | G16: =G14+G15 | H16: =H14+H15 | I16: =I14+I15 | J16: =J14+J15 | K16: =K14+K15 | ... N16: =N14+N15
A18: OPEX | B18: RAN Support & Maintenance (AMC) | C18: USD | D18: =D5*'Assumptions & Levers'!$C$22*0.1 | E18: =E5*'Assumptions & Levers'!$C$22*0.1 | F18: =F5*'Assumptions & Levers'!$C$22*0.1 | G18: =G5*'Assumptions & Levers'!$C$22*0.1 | H18: =H5*'Assumptions & Levers'!$C$22*0.1 | I18: =I5*'Assumptions & Levers'!$C$22*0.1 | J18: =J5*'Assumptions & Levers'!$C$22*0.1 | K18: =K5*'Assumptions & Levers'!$C$22*0.1 | ... M18: =M5*'Assumptions & Levers'!$C$22*0.1 | N18: =SUM(D18:M18)
A19: OPEX | B19: Tower Lease (incl DC & Passive O&M) | C19: USD | D19: =D5*'Assumptions & Levers'!$C$31*12/'Assumptions & Levers'!$C$5 | E19: =E5*'Assumptions & Levers'!$C$31*12/'Assumptions & Levers'!$C$5 | F19: =F5*'Assumptions & Levers'!$C$31*12/'Assumptions & Levers'!$C$5 | G19: =G5*'Assumptions & Levers'!$C$31*12/'Assumptions & Levers'!$C$5 | H19: =H5*'Assumptions & Levers'!$C$31*12/'Assumptions & Levers'!$C$5 | I19: =I5*'Assumptions & Levers'!$C$31*12/'Assumptions & Levers'!$C$5 | J19: =J5*'Assumptions & Levers'!$C$31*12/'Assumptions & Levers'!$C$5 | K19: =K5*'Assumptions & Levers'!$C$31*12/'Assumptions & Levers'!$C$5 | ... M19: =M5*'Assumptions & Levers'!$C$31*12/'Assumptions & Levers'!$C$5 | N19: =SUM(D19:M19)
A20: OPEX | B20: Land Lease & Compound Security | C20: USD | D20: 0 | E20: 0 | F20: 0 | G20: 0 | H20: 0 | I20: 0 | J20: 0 | K20: 0 | L20: 0 | M20: 0 | N20: =SUM(D20:M20)
A21: OPEX | B21: Electricity & Power Utility | C21: USD | D21: =D5*'Assumptions & Levers'!$C$35*12/'Assumptions & Levers'!$C$5 | E21: =E5*'Assumptions & Levers'!$C$35*12/'Assumptions & Levers'!$C$5 | F21: =F5*'Assumptions & Levers'!$C$35*12/'Assumptions & Levers'!$C$5 | G21: =G5*'Assumptions & Levers'!$C$35*12/'Assumptions & Levers'!$C$5 | H21: =H5*'Assumptions & Levers'!$C$35*12/'Assumptions & Levers'!$C$5 | I21: =I5*'Assumptions & Levers'!$C$35*12/'Assumptions & Levers'!$C$5 | J21: =J5*'Assumptions & Levers'!$C$35*12/'Assumptions & Levers'!$C$5 | K21: =K5*'Assumptions & Levers'!$C$35*12/'Assumptions & Levers'!$C$5 | ... M21: =M5*'Assumptions & Levers'!$C$35*12/'Assumptions & Levers'!$C$5 | N21: =SUM(D21:M21)
A22: OPEX | B22: Telecom Active O&M Services | C22: USD | D22: =D5*'Assumptions & Levers'!$C$36*12/'Assumptions & Levers'!$C$5 | E22: =E5*'Assumptions & Levers'!$C$36*12/'Assumptions & Levers'!$C$5 | F22: =F5*'Assumptions & Levers'!$C$36*12/'Assumptions & Levers'!$C$5 | G22: =G5*'Assumptions & Levers'!$C$36*12/'Assumptions & Levers'!$C$5 | H22: =H5*'Assumptions & Levers'!$C$36*12/'Assumptions & Levers'!$C$5 | I22: =I5*'Assumptions & Levers'!$C$36*12/'Assumptions & Levers'!$C$5 | J22: =J5*'Assumptions & Levers'!$C$36*12/'Assumptions & Levers'!$C$5 | K22: =K5*'Assumptions & Levers'!$C$36*12/'Assumptions & Levers'!$C$5 | ... M22: =M5*'Assumptions & Levers'!$C$36*12/'Assumptions & Levers'!$C$5 | N22: =SUM(D22:M22)
A23: OPEX | B23: FOC Leased Fiber Transmission | C23: USD | D23: =D5*'Assumptions & Levers'!$C$37*12/'Assumptions & Levers'!$C$5 | E23: =E5*'Assumptions & Levers'!$C$37*12/'Assumptions & Levers'!$C$5 | F23: =F5*'Assumptions & Levers'!$C$37*12/'Assumptions & Levers'!$C$5 | G23: =G5*'Assumptions & Levers'!$C$37*12/'Assumptions & Levers'!$C$5 | H23: =H5*'Assumptions & Levers'!$C$37*12/'Assumptions & Levers'!$C$5 | I23: =I5*'Assumptions & Levers'!$C$37*12/'Assumptions & Levers'!$C$5 | J23: =J5*'Assumptions & Levers'!$C$37*12/'Assumptions & Levers'!$C$5 | K23: =K5*'Assumptions & Levers'!$C$37*12/'Assumptions & Levers'!$C$5 | ... M23: =M5*'Assumptions & Levers'!$C$37*12/'Assumptions & Levers'!$C$5 | N23: =SUM(D23:M23)
A24: OPEX | B24: National IP Transit & Core Peering | C24: USD | D24: ='Assumptions & Levers'!$C$43 | E24: ='Assumptions & Levers'!$C$43 | F24: ='Assumptions & Levers'!$C$43 | G24: ='Assumptions & Levers'!$C$43 | H24: ='Assumptions & Levers'!$C$43 | I24: ='Assumptions & Levers'!$C$43 | J24: ='Assumptions & Levers'!$C$43 | K24: ='Assumptions & Levers'!$C$43 | ... M24: ='Assumptions & Levers'!$C$43 | N24: =SUM(D24:M24)
A25: OPEX | B25: CPE Support & Device Maintenance | C25: USD | D25: =D7*'Assumptions & Levers'!$C$27*0.03 | E25: =E7*'Assumptions & Levers'!$C$27*0.03 | F25: =F7*'Assumptions & Levers'!$C$27*0.03 | G25: =G7*'Assumptions & Levers'!$C$27*0.03 | H25: =H7*'Assumptions & Levers'!$C$27*0.03 | I25: =I7*'Assumptions & Levers'!$C$27*0.03 | J25: =J7*'Assumptions & Levers'!$C$27*0.03 | K25: =K7*'Assumptions & Levers'!$C$27*0.03 | ... M25: =M7*'Assumptions & Levers'!$C$27*0.03 | N25: =SUM(D25:M25)
A26: OPEX | B26: 5G Core & OSS/BSS Annual AMC/Support | C26: USD | D26: ='Assumptions & Levers'!$C$61 | E26: ='Assumptions & Levers'!$C$61 + SUM($E$37:E37)*'Assumptions & Levers'!$C$62 | F26: ='Assumptions & Levers'!$C$61 + SUM($E$37:F37)*'Assumptions & Levers'!$C$62 | G26: ='Assumptions & Levers'!$C$61 + SUM($E$37:G37)*'Assumptions & Levers'!$C$62 | H26: ='Assumptions & Levers'!$C$61 + SUM($E$37:H37)*'Assumptions & Levers'!$C$62 | I26: ='Assumptions & Levers'!$C$61 + SUM($E$37:I37)*'Assumptions & Levers'!$C$62 | J26: ='Assumptions & Levers'!$C$61 + SUM($E$37:J37)*'Assumptions & Levers'!$C$62 | K26: ='Assumptions & Levers'!$C$61 + SUM($E$37:K37)*'Assumptions & Levers'!$C$62 | L26: ='Assumptions & Levers'!$C$61 + SUM($E$37:L37)*'Assumptions & Levers'!$C$62 | M26: ='Assumptions & Levers'!$C$61 + SUM($E$37:M37)*'Assumptions & Levers'!$C$62 | N26: =SUM(D26:M26)
A27: OPEX | B27: Spectrum User Fees (SUF) | C27: USD | D27: ='Assumptions & Levers'!$C$46/'Assumptions & Levers'!$C$5 | E27: ='Assumptions & Levers'!$C$46/'Assumptions & Levers'!$C$5 | F27: ='Assumptions & Levers'!$C$46/'Assumptions & Levers'!$C$5 | G27: ='Assumptions & Levers'!$C$46/'Assumptions & Levers'!$C$5 | H27: ='Assumptions & Levers'!$C$46/'Assumptions & Levers'!$C$5 | I27: ='Assumptions & Levers'!$C$46/'Assumptions & Levers'!$C$5 | J27: ='Assumptions & Levers'!$C$46/'Assumptions & Levers'!$C$5 | K27: ='Assumptions & Levers'!$C$46/'Assumptions & Levers'!$C$5 | ... M27: ='Assumptions & Levers'!$C$46/'Assumptions & Levers'!$C$5 | N27: =SUM(D27:M27)
A28: OPEX | B28: NTC Station Licensing & Inspections | C28: USD | D28: =D5*'Assumptions & Levers'!$C$48/'Assumptions & Levers'!$C$5 | E28: =E5*'Assumptions & Levers'!$C$48/'Assumptions & Levers'!$C$5 | F28: =F5*'Assumptions & Levers'!$C$48/'Assumptions & Levers'!$C$5 | G28: =G5*'Assumptions & Levers'!$C$48/'Assumptions & Levers'!$C$5 | H28: =H5*'Assumptions & Levers'!$C$48/'Assumptions & Levers'!$C$5 | I28: =I5*'Assumptions & Levers'!$C$48/'Assumptions & Levers'!$C$5 | J28: =J5*'Assumptions & Levers'!$C$48/'Assumptions & Levers'!$C$5 | K28: =K5*'Assumptions & Levers'!$C$48/'Assumptions & Levers'!$C$5 | ... M28: =M5*'Assumptions & Levers'!$C$48/'Assumptions & Levers'!$C$5 | N28: =SUM(D28:M28)
A29: OPEX | B29: TOTAL OPEX | C29: USD | D29: =SUM(D18:D28) | E29: =SUM(E18:E28) | F29: =SUM(F18:F28) | G29: =SUM(G18:G28) | H29: =SUM(H18:H28) | I29: =SUM(I18:I28) | J29: =SUM(J18:J28) | K29: =SUM(K18:K28) | ... N29: =SUM(N18:N28)
A31: Profitability | B31: EBITDA | C31: USD | D31: =D16-D29 | E31: =E16-E29 | F31: =F16-F29 | G31: =G16-G29 | H31: =H16-H29 | I31: =I16-I29 | J31: =J16-J29 | K31: =K16-K29 | ... N31: =N16-N29
A32: Profitability | B32: EBITDA Margin (%) | C32: % | D32: =IFERROR(D31/D16, 0) | E32: =IFERROR(E31/E16, 0) | F32: =IFERROR(F31/F16, 0) | G32: =IFERROR(G31/G16, 0) | H32: =IFERROR(H31/H16, 0) | I32: =IFERROR(I31/I16, 0) | J32: =IFERROR(J31/J16, 0) | K32: =IFERROR(K31/K16, 0) | ... N32: =IFERROR(N31/N16, 0)
A34: CAPEX (Incurred) | B34: RAN BTS Equipment & Services | C34: USD | D34: =D6*('Assumptions & Levers'!$C$22 + 'Assumptions & Levers'!$C$23) | E34: =E6*('Assumptions & Levers'!$C$22 + 'Assumptions & Levers'!$C$23) | F34: =F6*('Assumptions & Levers'!$C$22 + 'Assumptions & Levers'!$C$23) | G34: =G6*('Assumptions & Levers'!$C$22 + 'Assumptions & Levers'!$C$23) | H34: =H6*('Assumptions & Levers'!$C$22 + 'Assumptions & Levers'!$C$23) | I34: =I6*('Assumptions & Levers'!$C$22 + 'Assumptions & Levers'!$C$23) | J34: =J6*('Assumptions & Levers'!$C$22 + 'Assumptions & Levers'!$C$23) | K34: =K6*('Assumptions & Levers'!$C$22 + 'Assumptions & Levers'!$C$23) | ... M34: =M6*('Assumptions & Levers'!$C$22 + 'Assumptions & Levers'!$C$23) | N34: =SUM(D34:M34)
A35: CAPEX (Incurred) | B35: Tower Civil Works, Genset & DC Plant | C35: USD | D35: 0 | E35: 0 | F35: 0 | G35: 0 | H35: 0 | I35: 0 | J35: 0 | K35: 0 | L35: 0 | M35: 0 | N35: =SUM(D35:M35)
A36: CAPEX (Incurred) | B36: Backhaul Infrastructure Hardware | C36: USD | D36: 0 | E36: 0 | F36: 0 | G36: 0 | H36: 0 | I36: 0 | J36: 0 | K36: 0 | L36: 0 | M36: 0 | N36: =SUM(D36:M36)
A37: CAPEX (Incurred) | B37: 5G Core HW/SW & OSS/BSS Platform | C37: USD | D37: ='Assumptions & Levers'!$C$24 + 'Assumptions & Levers'!$C$25 + 'Assumptions & Levers'!$C$26 | E37: =E6*'Assumptions & Levers'!$C$60 | F37: =F6*'Assumptions & Levers'!$C$60 | G37: =G6*'Assumptions & Levers'!$C$60 | H37: =H6*'Assumptions & Levers'!$C$60 | I37: =I6*'Assumptions & Levers'!$C$60 | J37: =J6*'Assumptions & Levers'!$C$60 | K37: =K6*'Assumptions & Levers'!$C$60 | L37: =L6*'Assumptions & Levers'!$C$60 | M37: =M6*'Assumptions & Levers'!$C$60 | N37: =SUM(D37:M37)
A38: CAPEX (Incurred) | B38: CPE Customer Devices | C38: USD | D38: =D11*'Assumptions & Levers'!$C$27 | E38: =E11*'Assumptions & Levers'!$C$27 | F38: =F11*'Assumptions & Levers'!$C$27 | G38: =G11*'Assumptions & Levers'!$C$27 | H38: =H11*'Assumptions & Levers'!$C$27 | I38: =I11*'Assumptions & Levers'!$C$27 | J38: =J11*'Assumptions & Levers'!$C$27 | K38: =K11*'Assumptions & Levers'!$C$27 | ... M38: =M11*'Assumptions & Levers'!$C$27 | N38: =SUM(D38:M38)
A39: CAPEX (Incurred) | B39: TOTAL CAPEX (INCURRED) | C39: USD | D39: =SUM(D34:D38) | E39: =SUM(E34:E38) | F39: =SUM(F34:F38) | G39: =SUM(G34:G38) | H39: =SUM(H34:H38) | I39: =SUM(I34:I38) | J39: =SUM(J34:J38) | K39: =SUM(K34:K38) | ... N39: =SUM(N34:N38)
A41: Cash Outflows | B41: Equipment Vendor Financing Down Payment (20%) | C41: USD | D41: 0 | E41: 0 | F41: 0 | G41: 0 | H41: 0 | I41: 0 | J41: 0 | K41: 0 | L41: 0 | M41: 0 | N41: 0
A42: Cash Outflows | B42: Civil Works & CPE Cash Capex (100% Upfront) | C42: USD | D42: =D39 | E42: =E39 | F42: =F39 | G42: =G39 | H42: =H39 | I42: =I39 | J42: =J39 | K42: =K39 | ... N42: =N39
A43: Cash Outflows | B43: Financed Equipment Principal Amortization | C43: USD | D43: 0 | E43: 0 | F43: 0 | G43: 0 | H43: 0 | I43: 0 | J43: 0 | K43: 0 | L43: 0 | M43: 0 | N43: 0
A44: Cash Outflows | B44: Financing Interest Expense | C44: USD | D44: 0 | E44: 0 | F44: 0 | G44: 0 | H44: 0 | I44: 0 | J44: 0 | K44: 0 | L44: 0 | M44: 0 | N44: 0
A45: Cash Outflows | B45: TOTAL CASH CAPITAL OUTFLOW (DEBT SERVICE + CAPEX) | C45: USD | D45: =D42 | E45: =E42 | F45: =F42 | G45: =G42 | H45: =H42 | I45: =I42 | J45: =J42 | K45: =K42 | ... N45: =N42
A47: Depreciation | B47: Depreciation: RAN, Core & Backhaul (7 Yrs) | C47: USD | D47: =(D34+D36+D37)/'Assumptions & Levers'!$C$54 | E47: =(D34+D36+D37 + E34+E36+E37)/'Assumptions & Levers'!$C$54 | F47: =(SUM(D34:F34) + SUM(D36:F36) + SUM(D37:F37))/'Assumptions & Levers'!$C$54 | G47: =(SUM(D34:G34) + SUM(D36:G36) + SUM(D37:G37))/'Assumptions & Levers'!$C$54 | H47: =(SUM(D34:H34) + SUM(D36:H36) + SUM(D37:H37))/'Assumptions & Levers'!$C$54 | I47: =(SUM(D34:I34) + SUM(D36:I36) + SUM(D37:I37))/'Assumptions & Levers'!$C$54 | J47: =(SUM(D34:J34) + SUM(D36:J36) + SUM(D37:J37))/'Assumptions & Levers'!$C$54 | K47: =(SUM(E34:K34) + SUM(E36:K36) + SUM(E37:K37))/'Assumptions & Levers'!$C$54 | L47: =(SUM(F34:L34) + SUM(F36:L36) + SUM(F37:L37))/'Assumptions & Levers'!$C$54 | M47: =(SUM(G34:M34) + SUM(G36:M36) + SUM(G37:M37))/'Assumptions & Levers'!$C$54 | N47: =SUM(D47:M47)
...

Sheet S2_Leased_FOC_Deferred
A1: Scenario 2: Leased Towers + FOC Backhaul + Deferred Payment (1,000 Sites Y1)
A2: Footprint: 1,000 Sites in Year 1 (Day-1 Full Build) | Tower: Leased (TowerCo) | Backhaul: FOC | Payment Terms: Deferred (Vendor Financing 20/80 + SUF Phasing)
A4: Category | B4: Line Item | C4: Unit | D4: Year 1 | E4: Year 2 | F4: Year 3 | G4: Year 4 | H4: Year 5 | I4: Year 6 | J4: Year 7 | K4: Year 8 | L4: Year 9 | M4: Year 10 | N4: 10-Year Total
A5: Network Rollout | B5: Active Cumulative Sites | C5: sites | D5: ='Assumptions & Levers'!$C$10 | E5: =D5 + 'Assumptions & Levers'!$C$11 | F5: =E5 + 'Assumptions & Levers'!$C$11 | G5: =F5 + 'Assumptions & Levers'!$C$11 | H5: =G5 + 'Assumptions & Levers'!$C$11 | I5: =H5 + 'Assumptions & Levers'!$C$11 | J5: =I5 + 'Assumptions & Levers'!$C$11 | K5: =J5 + 'Assumptions & Levers'!$C$11 | L5: =K5 + 'Assumptions & Levers'!$C$11 | M5: =L5 + 'Assumptions & Levers'!$C$11 | N5: =M5
A6: Network Rollout | B6: New Sites Commissioned | C6: sites | D6: =D5 | E6: =E5 - D5 | F6: =F5 - E5 | G6: =G5 - F5 | H6: =H5 - G5 | I6: =I5 - H5 | J6: =J5 - I5 | K6: =K5 - J5 | L6: =L5 - K5 | M6: =M5 - L5 | N6: =SUM(D6:M6)
A7: Subscribers | B7: Closing Active Subscribers | C7: subs | D7: =D5*'Assumptions & Levers'!$C$12 * IF('Assumptions & Levers'!$C$57=3, 1, IF('Assumptions & Levers'!$C$57=2, 0.5, 0.25)) | E7: =E5*'Assumptions & Levers'!$C$12 * IF('Assumptions & Levers'!$C$57=3, 1, IF('Assumptions & Levers'!$C$57=2, 0.8, 0.5)) | F7: =F5*'Assumptions & Levers'!$C$12 * IF('Assumptions & Levers'!$C$57=3, 1, IF('Assumptions & Levers'!$C$57=2, 1, 0.75)) | G7: =G5*'Assumptions & Levers'!$C$12 * IF('Assumptions & Levers'!$C$57=3, 1, IF('Assumptions & Levers'!$C$57=2, 1, 0.9)) | H7: =H5*'Assumptions & Levers'!$C$12 * 1 | I7: =I5*'Assumptions & Levers'!$C$12 * 1 | J7: =J5*'Assumptions & Levers'!$C$12 * 1 | K7: =K5*'Assumptions & Levers'!$C$12 * 1 | L7: =L5*'Assumptions & Levers'!$C$12 * 1 | M7: =M5*'Assumptions & Levers'!$C$12 * 1 | N7: =M7
A8: Subscribers | B8: Average Subscribers (Billing Base) | C8: subs | D8: =IF('Assumptions & Levers'!$C$57=3, D7, D7/2) | E8: =(D7+E7)/2 | F8: =(E7+F7)/2 | G8: =(F7+G7)/2 | H8: =(G7+H7)/2 | I8: =(H7+I7)/2 | J8: =(I7+J7)/2 | K8: =(J7+K7)/2 | L8: =(K7+L7)/2 | M8: =(L7+M7)/2 | N8: =AVERAGE(D8:M8)
A9: Subscribers | B9: Net Subscriber Additions | C9: subs | D9: =D7 | E9: =MAX(0, E7-D7) | F9: =MAX(0, F7-E7) | G9: =MAX(0, G7-F7) | H9: =MAX(0, H7-G7) | I9: =MAX(0, I7-H7) | J9: =MAX(0, J7-I7) | K9: =MAX(0, K7-J7) | L9: =MAX(0, L7-K7) | M9: =MAX(0, M7-L7) | N9: =SUM(D9:M9)
A10: Subscribers | B10: Churned Subscribers | C10: subs | D10: =D8*'Assumptions & Levers'!$C$14*12 | E10: =E8*'Assumptions & Levers'!$C$14*12 | F10: =F8*'Assumptions & Levers'!$C$14*12 | G10: =G8*'Assumptions & Levers'!$C$14*12 | H10: =H8*'Assumptions & Levers'!$C$14*12 | I10: =I8*'Assumptions & Levers'!$C$14*12 | J10: =J8*'Assumptions & Levers'!$C$14*12 | K10: =K8*'Assumptions & Levers'!$C$14*12 | ... M10: =M8*'Assumptions & Levers'!$C$14*12 | N10: =SUM(D10:M10)
A11: Subscribers | B11: CPE Units Procured (Net + Replacement) | C11: units | D11: =D9 + D10*(1 - 'Assumptions & Levers'!$C$15*(1 - 'Assumptions & Levers'!$C$16)) | E11: =E9 + E10*(1 - 'Assumptions & Levers'!$C$15*(1 - 'Assumptions & Levers'!$C$16)) | F11: =F9 + F10*(1 - 'Assumptions & Levers'!$C$15*(1 - 'Assumptions & Levers'!$C$16)) | G11: =G9 + G10*(1 - 'Assumptions & Levers'!$C$15*(1 - 'Assumptions & Levers'!$C$16)) | H11: =H9 + H10*(1 - 'Assumptions & Levers'!$C$15*(1 - 'Assumptions & Levers'!$C$16)) | I11: =I9 + I10*(1 - 'Assumptions & Levers'!$C$15*(1 - 'Assumptions & Levers'!$C$16)) | J11: =J9 + J10*(1 - 'Assumptions & Levers'!$C$15*(1 - 'Assumptions & Levers'!$C$16)) | K11: =K9 + K10*(1 - 'Assumptions & Levers'!$C$15*(1 - 'Assumptions & Levers'!$C$16)) | ... M11: =M9 + M10*(1 - 'Assumptions & Levers'!$C$15*(1 - 'Assumptions & Levers'!$C$16)) | N11: =SUM(D11:M11)
A13: Revenue | B13: Blended Monthly ARPU | C13: USD/sub/mo | D13: ='Assumptions & Levers'!$C$19/'Assumptions & Levers'!$C$5 | E13: ='Assumptions & Levers'!$C$19/'Assumptions & Levers'!$C$5 | F13: ='Assumptions & Levers'!$C$19/'Assumptions & Levers'!$C$5 | G13: ='Assumptions & Levers'!$C$19/'Assumptions & Levers'!$C$5 | H13: ='Assumptions & Levers'!$C$19/'Assumptions & Levers'!$C$5 | I13: ='Assumptions & Levers'!$C$19/'Assumptions & Levers'!$C$5 | J13: ='Assumptions & Levers'!$C$19/'Assumptions & Levers'!$C$5 | K13: ='Assumptions & Levers'!$C$19/'Assumptions & Levers'!$C$5 | ... M13: ='Assumptions & Levers'!$C$19/'Assumptions & Levers'!$C$5 | N13: =M13
A14: Revenue | B14: Annual Service Revenue | C14: USD | D14: =D8*D13*12 | E14: =E8*E13*12 | F14: =F8*F13*12 | G14: =G8*G13*12 | H14: =H8*H13*12 | I14: =I8*I13*12 | J14: =J8*J13*12 | K14: =K8*K13*12 | ... M14: =M8*M13*12 | N14: =SUM(D14:M14)
A15: Revenue | B15: Device Fee Revenue | C15: USD | D15: =D8*'Assumptions & Levers'!$C$20*12/'Assumptions & Levers'!$C$5 | E15: =E8*'Assumptions & Levers'!$C$20*12/'Assumptions & Levers'!$C$5 | F15: =F8*'Assumptions & Levers'!$C$20*12/'Assumptions & Levers'!$C$5 | G15: =G8*'Assumptions & Levers'!$C$20*12/'Assumptions & Levers'!$C$5 | H15: =H8*'Assumptions & Levers'!$C$20*12/'Assumptions & Levers'!$C$5 | I15: =I8*'Assumptions & Levers'!$C$20*12/'Assumptions & Levers'!$C$5 | J15: =J8*'Assumptions & Levers'!$C$20*12/'Assumptions & Levers'!$C$5 | K15: =K8*'Assumptions & Levers'!$C$20*12/'Assumptions & Levers'!$C$5 | ... M15: =M8*'Assumptions & Levers'!$C$20*12/'Assumptions & Levers'!$C$5 | N15: =SUM(D15:M15)
A16: Revenue | B16: TOTAL REVENUE | C16: USD | D16: =D14+D15 | E16: =E14+E15 | F16: =F14+F15 | G16: =G14+G15 | H16: =H14+H15 | I16: =I14+I15 | J16: =J14+J15 | K16: =K14+K15 | ... N16: =N14+N15
A18: OPEX | B18: RAN Support & Maintenance (AMC) | C18: USD | D18: =D5*'Assumptions & Levers'!$C$22*0.1 | E18: =E5*'Assumptions & Levers'!$C$22*0.1 | F18: =F5*'Assumptions & Levers'!$C$22*0.1 | G18: =G5*'Assumptions & Levers'!$C$22*0.1 | H18: =H5*'Assumptions & Levers'!$C$22*0.1 | I18: =I5*'Assumptions & Levers'!$C$22*0.1 | J18: =J5*'Assumptions & Levers'!$C$22*0.1 | K18: =K5*'Assumptions & Levers'!$C$22*0.1 | ... M18: =M5*'Assumptions & Levers'!$C$22*0.1 | N18: =SUM(D18:M18)
A19: OPEX | B19: Tower Lease (incl DC & Passive O&M) | C19: USD | D19: =D5*'Assumptions & Levers'!$C$31*12/'Assumptions & Levers'!$C$5 | E19: =E5*'Assumptions & Levers'!$C$31*12/'Assumptions & Levers'!$C$5 | F19: =F5*'Assumptions & Levers'!$C$31*12/'Assumptions & Levers'!$C$5 | G19: =G5*'Assumptions & Levers'!$C$31*12/'Assumptions & Levers'!$C$5 | H19: =H5*'Assumptions & Levers'!$C$31*12/'Assumptions & Levers'!$C$5 | I19: =I5*'Assumptions & Levers'!$C$31*12/'Assumptions & Levers'!$C$5 | J19: =J5*'Assumptions & Levers'!$C$31*12/'Assumptions & Levers'!$C$5 | K19: =K5*'Assumptions & Levers'!$C$31*12/'Assumptions & Levers'!$C$5 | ... M19: =M5*'Assumptions & Levers'!$C$31*12/'Assumptions & Levers'!$C$5 | N19: =SUM(D19:M19)
A20: OPEX | B20: Land Lease & Compound Security | C20: USD | D20: 0 | E20: 0 | F20: 0 | G20: 0 | H20: 0 | I20: 0 | J20: 0 | K20: 0 | L20: 0 | M20: 0 | N20: =SUM(D20:M20)
A21: OPEX | B21: Electricity & Power Utility | C21: USD | D21: =D5*'Assumptions & Levers'!$C$35*12/'Assumptions & Levers'!$C$5 | E21: =E5*'Assumptions & Levers'!$C$35*12/'Assumptions & Levers'!$C$5 | F21: =F5*'Assumptions & Levers'!$C$35*12/'Assumptions & Levers'!$C$5 | G21: =G5*'Assumptions & Levers'!$C$35*12/'Assumptions & Levers'!$C$5 | H21: =H5*'Assumptions & Levers'!$C$35*12/'Assumptions & Levers'!$C$5 | I21: =I5*'Assumptions & Levers'!$C$35*12/'Assumptions & Levers'!$C$5 | J21: =J5*'Assumptions & Levers'!$C$35*12/'Assumptions & Levers'!$C$5 | K21: =K5*'Assumptions & Levers'!$C$35*12/'Assumptions & Levers'!$C$5 | ... M21: =M5*'Assumptions & Levers'!$C$35*12/'Assumptions & Levers'!$C$5 | N21: =SUM(D21:M21)
A22: OPEX | B22: Telecom Active O&M Services | C22: USD | D22: =D5*'Assumptions & Levers'!$C$36*12/'Assumptions & Levers'!$C$5 | E22: =E5*'Assumptions & Levers'!$C$36*12/'Assumptions & Levers'!$C$5 | F22: =F5*'Assumptions & Levers'!$C$36*12/'Assumptions & Levers'!$C$5 | G22: =G5*'Assumptions & Levers'!$C$36*12/'Assumptions & Levers'!$C$5 | H22: =H5*'Assumptions & Levers'!$C$36*12/'Assumptions & Levers'!$C$5 | I22: =I5*'Assumptions & Levers'!$C$36*12/'Assumptions & Levers'!$C$5 | J22: =J5*'Assumptions & Levers'!$C$36*12/'Assumptions & Levers'!$C$5 | K22: =K5*'Assumptions & Levers'!$C$36*12/'Assumptions & Levers'!$C$5 | ... M22: =M5*'Assumptions & Levers'!$C$36*12/'Assumptions & Levers'!$C$5 | N22: =SUM(D22:M22)
A23: OPEX | B23: FOC Leased Fiber Transmission | C23: USD | D23: =D5*'Assumptions & Levers'!$C$37*12/'Assumptions & Levers'!$C$5 | E23: =E5*'Assumptions & Levers'!$C$37*12/'Assumptions & Levers'!$C$5 | F23: =F5*'Assumptions & Levers'!$C$37*12/'Assumptions & Levers'!$C$5 | G23: =G5*'Assumptions & Levers'!$C$37*12/'Assumptions & Levers'!$C$5 | H23: =H5*'Assumptions & Levers'!$C$37*12/'Assumptions & Levers'!$C$5 | I23: =I5*'Assumptions & Levers'!$C$37*12/'Assumptions & Levers'!$C$5 | J23: =J5*'Assumptions & Levers'!$C$37*12/'Assumptions & Levers'!$C$5 | K23: =K5*'Assumptions & Levers'!$C$37*12/'Assumptions & Levers'!$C$5 | ... M23: =M5*'Assumptions & Levers'!$C$37*12/'Assumptions & Levers'!$C$5 | N23: =SUM(D23:M23)
A24: OPEX | B24: National IP Transit & Core Peering | C24: USD | D24: ='Assumptions & Levers'!$C$43 | E24: ='Assumptions & Levers'!$C$43 | F24: ='Assumptions & Levers'!$C$43 | G24: ='Assumptions & Levers'!$C$43 | H24: ='Assumptions & Levers'!$C$43 | I24: ='Assumptions & Levers'!$C$43 | J24: ='Assumptions & Levers'!$C$43 | K24: ='Assumptions & Levers'!$C$43 | ... M24: ='Assumptions & Levers'!$C$43 | N24: =SUM(D24:M24)
A25: OPEX | B25: CPE Support & Device Maintenance | C25: USD | D25: =D7*'Assumptions & Levers'!$C$27*0.03 | E25: =E7*'Assumptions & Levers'!$C$27*0.03 | F25: =F7*'Assumptions & Levers'!$C$27*0.03 | G25: =G7*'Assumptions & Levers'!$C$27*0.03 | H25: =H7*'Assumptions & Levers'!$C$27*0.03 | I25: =I7*'Assumptions & Levers'!$C$27*0.03 | J25: =J7*'Assumptions & Levers'!$C$27*0.03 | K25: =K7*'Assumptions & Levers'!$C$27*0.03 | ... M25: =M7*'Assumptions & Levers'!$C$27*0.03 | N25: =SUM(D25:M25)
A26: OPEX | B26: 5G Core & OSS/BSS Annual AMC/Support | C26: USD | D26: ='Assumptions & Levers'!$C$61 | E26: ='Assumptions & Levers'!$C$61 + SUM($E$37:E37)*'Assumptions & Levers'!$C$62 | F26: ='Assumptions & Levers'!$C$61 + SUM($E$37:F37)*'Assumptions & Levers'!$C$62 | G26: ='Assumptions & Levers'!$C$61 + SUM($E$37:G37)*'Assumptions & Levers'!$C$62 | H26: ='Assumptions & Levers'!$C$61 + SUM($E$37:H37)*'Assumptions & Levers'!$C$62 | I26: ='Assumptions & Levers'!$C$61 + SUM($E$37:I37)*'Assumptions & Levers'!$C$62 | J26: ='Assumptions & Levers'!$C$61 + SUM($E$37:J37)*'Assumptions & Levers'!$C$62 | K26: ='Assumptions & Levers'!$C$61 + SUM($E$37:K37)*'Assumptions & Levers'!$C$62 | L26: ='Assumptions & Levers'!$C$61 + SUM($E$37:L37)*'Assumptions & Levers'!$C$62 | M26: ='Assumptions & Levers'!$C$61 + SUM($E$37:M37)*'Assumptions & Levers'!$C$62 | N26: =SUM(D26:M26)
A27: OPEX | B27: Spectrum User Fees (SUF) | C27: USD | D27: ='Assumptions & Levers'!$C$46/'Assumptions & Levers'!$C$5 | E27: ='Assumptions & Levers'!$C$46/'Assumptions & Levers'!$C$5 | F27: ='Assumptions & Levers'!$C$46/'Assumptions & Levers'!$C$5 | G27: ='Assumptions & Levers'!$C$46/'Assumptions & Levers'!$C$5 | H27: ='Assumptions & Levers'!$C$46/'Assumptions & Levers'!$C$5 | I27: ='Assumptions & Levers'!$C$46/'Assumptions & Levers'!$C$5 | J27: ='Assumptions & Levers'!$C$46/'Assumptions & Levers'!$C$5 | K27: ='Assumptions & Levers'!$C$46/'Assumptions & Levers'!$C$5 | ... M27: ='Assumptions & Levers'!$C$46/'Assumptions & Levers'!$C$5 | N27: =SUM(D27:M27)
A28: OPEX | B28: NTC Station Licensing & Inspections | C28: USD | D28: =D5*'Assumptions & Levers'!$C$48/'Assumptions & Levers'!$C$5 | E28: =E5*'Assumptions & Levers'!$C$48/'Assumptions & Levers'!$C$5 | F28: =F5*'Assumptions & Levers'!$C$48/'Assumptions & Levers'!$C$5 | G28: =G5*'Assumptions & Levers'!$C$48/'Assumptions & Levers'!$C$5 | H28: =H5*'Assumptions & Levers'!$C$48/'Assumptions & Levers'!$C$5 | I28: =I5*'Assumptions & Levers'!$C$48/'Assumptions & Levers'!$C$5 | J28: =J5*'Assumptions & Levers'!$C$48/'Assumptions & Levers'!$C$5 | K28: =K5*'Assumptions & Levers'!$C$48/'Assumptions & Levers'!$C$5 | ... M28: =M5*'Assumptions & Levers'!$C$48/'Assumptions & Levers'!$C$5 | N28: =SUM(D28:M28)
A29: OPEX | B29: TOTAL OPEX | C29: USD | D29: =SUM(D18:D28) | E29: =SUM(E18:E28) | F29: =SUM(F18:F28) | G29: =SUM(G18:G28) | H29: =SUM(H18:H28) | I29: =SUM(I18:I28) | J29: =SUM(J18:J28) | K29: =SUM(K18:K28) | ... N29: =SUM(N18:N28)
A31: Profitability | B31: EBITDA | C31: USD | D31: =D16-D29 | E31: =E16-E29 | F31: =F16-F29 | G31: =G16-G29 | H31: =H16-H29 | I31: =I16-I29 | J31: =J16-J29 | K31: =K16-K29 | ... N31: =N16-N29
A32: Profitability | B32: EBITDA Margin (%) | C32: % | D32: =IFERROR(D31/D16, 0) | E32: =IFERROR(E31/E16, 0) | F32: =IFERROR(F31/F16, 0) | G32: =IFERROR(G31/G16, 0) | H32: =IFERROR(H31/H16, 0) | I32: =IFERROR(I31/I16, 0) | J32: =IFERROR(J31/J16, 0) | K32: =IFERROR(K31/K16, 0) | ... N32: =IFERROR(N31/N16, 0)
A34: CAPEX (Incurred) | B34: RAN BTS Equipment & Services | C34: USD | D34: =D6*('Assumptions & Levers'!$C$22 + 'Assumptions & Levers'!$C$23) | E34: =E6*('Assumptions & Levers'!$C$22 + 'Assumptions & Levers'!$C$23) | F34: =F6*('Assumptions & Levers'!$C$22 + 'Assumptions & Levers'!$C$23) | G34: =G6*('Assumptions & Levers'!$C$22 + 'Assumptions & Levers'!$C$23) | H34: =H6*('Assumptions & Levers'!$C$22 + 'Assumptions & Levers'!$C$23) | I34: =I6*('Assumptions & Levers'!$C$22 + 'Assumptions & Levers'!$C$23) | J34: =J6*('Assumptions & Levers'!$C$22 + 'Assumptions & Levers'!$C$23) | K34: =K6*('Assumptions & Levers'!$C$22 + 'Assumptions & Levers'!$C$23) | ... M34: =M6*('Assumptions & Levers'!$C$22 + 'Assumptions & Levers'!$C$23) | N34: =SUM(D34:M34)
A35: CAPEX (Incurred) | B35: Tower Civil Works, Genset & DC Plant | C35: USD | D35: 0 | E35: 0 | F35: 0 | G35: 0 | H35: 0 | I35: 0 | J35: 0 | K35: 0 | L35: 0 | M35: 0 | N35: =SUM(D35:M35)
A36: CAPEX (Incurred) | B36: Backhaul Infrastructure Hardware | C36: USD | D36: 0 | E36: 0 | F36: 0 | G36: 0 | H36: 0 | I36: 0 | J36: 0 | K36: 0 | L36: 0 | M36: 0 | N36: =SUM(D36:M36)
A37: CAPEX (Incurred) | B37: 5G Core HW/SW & OSS/BSS Platform | C37: USD | D37: ='Assumptions & Levers'!$C$24 + 'Assumptions & Levers'!$C$25 + 'Assumptions & Levers'!$C$26 | E37: =E6*'Assumptions & Levers'!$C$60 | F37: =F6*'Assumptions & Levers'!$C$60 | G37: =G6*'Assumptions & Levers'!$C$60 | H37: =H6*'Assumptions & Levers'!$C$60 | I37: =I6*'Assumptions & Levers'!$C$60 | J37: =J6*'Assumptions & Levers'!$C$60 | K37: =K6*'Assumptions & Levers'!$C$60 | L37: =L6*'Assumptions & Levers'!$C$60 | M37: =M6*'Assumptions & Levers'!$C$60 | N37: =SUM(D37:M37)
A38: CAPEX (Incurred) | B38: CPE Customer Devices | C38: USD | D38: =D11*'Assumptions & Levers'!$C$27 | E38: =E11*'Assumptions & Levers'!$C$27 | F38: =F11*'Assumptions & Levers'!$C$27 | G38: =G11*'Assumptions & Levers'!$C$27 | H38: =H11*'Assumptions & Levers'!$C$27 | I38: =I11*'Assumptions & Levers'!$C$27 | J38: =J11*'Assumptions & Levers'!$C$27 | K38: =K11*'Assumptions & Levers'!$C$27 | ... M38: =M11*'Assumptions & Levers'!$C$27 | N38: =SUM(D38:M38)
A39: CAPEX (Incurred) | B39: TOTAL CAPEX (INCURRED) | C39: USD | D39: =SUM(D34:D38) | E39: =SUM(E34:E38) | F39: =SUM(F34:F38) | G39: =SUM(G34:G38) | H39: =SUM(H34:H38) | I39: =SUM(I34:I38) | J39: =SUM(J34:J38) | K39: =SUM(K34:K38) | ... N39: =SUM(N34:N38)
A41: Cash Outflows | B41: Equipment Vendor Financing Down Payment (20%) | C41: USD | D41: =(D34+D36+D37)*'Assumptions & Levers'!$C$49 | E41: =(E34+E36+E37)*'Assumptions & Levers'!$C$49 | F41: =(F34+F36+F37)*'Assumptions & Levers'!$C$49 | G41: =(G34+G36+G37)*'Assumptions & Levers'!$C$49 | H41: =(H34+H36+H37)*'Assumptions & Levers'!$C$49 | I41: =(I34+I36+I37)*'Assumptions & Levers'!$C$49 | J41: =(J34+J36+J37)*'Assumptions & Levers'!$C$49 | K41: =(K34+K36+K37)*'Assumptions & Levers'!$C$49 | ... M41: =(M34+M36+M37)*'Assumptions & Levers'!$C$49 | N41: =SUM(D41:M41)
A42: Cash Outflows | B42: Civil Works & CPE Cash Capex (100% Upfront) | C42: USD | D42: =D35+D38 | E42: =E35+E38 | F42: =F35+F38 | G42: =G35+G38 | H42: =H35+H38 | I42: =I35+I38 | J42: =J35+J38 | K42: =K35+K38 | ... M42: =M35+M38 | N42: =SUM(D42:M42)
A43: Cash Outflows | B43: Financed Equipment Principal Amortization | C43: USD | D43: 0 | E43: =D41 | F43: =D41+E41 | G43: =D41+E41+F41 | H43: =D41+E41+F41+G41 | I43: =E41+F41+G41+H41 | J43: =F41+G41+H41+I41 | K43: =G41+H41+I41+J41 | L43: =H41+I41+J41+K41 | M43: =I41+J41+K41+L41 | N43: =SUM(D43:M43)
A44: Cash Outflows | B44: Financing Interest Expense | C44: USD | D44: 0 | E44: =(D41 * 4) * 'Assumptions & Levers'!$C$52 | F44: =((D41+E41)*4 - E43) * 'Assumptions & Levers'!$C$52 | G44: =((D41+E41+F41)*4 - (E43+F43)) * 'Assumptions & Levers'!$C$52 | H44: =((D41+E41+F41+G41)*4 - (E43+F43+G43)) * 'Assumptions & Levers'!$C$52 | I44: =((E41+F41+G41+H41)*4 - (F43+G43+H43)) * 'Assumptions & Levers'!$C$52 | J44: =((F41+G41+H41+I41)*4 - (G43+H43+I43)) * 'Assumptions & Levers'!$C$52 | K44: =((G41+H41+I41+J41)*4 - (H43+I43+J43)) * 'Assumptions & Levers'!$C$52 | L44: =((H41+I41+J41+K41)*4 - (I43+J43+K43)) * 'Assumptions & Levers'!$C$52 | M44: =((I41+J41+K41+L41)*4 - (J43+K43+L43)) * 'Assumptions & Levers'!$C$52 | N44: =SUM(D44:M44)
A45: Cash Outflows | B45: TOTAL CASH CAPITAL OUTFLOW (DEBT SERVICE + CAPEX) | C45: USD | D45: =D41+D42+D43+D44 | E45: =E41+E42+E43+E44 | F45: =F41+F42+F43+F44 | G45: =G41+G42+G43+G44 | H45: =H41+H42+H43+H44 | I45: =I41+I42+I43+I44 | J45: =J41+J42+J43+J44 | K45: =K41+K42+K43+K44 | ... N45: =N41+N42+N43+N44
A47: Depreciation | B47: Depreciation: RAN, Core & Backhaul (7 Yrs) | C47: USD | D47: =(D34+D36+D37)/'Assumptions & Levers'!$C$54 | E47: =(D34+D36+D37 + E34+E36+E37)/'Assumptions & Levers'!$C$54 | F47: =(SUM(D34:F34) + SUM(D36:F36) + SUM(D37:F37))/'Assumptions & Levers'!$C$54 | G47: =(SUM(D34:G34) + SUM(D36:G36) + SUM(D37:G37))/'Assumptions & Levers'!$C$54 | H47: =(SUM(D34:H34) + SUM(D36:H36) + SUM(D37:H37))/'Assumptions & Levers'!$C$54 | I47: =(SUM(D34:I34) + SUM(D36:I36) + SUM(D37:I37))/'Assumptions & Levers'!$C$54 | J47: =(SUM(D34:J34) + SUM(D36:J36) + SUM(D37:J37))/'Assumptions & Levers'!$C$54 | K47: =(SUM(E34:K34) + SUM(E36:K36) + SUM(E37:K37))/'Assumptions & Levers'!$C$54 | L47: =(SUM(F34:L34) + SUM(F36:L36) + SUM(F37:L37))/'Assumptions & Levers'!$C$54 | M47: =(SUM(G34:M34) + SUM(G36:M36) + SUM(G37:M37))/'Assumptions & Levers'!$C$54 | N47: =SUM(D47:M47)
...

Sheet S3_Leased_Star_NonDef
A1: Scenario 3: Leased Towers + Starlink Backhaul + Non-Deferred Payment (1,000 Sites Y1)
A2: Footprint: 1,000 Sites in Year 1 (Day-1 Full Build) | Tower: Leased (TowerCo) | Backhaul: Starlink | Payment Terms: Non-Deferred (100% Upfront)
A4: Category | B4: Line Item | C4: Unit | D4: Year 1 | E4: Year 2 | F4: Year 3 | G4: Year 4 | H4: Year 5 | I4: Year 6 | J4: Year 7 | K4: Year 8 | L4: Year 9 | M4: Year 10 | N4: 10-Year Total
A5: Network Rollout | B5: Active Cumulative Sites | C5: sites | D5: ='Assumptions & Levers'!$C$10 | E5: =D5 + 'Assumptions & Levers'!$C$11 | F5: =E5 + 'Assumptions & Levers'!$C$11 | G5: =F5 + 'Assumptions & Levers'!$C$11 | H5: =G5 + 'Assumptions & Levers'!$C$11 | I5: =H5 + 'Assumptions & Levers'!$C$11 | J5: =I5 + 'Assumptions & Levers'!$C$11 | K5: =J5 + 'Assumptions & Levers'!$C$11 | L5: =K5 + 'Assumptions & Levers'!$C$11 | M5: =L5 + 'Assumptions & Levers'!$C$11 | N5: =M5
A6: Network Rollout | B6: New Sites Commissioned | C6: sites | D6: =D5 | E6: =E5 - D5 | F6: =F5 - E5 | G6: =G5 - F5 | H6: =H5 - G5 | I6: =I5 - H5 | J6: =J5 - I5 | K6: =K5 - J5 | L6: =L5 - K5 | M6: =M5 - L5 | N6: =SUM(D6:M6)
A7: Subscribers | B7: Closing Active Subscribers | C7: subs | D7: =D5*'Assumptions & Levers'!$C$12 * IF('Assumptions & Levers'!$C$57=3, 1, IF('Assumptions & Levers'!$C$57=2, 0.5, 0.25)) | E7: =E5*'Assumptions & Levers'!$C$12 * IF('Assumptions & Levers'!$C$57=3, 1, IF('Assumptions & Levers'!$C$57=2, 0.8, 0.5)) | F7: =F5*'Assumptions & Levers'!$C$12 * IF('Assumptions & Levers'!$C$57=3, 1, IF('Assumptions & Levers'!$C$57=2, 1, 0.75)) | G7: =G5*'Assumptions & Levers'!$C$12 * IF('Assumptions & Levers'!$C$57=3, 1, IF('Assumptions & Levers'!$C$57=2, 1, 0.9)) | H7: =H5*'Assumptions & Levers'!$C$12 * 1 | I7: =I5*'Assumptions & Levers'!$C$12 * 1 | J7: =J5*'Assumptions & Levers'!$C$12 * 1 | K7: =K5*'Assumptions & Levers'!$C$12 * 1 | L7: =L5*'Assumptions & Levers'!$C$12 * 1 | M7: =M5*'Assumptions & Levers'!$C$12 * 1 | N7: =M7
