Workbook

Sheet Read Me
A1: Philippine 5G FWA Barangay Rollout Plan — Band n50 Dimensioning & Site Prioritization Model
A2: Dynamic Production Release 2.0 | Live Formula Edition | Option A Architecture | 1,000 Subscribers per BTS Total
A4: 1. EXECUTIVE OVERVIEW & CORE TELECOM SPECIFICATIONS
A5: Parameter | B5: Technical Specification | C5: Operational Description
A6: Spectrum Carrier | B6: Band n50 (1432–1517 MHz, 1.5 GHz L-Band TDD) | C6: Primary sub-2 GHz FWA coverage carrier offering superior indoor penetration and 2.5–3.5 km rural cell radius.
A7: Carrier Bandwidth | B7: 60 MHz Contiguous TDD | C7: Delivers 499 Mbps aggregate DL capacity per BTS (planning SE = 4.5 bps/Hz, 70% DL frame split).
A8: Radio Configuration | B8: 3 Sectors @ 4T4R MIMO AAUs + Distributed BBU | C8: Standard 3-sector macro deployment (~120° azimuth per sector) with 256-QAM and multi-user MIMO.
A9: Design Subscriber Load | B9: 1,000 Subscribers per BTS Total | C9: Dimensioned for ~333 active subscribers per sector, sustaining 15–25 Mbps busy-hour bursts with high QoE.
A10: Target Take-Rate | B10: 30% Addressable Households | C10: Standard commercial adoption ceiling within target barangay catchments.
A11: Optical Backhaul Anchor | B11: Converge ICT Backbone Infrastructure | C11: Anchored on Converge's 2,405 active backbone nodes and 334,462 fiber line vertices.
A13: 2. WORKBOOK DIRECTORY & TAB NAVIGATION GUIDE
A14: Tab Name | B14: Tab Index | C14: Contents & Operational Purpose
A15: Read Me | B15: Sheet 1 (Active) | C15: Executive overview, Option A architecture, methodology, and exhaustive data dictionary defining all headers.
A16: Executive Summary | B16: Sheet 2 | C16: High-level rollout comparison across Batches 1 to 5, key performance indicators, single-digit reconciled stats.
A17: Methodology & Assumptions | B17: Sheet 3 | C17: Mathematical scoring formulas, weights, distance decay parameters, sweet spot definitions, and penalties.
A18: Batch 1 (First 1,000) | B18: Sheet 4 | C18: Phase 1 priority launch sites (Rank 1 to 1,000) with complete 25-column production schema.
A19: Batch 2 (1,001 - 2,000) | B19: Sheet 5 | C19: Phase 2 expansion sites (Rank 1,001 to 2,000) with complete 25-column production schema.
A20: Batch 3 (2,001 - 3,000) | B20: Sheet 6 | C20: Phase 3 expansion sites (Rank 2,001 to 3,000) with complete 25-column production schema.
A21: Batch 4 & 5 (3,001 - 5,000) | B21: Sheet 7 | C21: Phase 4 & 5 nationwide rural expansion sites (Rank 3,001 to 5,000) with complete 25-column production schema.
A22: Provincial Summary | B22: Sheet 8 | C22: Breakdown of barangay counts, population reach, and total n50 BTS capacity by Province across all 5 phases.
A24: 3. OPTION A ARCHITECTURAL FRAMEWORK: DAY 1 BUILD VS. PEAK DEMAND CAPACITY
A25: Architectural Concept | B25: Metric / Scope | C25: Telecom Engineering & Operational Implementation
A26: Initial Day 1 Build (BTS) | B26: 1,000 BTS per Batch / 5,000 BTS Total | C26: CAPEX Deployment: Exactly 1 BTS installed per priority barangay on Day 1 to establish immediate market presence, fast time-to-market, and initial coverage without speculative overbuilding.
A27: Peak 30% Demand Capacity (BTS) | B27: 1,143 BTS in Batch 1 / 5,559 BTS Total | C27: Theoretical Market Ceiling: Total radio capacity required if full 30% household penetration is reached (@ 1,000 subs/BTS). In Batch 1, 903 barangays need 1 BTS, 72 need 2 BTS, 14 need 3 BTS, and 11 need 4+ BTS.
A28: Capacity Upgrade (Same Tower) | B28: 2nd Carrier / Sector Split (3 to 6 Sectors) | C28: In dense/compact barangays, adding a 2nd BTS means adding a second radio carrier OR splitting sectors on the existing mast. Uses existing tower, fiber drop, and power meter. Requires ZERO land acquisition and ZERO civil works (CW).
A29: Coverage Upgrade (Dispersed Sitios) | B29: 2nd Physical Tower / Co-location Site | C29: In large rural barangays (20-40 km²) where settlements are 5-8 km apart, radio propagation requires a second physical tower site or TowerCo co-location in the separate distant sitio.
A31: 4. THE THREE CORE SELECTION PILLARS (SCORING ENGINE)
A32: Pillar Name | B32: Weight | C32: Core Objective | D32: Algorithmic Definition & Scoring Mechanics
A33: Pillar 1: Necessity | B33: 30% Weight | C33: Direct Broadband Deficit & Lack of Internet Service | D33: Evaluates lack of commercial wireline FTTH/cable. PSA Rural ('R') status receives 85 pts; off-net municipalities receive 100 pts; 4th-6th class income towns receive up to 90 pts; heavily penalizes saturated metro FTTH markets like NCR (-20 pts).
A34: Pillar 2: Business Viability | B34: 35% Weight | C34: Economic Activity to Generate Sales & Rapid Payback | D34: Evaluates household density and ability to sustain recurring retail plans (₱599-₱999/mo). Full 100% score awarded for demand between 300 and 1,000 target subscribers (sweet spot for 1-BTS amortization with 14-22 mo payback), with municipal income class purchasing power multipliers.
A35: Pillar 3: Ease of Deployment | B35: 35% Weight | C35: Tower Erection, Right-of-Way, Fiber & Power Proximity | D35: Evaluates physical buildability. Based on true great-circle Haversine distance to Converge's 2,405 nodes (100 * exp(-d / 3.0)), fiber line corridor bonus (+10 pts within 2 km), commercial 220V power grid reliability, and existing TowerCo assets.
A37: 5. DATA DICTIONARY: EXHAUSTIVE DEFINITION OF ALL 25 BATCH SHEET HEADERS
A38: Col | B38: Header Name | C38: Data Type | D38: Primary Source | E38: Detailed Operational & Engineering Definition
A39: A | B39: Batch Rank | C39: Integer (1 - 1,000) | D39: Ranking Engine | E39: Sequential priority ranking (1 to 1,000) within the specific batch, sorted strictly by Composite Score descending.
A40: B | B40: Overall Rank | C40: Integer (1 - 5,000) | D40: Ranking Engine | E40: National commercial priority rank across all 41,976 evaluated Philippine barangays.
A41: C | B41: PSGC Code | C41: Text (9-10 digits) | D41: PSA 2020 CPH | E41: Official Philippine Standard Geographic Code uniquely identifying the administrative barangay entity.
A42: D | B42: Region | C42: Text | D42: PSA / NEDA | E42: Administrative Region of the Philippines (e.g., Region IV-A CALABARZON, Region III Central Luzon, Region VII Central Visayas).
A43: E | B43: Province | C43: Text | D43: PSA / DILG | E43: Province name under which the municipality and barangay are administratively governed.
A44: F | B44: Municipality | C44: Text | D44: PSA / DILG | E44: City or Municipality administrative entity.
A45: G | B45: Barangay | C45: Text | D45: PSA / DILG | E45: Official name of the barangay (primary administrative and operational unit for FWA BTS siting).
...

Sheet Executive Summary
A1: Philippine FWA Rollout — Band n50 Dynamic Dimensioning & Executive Model
A2: Fully dynamic executive comparison across 5 phases. All metrics recalculate live when parameters are updated in 'Methodology & Assumptions'.
A5: PHASE 1 BTS DEPLOYED | C5: POPULATION REACHED | E5: ADDRESSABLE HOUSEHOLDS | G5: TARGET SUBS @ 30% | I5: RURAL CATCHMENTS | K5: FIBER PROXIMITY (<3KM)
A6: =C11 | C6: =E11 | E6: =F11 | G6: =G11 | I6: 554 (55.4%) | K6: 1000 (100.0%)
A7: 1 BTS / Priority Barangay | C7: PSA 2020 Census (Batch 1) | E7: DOF / Provincial HH Multipliers | G7: Avg 480 subs/site (Runway to 1k) | I7: PSA 2020 Classification | K7: Direct Optical Backhaul
A9: ROLLOUT BATCH COMPARISON (5,000 BARANGAYS ACROSS 5 PHASES)
A10: Rollout Phase | B10: Barangays | C10: Initial Day 1 Build (BTS) | D10: Peak 30% Demand Capacity (BTS) | E10: Population | F10: Households | G10: Subs @ 30% | H10: Rural % | I10: Avg Distance to Node (km) | J10: Avg Deploy Score | K10: Avg Viability | L10: Avg Necessity | M10: Avg Composite Score
A11: Batch 1 (Phase 1) | B11: =COUNT('Batch 1 (First 1,000)'!A5:A1004) | C11: =SUM('Batch 1 (First 1,000)'!R5:R1004) | D11: =SUM('Batch 1 (First 1,000)'!Q5:Q1004) | E11: =SUM('Batch 1 (First 1,000)'!L5:L1004) | F11: =SUM('Batch 1 (First 1,000)'!N5:N1004) | G11: =SUM('Batch 1 (First 1,000)'!O5:O1004) | H11: =COUNTIF('Batch 1 (First 1,000)'!J5:J1004, "R")/B11 | I11: =AVERAGE('Batch 1 (First 1,000)'!S5:S1004) | J11: =AVERAGE('Batch 1 (First 1,000)'!V5:V1004) | K11: =AVERAGE('Batch 1 (First 1,000)'!W5:W1004) | L11: =AVERAGE('Batch 1 (First 1,000)'!X5:X1004) | M11: =AVERAGE('Batch 1 (First 1,000)'!Y5:Y1004)
A12: Batch 2 (Phase 2) | B12: =COUNT('Batch 2 (1,001 - 2,000)'!A5:A1004) | C12: =SUM('Batch 2 (1,001 - 2,000)'!R5:R1004) | D12: =SUM('Batch 2 (1,001 - 2,000)'!Q5:Q1004) | E12: =SUM('Batch 2 (1,001 - 2,000)'!L5:L1004) | F12: =SUM('Batch 2 (1,001 - 2,000)'!N5:N1004) | G12: =SUM('Batch 2 (1,001 - 2,000)'!O5:O1004) | H12: =COUNTIF('Batch 2 (1,001 - 2,000)'!J5:J1004, "R")/B12 | I12: =AVERAGE('Batch 2 (1,001 - 2,000)'!S5:S1004) | J12: =AVERAGE('Batch 2 (1,001 - 2,000)'!V5:V1004) | K12: =AVERAGE('Batch 2 (1,001 - 2,000)'!W5:W1004) | L12: =AVERAGE('Batch 2 (1,001 - 2,000)'!X5:X1004) | M12: =AVERAGE('Batch 2 (1,001 - 2,000)'!Y5:Y1004)
A13: Batch 3 (Phase 3) | B13: =COUNT('Batch 3 (2,001 - 3,000)'!A5:A1004) | C13: =SUM('Batch 3 (2,001 - 3,000)'!R5:R1004) | D13: =SUM('Batch 3 (2,001 - 3,000)'!Q5:Q1004) | E13: =SUM('Batch 3 (2,001 - 3,000)'!L5:L1004) | F13: =SUM('Batch 3 (2,001 - 3,000)'!N5:N1004) | G13: =SUM('Batch 3 (2,001 - 3,000)'!O5:O1004) | H13: =COUNTIF('Batch 3 (2,001 - 3,000)'!J5:J1004, "R")/B13 | I13: =AVERAGE('Batch 3 (2,001 - 3,000)'!S5:S1004) | J13: =AVERAGE('Batch 3 (2,001 - 3,000)'!V5:V1004) | K13: =AVERAGE('Batch 3 (2,001 - 3,000)'!W5:W1004) | L13: =AVERAGE('Batch 3 (2,001 - 3,000)'!X5:X1004) | M13: =AVERAGE('Batch 3 (2,001 - 3,000)'!Y5:Y1004)
A14: Batch 4 (Phase 4) | B14: =COUNT('Batch 4 & 5 (3,001 - 5,000)'!A5:A1004) | C14: =SUM('Batch 4 & 5 (3,001 - 5,000)'!R5:R1004) | D14: =SUM('Batch 4 & 5 (3,001 - 5,000)'!Q5:Q1004) | E14: =SUM('Batch 4 & 5 (3,001 - 5,000)'!L5:L1004) | F14: =SUM('Batch 4 & 5 (3,001 - 5,000)'!N5:N1004) | G14: =SUM('Batch 4 & 5 (3,001 - 5,000)'!O5:O1004) | H14: =COUNTIF('Batch 4 & 5 (3,001 - 5,000)'!J5:J1004, "R")/B14 | I14: =AVERAGE('Batch 4 & 5 (3,001 - 5,000)'!S5:S1004) | J14: =AVERAGE('Batch 4 & 5 (3,001 - 5,000)'!V5:V1004) | K14: =AVERAGE('Batch 4 & 5 (3,001 - 5,000)'!W5:W1004) | L14: =AVERAGE('Batch 4 & 5 (3,001 - 5,000)'!X5:X1004) | M14: =AVERAGE('Batch 4 & 5 (3,001 - 5,000)'!Y5:Y1004)
A15: Batch 5 (Phase 5) | B15: =COUNT('Batch 4 & 5 (3,001 - 5,000)'!A1005:A2004) | C15: =SUM('Batch 4 & 5 (3,001 - 5,000)'!R1005:R2004) | D15: =SUM('Batch 4 & 5 (3,001 - 5,000)'!Q1005:Q2004) | E15: =SUM('Batch 4 & 5 (3,001 - 5,000)'!L1005:L2004) | F15: =SUM('Batch 4 & 5 (3,001 - 5,000)'!N1005:N2004) | G15: =SUM('Batch 4 & 5 (3,001 - 5,000)'!O1005:O2004) | H15: =COUNTIF('Batch 4 & 5 (3,001 - 5,000)'!J1005:J2004, "R")/B15 | I15: =AVERAGE('Batch 4 & 5 (3,001 - 5,000)'!S1005:S2004) | J15: =AVERAGE('Batch 4 & 5 (3,001 - 5,000)'!V1005:V2004) | K15: =AVERAGE('Batch 4 & 5 (3,001 - 5,000)'!W1005:W2004) | L15: =AVERAGE('Batch 4 & 5 (3,001 - 5,000)'!X1005:X2004) | M15: =AVERAGE('Batch 4 & 5 (3,001 - 5,000)'!Y1005:Y2004)
A16: TOTAL (Batches 1 - 5) | B16: =SUM(B11:B15) | C16: =SUM(C11:C15) | D16: =SUM(D11:D15) | E16: =SUM(E11:E15) | F16: =SUM(F11:F15) | G16: =SUM(G11:G15) | H16: =(COUNTIF('Batch 1 (First 1,000)'!J5:J1004, "R")+COUNTIF('Batch 2 (1,001 - 2,000)'!J5:J1004, "R")+COUNTIF('Batch 3 (2,001 - 3,000)'!J5:J1004, "R")+COUNTIF('Batch 4 & 5 (3,001 - 5,000)'!J5:J2004, "R"))/B16 | I16: =AVERAGE(I11:I15) | J16: =AVERAGE(J11:J15) | K16: =AVERAGE(K11:K15) | L16: =AVERAGE(L11:L15) | M16: =AVERAGE(M11:M15)
A18: Operational Note on BTS Metrics: 'Initial Day 1 Build' represents the immediate CAPEX rollout (1 BTS per priority barangay) to secure territory without overbuilding. 'Peak 30% Demand Capacity' represents the total subscriber absorption potential (at 1,000 subs/BTS) if full 30% household penetration is reached, unlocking organic expansion BTS on existing site footprints without new land acquisition.

Sheet Methodology & Assumptions
A1: Dynamic FWA Model Parameters & Sensitivity Inputs (Editable)
A2: Changes to any parameter below immediately and dynamically recalculate all batch sheets and executive summary tables.
A4: Parameter | B4: Dynamic Input Value | C4: Unit / Format | D4: Sensitivity Guidance & Operational Rationale
A5: Viability Weight | B5: 0.35 | C5: % Weight | D5: Commercial demand density and retail sales velocity (range: 25% - 45%).
A6: Deployment Ease Weight | B6: 0.35 | C6: % Weight | D6: Point-to-point physical proximity to Converge nodes & fiber lines (range: 25% - 45%).
A7: Necessity Weight | B7: 0.3 | C7: % Weight | D7: Lack of commercial internet service and rural broadband deficit (range: 20% - 40%).
A8: Penetration Rate | B8: 0.3 | C8: % Take-Rate | D8: Commercial target penetration of addressable households (range: 15% - 50%).
A9: n50 BTS Capacity | B9: 1000 | C9: Subs / BTS | D9: 3-sector 4T4R macro BTS subscriber design limit (~333 subs/sector; range: 600 - 1,200).
A10: Viability Sweet Spot Low | B10: 300 | C10: Min Subs | D10: Minimum target subscribers for efficient 1-BTS amortization with high ROI.
A11: Viability Sweet Spot High | B11: 1000 | C11: Max Subs | D11: Maximum subscriber capacity for 1 BTS (scores 100% viability).
A12: Deploy Decay Factor | B12: 3 | C12: km | D12: Distance decay constant: score = 100 * exp(-dist / 3.0).
A13: Fiber Corridor Radius | B13: 2 | C13: km | D13: Bonus threshold: +10 pts if within 2.0 km of a backbone fiber line.
A14: NCR Metro Penalty | B14: -20 | C14: pts | D14: Heavy FTTH wireline incumbent saturation penalty.
A15: BARMM Risk Adjustment | B15: -10 | C15: pts | D15: Early-phase operational deployment risk adjustment.
A17: 💡 Quick Tip: Yellow-highlighted cells in Column B are live inputs. Edit Penetration Rate (B8), BTS Capacity (B9), or Weights (B5:B7) to see instant changes across all sheets.

Sheet Batch 1 (First 1,000)
A1: FWA Rollout Batch 1 — First 1,000 Priority Sites
A2: Dynamic commercial deployment rollout schedule (1,000 sites), linked to live parameters in 'Methodology & Assumptions'.
A4: Batch Rank | B4: Overall Rank | C4: PSGC Code | D4: Region | E4: Province | F4: Municipality | G4: Barangay | H4: Latitude | I4: Longitude | J4: Urban / Rural | K4: Municipal Income Class | L4: 2020 Pop | M4: Avg HH Size | N4: Households | O4: Subs @ 30% | P4: Carrier Spectrum | Q4: Peak 30% Demand Capacity (BTS) | R4: Initial Day 1 Build (BTS) | S4: Dist. to Nearest Node (km) | T4: Dist. to Fiber Line (km) | U4: Deploy Tier | V4: Deploy Score (35%) | W4: Viability Score (35%) | X4: Necessity Score (30%) | Y4: Composite Score
A5: 1 | B5: 1 | C5: 0205705004 | D5: Region II (Cagayan Valley) | E5: Quirino | F5: Saguday | G5: Rizal | H5: 16.544939 | I5: 121.56269 | J5: R | K5: 4th | L5: 3336 | M5: 4.03 | N5: =ROUND(L5/M5, 0) | O5: =ROUND(N5*'Methodology & Assumptions'!$B$8, 0) | P5: Band n50 (1.5 GHz, 60 MHz) | Q5: =ROUNDUP(O5/'Methodology & Assumptions'!$B$9, 0) | R5: 1 | S5: 0.14 | T5: 0.15 | U5: Tier 1A (Direct Coloc, <1 km) | V5: 100 | W5: 90.1 | X5: 83.5 | Y5: =ROUND((V5*'Methodology & Assumptions'!$B$6)+(W5*'Methodology & Assumptions'!$B$5)+(X5*'Methodology & Assumptions'!$B$7), 2)
A6: 2 | B6: 2 | C6: 0603042010 | D6: Region VI (Western Visayas) | E6: Iloilo | F6: San Rafael | G6: Poblacion | H6: 11.178909 | I6: 122.8275 | J6: R | K6: 4th | L6: 4460 | M6: 4.29 | N6: =ROUND(L6/M6, 0) | O6: =ROUND(N6*'Methodology & Assumptions'!$B$8, 0) | P6: Band n50 (1.5 GHz, 60 MHz) | Q6: =ROUNDUP(O6/'Methodology & Assumptions'!$B$9, 0) | R6: 1 | S6: 0.27 | T6: 0.1 | U6: Tier 1A (Direct Coloc, <1 km) | V6: 100 | W6: 100 | X6: 68.5 | Y6: =ROUND((V6*'Methodology & Assumptions'!$B$6)+(W6*'Methodology & Assumptions'!$B$5)+(X6*'Methodology & Assumptions'!$B$7), 2)
A7: 3 | B7: 3 | C7: 1208007005 | D7: Region XII (SOCCSKSARGEN) | E7: Sarangani | F7: Malungon | G7: Banate | H7: 6.475481 | I7: 125.32087 | J7: R | K7: Class 1-3 / Urban | L7: 3944 | M7: 4.1 | N7: =ROUND(L7/M7, 0) | O7: =ROUND(N7*'Methodology & Assumptions'!$B$8, 0) | P7: Band n50 (1.5 GHz, 60 MHz) | Q7: =ROUNDUP(O7/'Methodology & Assumptions'!$B$9, 0) | R7: 1 | S7: 0.47 | T7: 0.06 | U7: Tier 1A (Direct Coloc, <1 km) | V7: 95.6 | W7: 100 | X7: 73 | Y7: =ROUND((V7*'Methodology & Assumptions'!$B$6)+(W7*'Methodology & Assumptions'!$B$5)+(X7*'Methodology & Assumptions'!$B$7), 2)
A8: 4 | B8: 4 | C8: 0403412010 | D8: Region IV-A (CALABARZON) | E8: Laguna | F8: Luisiana | G8: San Antonio | H8: 14.185892 | I8: 121.50672 | J8: R | K8: 4th | L8: 3289 | M8: 4.07 | N8: =ROUND(L8/M8, 0) | O8: =ROUND(N8*'Methodology & Assumptions'!$B$8, 0) | P8: Band n50 (1.5 GHz, 60 MHz) | Q8: =ROUNDUP(O8/'Methodology & Assumptions'!$B$9, 0) | R8: 1 | S8: 0.19 | T8: 4.07 | U8: Tier 1A (Direct Coloc, <1 km) | V8: 93.8 | W8: 88.5 | X8: 83.5 | Y8: =ROUND((V8*'Methodology & Assumptions'!$B$6)+(W8*'Methodology & Assumptions'!$B$5)+(X8*'Methodology & Assumptions'!$B$7), 2)
A9: 5 | B9: 5 | C9: 0504102020 | D9: Region V (Bicol Region) | E9: Masbate | F9: Baleno | G9: Poblacion | H9: 12.474103 | I9: 123.4972 | J9: R | K9: 2nd | L9: 4025 | M9: 4.83 | N9: =ROUND(L9/M9, 0) | O9: =ROUND(N9*'Methodology & Assumptions'!$B$8, 0) | P9: Band n50 (1.5 GHz, 60 MHz) | Q9: =ROUNDUP(O9/'Methodology & Assumptions'!$B$9, 0) | R9: 1 | S9: 0.25 | T9: 0.24 | U9: Tier 1A (Direct Coloc, <1 km) | V9: 100 | W9: 90.7 | X9: 73 | Y9: =ROUND((V9*'Methodology & Assumptions'!$B$6)+(W9*'Methodology & Assumptions'!$B$5)+(X9*'Methodology & Assumptions'!$B$7), 2)
A10: 6 | B10: 6 | C10: 0806408007 | D10: Region VIII (Eastern Visayas) | E10: Southern Leyte | F10: Macrohon | G10: Ichon | H10: 10.10761 | I10: 124.9009 | J10: R | K10: 3rd | L10: 3801 | M10: 4.32 | N10: =ROUND(L10/M10, 0) | O10: =ROUND(N10*'Methodology & Assumptions'!$B$8, 0) | P10: Band n50 (1.5 GHz, 60 MHz) | Q10: =ROUNDUP(O10/'Methodology & Assumptions'!$B$9, 0) | R10: 1 | S10: 0.46 | T10: 0.05 | U10: Tier 1A (Direct Coloc, <1 km) | V10: 95.8 | W10: 94.4 | X10: 73 | Y10: =ROUND((V10*'Methodology & Assumptions'!$B$6)+(W10*'Methodology & Assumptions'!$B$5)+(X10*'Methodology & Assumptions'!$B$7), 2)
A11: 7 | B11: 7 | C11: 1004313008 | D11: Region X (Northern Mindanao) | E11: Misamis Oriental | F11: Lagonglong | G11: Poblacion | H11: 8.806659 | I11: 124.78784 | J11: R | K11: 4th | L11: 4104 | M11: 4.72 | N11: =ROUND(L11/M11, 0) | O11: =ROUND(N11*'Methodology & Assumptions'!$B$8, 0) | P11: Band n50 (1.5 GHz, 60 MHz) | Q11: =ROUNDUP(O11/'Methodology & Assumptions'!$B$9, 0) | R11: 1 | S11: 0.29 | T11: 0.05 | U11: Tier 1A (Direct Coloc, <1 km) | V11: 100 | W11: 93.6 | X11: 68.5 | Y11: =ROUND((V11*'Methodology & Assumptions'!$B$6)+(W11*'Methodology & Assumptions'!$B$5)+(X11*'Methodology & Assumptions'!$B$7), 2)
A12: 8 | B12: 8 | C12: 0501604008 | D12: Region V (Bicol Region) | E12: Camarines Norte | F12: San Lorenzo Ruiz | G12: Matacong | H12: 14.034224 | I12: 122.8629 | J12: R | K12: 5th | L12: 3989 | M12: 4.42 | N12: =ROUND(L12/M12, 0) | O12: =ROUND(N12*'Methodology & Assumptions'!$B$8, 0) | P12: Band n50 (1.5 GHz, 60 MHz) | Q12: =ROUNDUP(O12/'Methodology & Assumptions'!$B$9, 0) | R12: 1 | S12: 0.23 | T12: 7.27 | U12: Tier 1A (Direct Coloc, <1 km) | V12: 92.6 | W12: 96.3 | X12: 73 | Y12: =ROUND((V12*'Methodology & Assumptions'!$B$6)+(W12*'Methodology & Assumptions'!$B$5)+(X12*'Methodology & Assumptions'!$B$7), 2)
A13: 9 | B13: 9 | C13: 0305410001 | D13: Region III (Central Luzon) | E13: Pampanga | F13: Macabebe | G13: Batasan | H13: 14.892725 | I13: 120.71382 | J13: R | K13: Class 1-3 / Urban | L13: 4450 | M13: 4.63 | N13: =ROUND(L13/M13, 0) | O13: =ROUND(N13*'Methodology & Assumptions'!$B$8, 0) | P13: Band n50 (1.5 GHz, 60 MHz) | Q13: =ROUNDUP(O13/'Methodology & Assumptions'!$B$9, 0) | R13: 1 | S13: 0.77 | T13: 1 | U13: Tier 1A (Direct Coloc, <1 km) | V13: 87.3 | W13: 100 | X13: 73 | Y13: =ROUND((V13*'Methodology & Assumptions'!$B$6)+(W13*'Methodology & Assumptions'!$B$5)+(X13*'Methodology & Assumptions'!$B$7), 2)
A14: 10 | B14: 10 | C14: 0405803007 | D14: Region IV-A (CALABARZON) | E14: Rizal | F14: Baras | G14: San Juan | H14: 14.524041 | I14: 121.26768 | J14: R | K14: 1st | L14: 4838 | M14: 4.14 | N14: =ROUND(L14/M14, 0) | O14: =ROUND(N14*'Methodology & Assumptions'!$B$8, 0) | P14: Band n50 (1.5 GHz, 60 MHz) | Q14: =ROUNDUP(O14/'Methodology & Assumptions'!$B$9, 0) | R14: 1 | S14: 0.28 | T14: 0.24 | U14: Tier 1A (Direct Coloc, <1 km) | V14: 100 | W14: 100 | X14: 58 | Y14: =ROUND((V14*'Methodology & Assumptions'!$B$6)+(W14*'Methodology & Assumptions'!$B$5)+(X14*'Methodology & Assumptions'!$B$7), 2)
A15: 11 | B15: 11 | C15: 0604502006 | D15: Region VI (Western Visayas) | E15: Negros Occidental | F15: City of Bago | G15: Balingasag | H15: 10.530131 | I15: 122.84517 | J15: R | K15: Class 1-3 / Urban | L15: 4822 | M15: 4.33 | N15: =ROUND(L15/M15, 0) | O15: =ROUND(N15*'Methodology & Assumptions'!$B$8, 0) | P15: Band n50 (1.5 GHz, 60 MHz) | Q15: =ROUNDUP(O15/'Methodology & Assumptions'!$B$9, 0) | R15: 1 | S15: 0.17 | T15: 0.17 | U15: Tier 1A (Direct Coloc, <1 km) | V15: 100 | W15: 100 | X15: 58 | Y15: =ROUND((V15*'Methodology & Assumptions'!$B$6)+(W15*'Methodology & Assumptions'!$B$5)+(X15*'Methodology & Assumptions'!$B$7), 2)
A16: 12 | B16: 12 | C16: 0401023021 | D16: Region IV-A (CALABARZON) | E16: Batangas | F16: San Juan | G16: Mabalanoy | H16: 13.818392 | I16: 121.39739 | J16: R | K16: Class 1-3 / Urban | L16: 4764 | M16: 4.62 | N16: =ROUND(L16/M16, 0) | O16: =ROUND(N16*'Methodology & Assumptions'!$B$8, 0) | P16: Band n50 (1.5 GHz, 60 MHz) | Q16: =ROUNDUP(O16/'Methodology & Assumptions'!$B$9, 0) | R16: 1 | S16: 0.31 | T16: 0.3 | U16: Tier 1A (Direct Coloc, <1 km) | V16: 100 | W16: 100 | X16: 58 | Y16: =ROUND((V16*'Methodology & Assumptions'!$B$6)+(W16*'Methodology & Assumptions'!$B$5)+(X16*'Methodology & Assumptions'!$B$7), 2)
... A1004: 1000 | B1004: 1000 | C1004: 0301412015 | D1004: Region III (Central Luzon) | E1004: Bulacan | F1004: City of Meycauayan | G1004: Malhacan | H1004: 14.743967 | I1004: 120.97171 | J1004: U | K1004: Class 1-3 / Urban | L1004: 21540 | M1004: 4.1 | N1004: =ROUND(L1004/M1004, 0) | O1004: =ROUND(N1004*'Methodology & Assumptions'!$B$8, 0) | P1004: Band n50 (1.5 GHz, 60 MHz) | Q1004: =ROUNDUP(O1004/'Methodology & Assumptions'!$B$9, 0) | R1004: 1 | S1004: 0.72 | T1004: 1.31 | U1004: Tier 1A (Direct Coloc, <1 km) | V1004: 88.7 | W1004: 100 | X1004: 28 | Y1004: =ROUND((V1004*'Methodology & Assumptions'!$B$6)+(W1004*'Methodology & Assumptions'!$B$5)+(X1004*'Methodology & Assumptions'!$B$7), 2)

Sheet Batch 2 (1,001 - 2,000)
A1: FWA Rollout Batch 2 — Sites 1,001 to 2,000
A2: Dynamic commercial deployment rollout schedule (1,000 sites), linked to live parameters in 'Methodology & Assumptions'.
A4: Batch Rank | B4: Overall Rank | C4: PSGC Code | D4: Region | E4: Province | F4: Municipality | G4: Barangay | H4: Latitude | I4: Longitude | J4: Urban / Rural | K4: Municipal Income Class | L4: 2020 Pop | M4: Avg HH Size | N4: Households | O4: Subs @ 30% | P4: Carrier Spectrum | Q4: Peak 30% Demand Capacity (BTS) | R4: Initial Day 1 Build (BTS) | S4: Dist. to Nearest Node (km) | T4: Dist. to Fiber Line (km) | U4: Deploy Tier | V4: Deploy Score (35%) | W4: Viability Score (35%) | X4: Necessity Score (30%) | Y4: Composite Score
A5: 1 | B5: 1001 | C5: 1404406009 | D5: Cordillera Administrative Region (CAR) | E5: Mountain Province | F5: Paracelis | G5: Poblacion | H5: 17.178626 | I5: 121.40436 | J5: U | K5: Class 1-3 / Urban | L5: 6786 | M5: 4.42 | N5: =ROUND(L5/M5, 0) | O5: =ROUND(N5*'Methodology & Assumptions'!$B$8, 0) | P5: Band n50 (1.5 GHz, 60 MHz) | Q5: =ROUNDUP(O5/'Methodology & Assumptions'!$B$9, 0) | R5: 1 | S5: 0.36 | T5: 22.04 | U5: Tier 1A (Direct Coloc, <1 km) | V5: 88.7 | W5: 100 | X5: 28 | Y5: =ROUND((V5*'Methodology & Assumptions'!$B$6)+(W5*'Methodology & Assumptions'!$B$5)+(X5*'Methodology & Assumptions'!$B$7), 2)
A6: 2 | B6: 1002 | C6: 0403420007 | D6: Region IV-A (CALABARZON) | E6: Laguna | F6: Pakil | G6: Gonzales | H6: 14.384291 | I6: 121.47737 | J6: R | K6: 3rd | L6: 2614 | M6: 4.49 | N6: =ROUND(L6/M6, 0) | O6: =ROUND(N6*'Methodology & Assumptions'!$B$8, 0) | P6: Band n50 (1.5 GHz, 60 MHz) | Q6: =ROUNDUP(O6/'Methodology & Assumptions'!$B$9, 0) | R6: 1 | S6: 0.58 | T6: 0.19 | U6: Tier 1A (Direct Coloc, <1 km) | V6: 92.3 | W6: 70.7 | X6: 58 | Y6: =ROUND((V6*'Methodology & Assumptions'!$B$6)+(W6*'Methodology & Assumptions'!$B$5)+(X6*'Methodology & Assumptions'!$B$7), 2)
A7: 3 | B7: 1003 | C7: 0401005097 | D7: Region IV-A (CALABARZON) | E7: Batangas | F7: Batangas City | G7: Santa Rita Karsada | H7: 13.779163 | I7: 121.03892 | J7: U | K7: Class 1-3 / Urban | L7: 20321 | M7: 4.62 | N7: =ROUND(L7/M7, 0) | O7: =ROUND(N7*'Methodology & Assumptions'!$B$8, 0) | P7: Band n50 (1.5 GHz, 60 MHz) | Q7: =ROUNDUP(O7/'Methodology & Assumptions'!$B$9, 0) | R7: 1 | S7: 0.72 | T7: 0.02 | U7: Tier 1A (Direct Coloc, <1 km) | V7: 88.7 | W7: 100 | X7: 28 | Y7: =ROUND((V7*'Methodology & Assumptions'!$B$6)+(W7*'Methodology & Assumptions'!$B$5)+(X7*'Methodology & Assumptions'!$B$7), 2)
A8: 4 | B8: 1004 | C8: 0201505037 | D8: Region II (Cagayan Valley) | E8: Cagayan | F8: Aparri | G8: Punta | H8: 18.359414 | I8: 121.63541 | J8: U | K8: Class 1-3 / Urban | L8: 4841 | M8: 4.38 | N8: =ROUND(L8/M8, 0) | O8: =ROUND(N8*'Methodology & Assumptions'!$B$8, 0) | P8: Band n50 (1.5 GHz, 60 MHz) | Q8: =ROUNDUP(O8/'Methodology & Assumptions'!$B$9, 0) | R8: 1 | S8: 0.36 | T8: 10.49 | U8: Tier 1A (Direct Coloc, <1 km) | V8: 88.7 | W8: 100 | X8: 28 | Y8: =ROUND((V8*'Methodology & Assumptions'!$B$6)+(W8*'Methodology & Assumptions'!$B$5)+(X8*'Methodology & Assumptions'!$B$7), 2)
A9: 5 | B9: 1005 | C9: 0105531029 | D9: Region I (Ilocos Region) | E9: Pangasinan | F9: Rosales | G9: Station District | H9: 15.889695 | I9: 120.63427 | J9: R | K9: Class 1-3 / Urban | L9: 2750 | M9: 4.39 | N9: =ROUND(L9/M9, 0) | O9: =ROUND(N9*'Methodology & Assumptions'!$B$8, 0) | P9: Band n50 (1.5 GHz, 60 MHz) | Q9: =ROUNDUP(O9/'Methodology & Assumptions'!$B$9, 0) | R9: 1 | S9: 0.72 | T9: 0.68 | U9: Tier 1A (Direct Coloc, <1 km) | V9: 88.8 | W9: 74.1 | X9: 58 | Y9: =ROUND((V9*'Methodology & Assumptions'!$B$6)+(W9*'Methodology & Assumptions'!$B$5)+(X9*'Methodology & Assumptions'!$B$7), 2)
A10: 6 | B10: 1006 | C10: 0501701025 | D10: Region V (Bicol Region) | E10: Camarines Sur | F10: Baao | G10: Santa Cruz | H10: 13.453145 | I10: 123.37008 | J10: R | K10: Class 1-3 / Urban | L10: 2961 | M10: 4.9 | N10: =ROUND(L10/M10, 0) | O10: =ROUND(N10*'Methodology & Assumptions'!$B$8, 0) | P10: Band n50 (1.5 GHz, 60 MHz) | Q10: =ROUNDUP(O10/'Methodology & Assumptions'!$B$9, 0) | R10: 1 | S10: 0.65 | T10: 0.27 | U10: Tier 1A (Direct Coloc, <1 km) | V10: 90.6 | W10: 72.3 | X10: 58 | Y10: =ROUND((V10*'Methodology & Assumptions'!$B$6)+(W10*'Methodology & Assumptions'!$B$5)+(X10*'Methodology & Assumptions'!$B$7), 2)
A11: 7 | B11: 1007 | C11: 0405811001 | D11: Region IV-A (CALABARZON) | E11: Rizal | F11: San Mateo | G11: Ampid I | H11: 14.68114 | I11: 121.1193 | J11: U | K11: Class 1-3 / Urban | L11: 27346 | M11: 4.39 | N11: =ROUND(L11/M11, 0) | O11: =ROUND(N11*'Methodology & Assumptions'!$B$8, 0) | P11: Band n50 (1.5 GHz, 60 MHz) | Q11: =ROUNDUP(O11/'Methodology & Assumptions'!$B$9, 0) | R11: 1 | S11: 0.72 | T11: 0.18 | U11: Tier 1A (Direct Coloc, <1 km) | V11: 88.6 | W11: 100 | X11: 28 | Y11: =ROUND((V11*'Methodology & Assumptions'!$B$6)+(W11*'Methodology & Assumptions'!$B$5)+(X11*'Methodology & Assumptions'!$B$7), 2)
A12: 8 | B12: 1008 | C12: 0301412021 | D12: Region III (Central Luzon) | E12: Bulacan | F12: City of Meycauayan | G12: Saluysoy | H12: 14.743155 | I12: 120.95581 | J12: U | K12: Class 1-3 / Urban | L12: 11024 | M12: 4.1 | N12: =ROUND(L12/M12, 0) | O12: =ROUND(N12*'Methodology & Assumptions'!$B$8, 0) | P12: Band n50 (1.5 GHz, 60 MHz) | Q12: =ROUNDUP(O12/'Methodology & Assumptions'!$B$9, 0) | R12: 1 | S12: 0.72 | T12: 0.34 | U12: Tier 1A (Direct Coloc, <1 km) | V12: 88.6 | W12: 100 | X12: 28 | Y12: =ROUND((V12*'Methodology & Assumptions'!$B$6)+(W12*'Methodology & Assumptions'!$B$5)+(X12*'Methodology & Assumptions'!$B$7), 2)
A13: 9 | B13: 1009 | C13: 0301423018 | D13: Region III (Central Luzon) | E13: Bulacan | F13: Santa Maria | G13: San Gabriel | H13: 14.806653 | I13: 120.96338 | J13: U | K13: Class 1-3 / Urban | L13: 9630 | M13: 4.1 | N13: =ROUND(L13/M13, 0) | O13: =ROUND(N13*'Methodology & Assumptions'!$B$8, 0) | P13: Band n50 (1.5 GHz, 60 MHz) | Q13: =ROUNDUP(O13/'Methodology & Assumptions'!$B$9, 0) | R13: 1 | S13: 0.72 | T13: 0.48 | U13: Tier 1A (Direct Coloc, <1 km) | V13: 88.6 | W13: 100 | X13: 28 | Y13: =ROUND((V13*'Methodology & Assumptions'!$B$6)+(W13*'Methodology & Assumptions'!$B$5)+(X13*'Methodology & Assumptions'!$B$7), 2)
A14: 10 | B14: 1010 | C14: 0831600149 | D14: Region VIII (Eastern Visayas) | E14: Leyte | F14: City of Tacloban | G14: Barangay 62-B | H14: 11.220557 | I14: 124.99974 | J14: R | K14: Class 1-3 / Urban | L14: 3487 | M14: 4.24 | N14: =ROUND(L14/M14, 0) | O14: =ROUND(N14*'Methodology & Assumptions'!$B$8, 0) | P14: Band n50 (1.5 GHz, 60 MHz) | Q14: =ROUNDUP(O14/'Methodology & Assumptions'!$B$9, 0) | R14: 1 | S14: 1.39 | T14: 1.38 | U14: Tier 1B (Micro Drop, 1-3 km) | V14: 73 | W14: 89.9 | X14: 58 | Y14: =ROUND((V14*'Methodology & Assumptions'!$B$6)+(W14*'Methodology & Assumptions'!$B$5)+(X14*'Methodology & Assumptions'!$B$7), 2)
A15: 11 | B15: 1011 | C15: 1004308049 | D15: Region X (Northern Mindanao) | E15: Misamis Oriental | F15: City of Gingoog | G15: Barangay 24 | H15: 8.826999 | I15: 125.09552 | J15: R | K15: Class 1-3 / Urban | L15: 3333 | M15: 4.54 | N15: =ROUND(L15/M15, 0) | O15: =ROUND(N15*'Methodology & Assumptions'!$B$8, 0) | P15: Band n50 (1.5 GHz, 60 MHz) | Q15: =ROUNDUP(O15/'Methodology & Assumptions'!$B$9, 0) | R15: 1 | S15: 1.06 | T15: 0.39 | U15: Tier 1B (Micro Drop, 1-3 km) | V15: 80.2 | W15: 82.7 | X15: 58 | Y15: =ROUND((V15*'Methodology & Assumptions'!$B$6)+(W15*'Methodology & Assumptions'!$B$5)+(X15*'Methodology & Assumptions'!$B$7), 2)
A16: 12 | B16: 1012 | C16: 0305413043 | D16: Region III (Central Luzon) | E16: Pampanga | F16: Mexico | G16: Santo Rosario | H16: 15.06766 | I16: 120.7278 | J16: U | K16: Class 1-3 / Urban | L16: 4163 | M16: 4.63 | N16: =ROUND(L16/M16, 0) | O16: =ROUND(N16*'Methodology & Assumptions'!$B$8, 0) | P16: Band n50 (1.5 GHz, 60 MHz) | Q16: =ROUNDUP(O16/'Methodology & Assumptions'!$B$9, 0) | R16: 1 | S16: 0.58 | T16: 0.17 | U16: Tier 1A (Direct Coloc, <1 km) | V16: 92.5 | W16: 96 | X16: 28 | Y16: =ROUND((V16*'Methodology & Assumptions'!$B$6)+(W16*'Methodology & Assumptions'!$B$5)+(X16*'Methodology & Assumptions'!$B$7), 2)
... A1004: 1000 | B1004: 2000 | C1004: 0403405033 | D1004: Region IV-A (CALABARZON) | E1004: Laguna | F1004: City of Calamba | G1004: Paciano Rizal | H1004: 14.212158 | I1004: 121.1337 | J1004: U | K1004: Class 1-3 / Urban | L1004: 15679 | M1004: 4.2 | N1004: =ROUND(L1004/M1004, 0) | O1004: =ROUND(N1004*'Methodology & Assumptions'!$B$8, 0) | P1004: Band n50 (1.5 GHz, 60 MHz) | Q1004: =ROUNDUP(O1004/'Methodology & Assumptions'!$B$9, 0) | R1004: 1 | S1004: 1.19 | T1004: 0.15 | U1004: Tier 1B (Micro Drop, 1-3 km) | V1004: 77.2 | W1004: 100 | X1004: 28 | Y1004: =ROUND((V1004*'Methodology & Assumptions'!$B$6)+(W1004*'Methodology & Assumptions'!$B$5)+(X1004*'Methodology & Assumptions'!$B$7), 2)

Sheet Batch 3 (2,001 - 3,000)
A1: FWA Rollout Batch 3 — Sites 2,001 to 3,000
A2: Dynamic commercial deployment rollout schedule (1,000 sites), linked to live parameters in 'Methodology & Assumptions'.
A4: Batch Rank | B4: Overall Rank | C4: PSGC Code | D4: Region | E4: Province | F4: Municipality | G4: Barangay | H4: Latitude | I4: Longitude | J4: Urban / Rural | K4: Municipal Income Class | L4: 2020 Pop | M4: Avg HH Size | N4: Households | O4: Subs @ 30% | P4: Carrier Spectrum | Q4: Peak 30% Demand Capacity (BTS) | R4: Initial Day 1 Build (BTS) | S4: Dist. to Nearest Node (km) | T4: Dist. to Fiber Line (km) | U4: Deploy Tier | V4: Deploy Score (35%) | W4: Viability Score (35%) | X4: Necessity Score (30%) | Y4: Composite Score
A5: 1 | B5: 2001 | C5: 0301420037 | D5: Region III (Central Luzon) | E5: Bulacan | F5: City of San Jose Del Monte | G5: Minuyan II | H5: 14.843118 | I5: 121.07555 | J5: U | K5: Class 1-3 / Urban | L5: 5977 | M5: 4.1 | N5: =ROUND(L5/M5, 0) | O5: =ROUND(N5*'Methodology & Assumptions'!$B$8, 0) | P5: Band n50 (1.5 GHz, 60 MHz) | Q5: =ROUNDUP(O5/'Methodology & Assumptions'!$B$9, 0) | R5: 1 | S5: 0.78 | T5: 3.82 | U5: Tier 1A (Direct Coloc, <1 km) | V5: 77.2 | W5: 100 | X5: 28 | Y5: =ROUND((V5*'Methodology & Assumptions'!$B$6)+(W5*'Methodology & Assumptions'!$B$5)+(X5*'Methodology & Assumptions'!$B$7), 2)
A6: 2 | B6: 2002 | C6: 1001304021 | D6: Region X (Northern Mindanao) | E6: Bukidnon | F6: Don Carlos | G6: Pinamaloy | H6: 7.664438 | I6: 124.99428 | J6: R | K6: Class 1-3 / Urban | L6: 3236 | M6: 4.63 | N6: =ROUND(L6/M6, 0) | O6: =ROUND(N6*'Methodology & Assumptions'!$B$8, 0) | P6: Band n50 (1.5 GHz, 60 MHz) | Q6: =ROUNDUP(O6/'Methodology & Assumptions'!$B$9, 0) | R6: 1 | S6: 1.46 | T6: 0.32 | U6: Tier 1B (Micro Drop, 1-3 km) | V6: 71.4 | W6: 80 | X6: 58 | Y6: =ROUND((V6*'Methodology & Assumptions'!$B$6)+(W6*'Methodology & Assumptions'!$B$5)+(X6*'Methodology & Assumptions'!$B$7), 2)
A7: 3 | B7: 2003 | C7: 0304923030 | D7: Region III (Central Luzon) | E7: Nueva Ecija | F7: Rizal | G7: Portal | H7: 15.585783 | I7: 120.92458 | J7: R | K7: Class 1-3 / Urban | L7: 2075 | M7: 4.32 | N7: =ROUND(L7/M7, 0) | O7: =ROUND(N7*'Methodology & Assumptions'!$B$8, 0) | P7: Band n50 (1.5 GHz, 60 MHz) | Q7: =ROUNDUP(O7/'Methodology & Assumptions'!$B$9, 0) | R7: 1 | S7: 0.71 | T7: 0.52 | U7: Tier 1A (Direct Coloc, <1 km) | V7: 89 | W7: 62.4 | X7: 58 | Y7: =ROUND((V7*'Methodology & Assumptions'!$B$6)+(W7*'Methodology & Assumptions'!$B$5)+(X7*'Methodology & Assumptions'!$B$7), 2)
A8: 4 | B8: 2004 | C8: 0504113020 | D8: Region V (Bicol Region) | E8: Masbate | F8: Mobo | G8: Poblacion Dist. II | H8: 12.337958 | I8: 123.65766 | J8: R | K8: 2nd | L8: 2063 | M8: 5 | N8: =ROUND(L8/M8, 0) | O8: =ROUND(N8*'Methodology & Assumptions'!$B$8, 0) | P8: Band n50 (1.5 GHz, 60 MHz) | Q8: =ROUNDUP(O8/'Methodology & Assumptions'!$B$9, 0) | R8: 1 | S8: 0.17 | T8: 4.4 | U8: Tier 1A (Direct Coloc, <1 km) | V8: 94.4 | W8: 57.1 | X8: 58 | Y8: =ROUND((V8*'Methodology & Assumptions'!$B$6)+(W8*'Methodology & Assumptions'!$B$5)+(X8*'Methodology & Assumptions'!$B$7), 2)
A9: 5 | B9: 2005 | C9: 0405618034 | D9: Region IV-A (CALABARZON) | E9: Quezon | F9: Guinayangan | G9: Manlayo | H9: 13.904886 | I9: 122.45028 | J9: R | K9: Class 1-3 / Urban | L9: 1927 | M9: 4.46 | N9: =ROUND(L9/M9, 0) | O9: =ROUND(N9*'Methodology & Assumptions'!$B$8, 0) | P9: Band n50 (1.5 GHz, 60 MHz) | Q9: =ROUNDUP(O9/'Methodology & Assumptions'!$B$9, 0) | R9: 1 | S9: 0.22 | T9: 11.35 | U9: Tier 1A (Direct Coloc, <1 km) | V9: 92.8 | W9: 58.7 | X9: 58 | Y9: =ROUND((V9*'Methodology & Assumptions'!$B$6)+(W9*'Methodology & Assumptions'!$B$5)+(X9*'Methodology & Assumptions'!$B$7), 2)
A10: 6 | B10: 2006 | C10: 0405623013 | D10: Region IV-A (CALABARZON) | E10: Quezon | F10: Lucban | G10: Barangay 10 | H10: 14.114231 | I10: 121.55996 | J10: R | K10: Class 1-3 / Urban | L10: 1534 | M10: 4.46 | N10: =ROUND(L10/M10, 0) | O10: =ROUND(N10*'Methodology & Assumptions'!$B$8, 0) | P10: Band n50 (1.5 GHz, 60 MHz) | Q10: =ROUNDUP(O10/'Methodology & Assumptions'!$B$9, 0) | R10: 1 | S10: 0.2 | T10: 0.19 | U10: Tier 1A (Direct Coloc, <1 km) | V10: 100 | W10: 51.5 | X10: 58 | Y10: =ROUND((V10*'Methodology & Assumptions'!$B$6)+(W10*'Methodology & Assumptions'!$B$5)+(X10*'Methodology & Assumptions'!$B$7), 2)
A11: 7 | B11: 2007 | C11: 1130700175 | D11: Region XI (Davao Region) | E11: Davao del Sur | F11: City of Davao | G11: Baganihan | H11: 7.475985 | I11: 125.24414 | J11: R | K11: Class 1-3 / Urban | L11: 1507 | M11: 4.1 | N11: =ROUND(L11/M11, 0) | O11: =ROUND(N11*'Methodology & Assumptions'!$B$8, 0) | P11: Band n50 (1.5 GHz, 60 MHz) | Q11: =ROUNDUP(O11/'Methodology & Assumptions'!$B$9, 0) | R11: 1 | S11: 0.38 | T11: 0.24 | U11: Tier 1A (Direct Coloc, <1 km) | V11: 98.1 | W11: 53.3 | X11: 58 | Y11: =ROUND((V11*'Methodology & Assumptions'!$B$6)+(W11*'Methodology & Assumptions'!$B$5)+(X11*'Methodology & Assumptions'!$B$7), 2)
A12: 8 | B12: 2008 | C12: 1102403003 | D12: Region XI (Davao Region) | E12: Davao del Sur | F12: City of Digos | G12: San Jose | H12: 6.733199 | I12: 125.35471 | J12: U | K12: Class 1-3 / Urban | L12: 7009 | M12: 4.1 | N12: =ROUND(L12/M12, 0) | O12: =ROUND(N12*'Methodology & Assumptions'!$B$8, 0) | P12: Band n50 (1.5 GHz, 60 MHz) | Q12: =ROUNDUP(O12/'Methodology & Assumptions'!$B$9, 0) | R12: 1 | S12: 1.19 | T12: 0.05 | U12: Tier 1B (Micro Drop, 1-3 km) | V12: 77.2 | W12: 100 | X12: 28 | Y12: =ROUND((V12*'Methodology & Assumptions'!$B$6)+(W12*'Methodology & Assumptions'!$B$5)+(X12*'Methodology & Assumptions'!$B$7), 2)
A13: 9 | B13: 2009 | C13: 0402109084 | D13: Region IV-A (CALABARZON) | E13: Cavite | F13: City of Imus | G13: Palico IV | H13: 14.426589 | I13: 120.94567 | J13: U | K13: Class 1-3 / Urban | L13: 3677 | M13: 4.49 | N13: =ROUND(L13/M13, 0) | O13: =ROUND(N13*'Methodology & Assumptions'!$B$8, 0) | P13: Band n50 (1.5 GHz, 60 MHz) | Q13: =ROUNDUP(O13/'Methodology & Assumptions'!$B$9, 0) | R13: 1 | S13: 0.4 | T13: 2.2 | U13: Tier 1A (Direct Coloc, <1 km) | V13: 87.6 | W13: 89.6 | X13: 28 | Y13: =ROUND((V13*'Methodology & Assumptions'!$B$6)+(W13*'Methodology & Assumptions'!$B$5)+(X13*'Methodology & Assumptions'!$B$7), 2)
A14: 10 | B14: 2010 | C14: 0301421036 | D14: Region III (Central Luzon) | E14: Bulacan | F14: San Miguel | G14: Pinambaran | H14: 15.203454 | I14: 120.97738 | J14: R | K14: Class 1-3 / Urban | L14: 4573 | M14: 4.1 | N14: =ROUND(L14/M14, 0) | O14: =ROUND(N14*'Methodology & Assumptions'!$B$8, 0) | P14: Band n50 (1.5 GHz, 60 MHz) | Q14: =ROUNDUP(O14/'Methodology & Assumptions'!$B$9, 0) | R14: 1 | S14: 2 | T14: 2.16 | U14: Tier 1B (Micro Drop, 1-3 km) | V14: 51.4 | W14: 100 | X14: 58 | Y14: =ROUND((V14*'Methodology & Assumptions'!$B$6)+(W14*'Methodology & Assumptions'!$B$5)+(X14*'Methodology & Assumptions'!$B$7), 2)
A15: 11 | B15: 2011 | C15: 1600307010 | D15: Region XIII (Caraga) | E15: Agusan del Sur | F15: Rosario | G15: Libuac | H15: 8.390706 | I15: 126.0098 | J15: R | K15: Class 1-3 / Urban | L15: 3208 | M15: 4.1 | N15: =ROUND(L15/M15, 0) | O15: =ROUND(N15*'Methodology & Assumptions'!$B$8, 0) | P15: Band n50 (1.5 GHz, 60 MHz) | Q15: =ROUNDUP(O15/'Methodology & Assumptions'!$B$9, 0) | R15: 1 | S15: 1.81 | T15: 1.15 | U15: Tier 1B (Micro Drop, 1-3 km) | V15: 64.8 | W15: 86.7 | X15: 58 | Y15: =ROUND((V15*'Methodology & Assumptions'!$B$6)+(W15*'Methodology & Assumptions'!$B$5)+(X15*'Methodology & Assumptions'!$B$7), 2)
A16: 12 | B16: 2012 | C16: 0600407001 | D16: Region VI (Western Visayas) | E16: Aklan | F16: Kalibo | G16: Andagaw | H16: 11.704115 | I16: 122.37567 | J16: U | K16: Class 1-3 / Urban | L16: 15404 | M16: 4.27 | N16: =ROUND(L16/M16, 0) | O16: =ROUND(N16*'Methodology & Assumptions'!$B$8, 0) | P16: Band n50 (1.5 GHz, 60 MHz) | Q16: =ROUNDUP(O16/'Methodology & Assumptions'!$B$9, 0) | R16: 1 | S16: 1.19 | T16: 0.93 | U16: Tier 1B (Micro Drop, 1-3 km) | V16: 77.2 | W16: 100 | X16: 28 | Y16: =ROUND((V16*'Methodology & Assumptions'!$B$6)+(W16*'Methodology & Assumptions'!$B$5)+(X16*'Methodology & Assumptions'!$B$7), 2)
... A1004: 1000 | B1004: 3000 | C1004: 0304923031 | D1004: Region III (Central Luzon) | E1004: Nueva Ecija | F1004: Rizal | G1004: San Esteban | H1004: 15.585783 | I1004: 120.92458 | J1004: R | K1004: Class 1-3 / Urban | L1004: 1655 | M1004: 4.32 | N1004: =ROUND(L1004/M1004, 0) | O1004: =ROUND(N1004*'Methodology & Assumptions'!$B$8, 0) | P1004: Band n50 (1.5 GHz, 60 MHz) | Q1004: =ROUNDUP(O1004/'Methodology & Assumptions'!$B$9, 0) | R1004: 1 | S1004: 0.71 | T1004: 0.52 | U1004: Tier 1A (Direct Coloc, <1 km) | V1004: 89 | W1004: 54.7 | X1004: 58 | Y1004: =ROUND((V1004*'Methodology & Assumptions'!$B$6)+(W1004*'Methodology & Assumptions'!$B$5)+(X1004*'Methodology & Assumptions'!$B$7), 2)

Sheet Batch 4 & 5 (3,001 - 5,000)
A1: FWA Rollout Batch 4 & 5 — Sites 3,001 to 5,000
A2: Dynamic commercial deployment rollout schedule (2,000 sites), linked to live parameters in 'Methodology & Assumptions'.
A4: Batch Rank | B4: Overall Rank | C4: PSGC Code | D4: Region | E4: Province | F4: Municipality | G4: Barangay | H4: Latitude | I4: Longitude | J4: Urban / Rural | K4: Municipal Income Class | L4: 2020 Pop | M4: Avg HH Size | N4: Households | O4: Subs @ 30% | P4: Carrier Spectrum | Q4: Peak 30% Demand Capacity (BTS) | R4: Initial Day 1 Build (BTS) | S4: Dist. to Nearest Node (km) | T4: Dist. to Fiber Line (km) | U4: Deploy Tier | V4: Deploy Score (35%) | W4: Viability Score (35%) | X4: Necessity Score (30%) | Y4: Composite Score
A5: 1 | B5: 3001 | C5: 0500510003 | D5: Region V (Bicol Region) | E5: Albay | F5: Malinao | G5: Balading | H5: 13.389386 | I5: 123.71065 | J5: U | K5: Class 1-3 / Urban | L5: 3117 | M5: 4.67 | N5: =ROUND(L5/M5, 0) | O5: =ROUND(N5*'Methodology & Assumptions'!$B$8, 0) | P5: Band n50 (1.5 GHz, 60 MHz) | Q5: =ROUNDUP(O5/'Methodology & Assumptions'!$B$9, 0) | R5: 1 | S5: 0.59 | T5: 0.32 | U5: Tier 1A (Direct Coloc, <1 km) | V5: 92.1 | W5: 77.3 | X5: 28 | Y5: =ROUND((V5*'Methodology & Assumptions'!$B$6)+(W5*'Methodology & Assumptions'!$B$5)+(X5*'Methodology & Assumptions'!$B$7), 2)
A6: 2 | B6: 3002 | C6: 0205005027 | D6: Region II (Cagayan Valley) | E6: Nueva Vizcaya | F6: Bayombong | G6: Santa Rosa | H6: 16.489062 | I6: 121.16166 | J6: R | K6: Class 1-3 / Urban | L6: 2642 | M6: 4.19 | N6: =ROUND(L6/M6, 0) | O6: =ROUND(N6*'Methodology & Assumptions'!$B$8, 0) | P6: Band n50 (1.5 GHz, 60 MHz) | Q6: =ROUNDUP(O6/'Methodology & Assumptions'!$B$9, 0) | R6: 1 | S6: 1.57 | T6: 0.34 | U6: Tier 1B (Micro Drop, 1-3 km) | V6: 69.3 | W6: 74.4 | X6: 58 | Y6: =ROUND((V6*'Methodology & Assumptions'!$B$6)+(W6*'Methodology & Assumptions'!$B$5)+(X6*'Methodology & Assumptions'!$B$7), 2)
A7: 3 | B7: 3003 | C7: 0402106014 | D7: Region IV-A (CALABARZON) | E7: Cavite | F7: City of Dasmariñas | G7: San Agustin I | H7: 14.303142 | I7: 120.94461 | J7: U | K7: Class 1-3 / Urban | L7: 11971 | M7: 4.49 | N7: =ROUND(L7/M7, 0) | O7: =ROUND(N7*'Methodology & Assumptions'!$B$8, 0) | P7: Band n50 (1.5 GHz, 60 MHz) | Q7: =ROUNDUP(O7/'Methodology & Assumptions'!$B$9, 0) | R7: 1 | S7: 1.56 | T7: 0.69 | U7: Tier 1B (Micro Drop, 1-3 km) | V7: 69.4 | W7: 100 | X7: 28 | Y7: =ROUND((V7*'Methodology & Assumptions'!$B$6)+(W7*'Methodology & Assumptions'!$B$5)+(X7*'Methodology & Assumptions'!$B$7), 2)
A8: 4 | B8: 3004 | C8: 0702214014 | D8: Region VII (Central Visayas) | E8: Cebu | F8: City of Carcar | G8: Poblacion III | H8: 10.109809 | I8: 123.64981 | J8: U | K8: Class 1-3 / Urban | L8: 7329 | M8: 4.42 | N8: =ROUND(L8/M8, 0) | O8: =ROUND(N8*'Methodology & Assumptions'!$B$8, 0) | P8: Band n50 (1.5 GHz, 60 MHz) | Q8: =ROUNDUP(O8/'Methodology & Assumptions'!$B$9, 0) | R8: 1 | S8: 1.56 | T8: 0.26 | U8: Tier 1B (Micro Drop, 1-3 km) | V8: 69.4 | W8: 100 | X8: 28 | Y8: =ROUND((V8*'Methodology & Assumptions'!$B$6)+(W8*'Methodology & Assumptions'!$B$5)+(X8*'Methodology & Assumptions'!$B$7), 2)
A9: 5 | B9: 3005 | C9: 1004302031 | D9: Region X (Northern Mindanao) | E9: Misamis Oriental | F9: Balingasag | G9: Talusan | H9: 8.73491 | I9: 124.79254 | J9: R | K9: Class 1-3 / Urban | L9: 3421 | M9: 4.54 | N9: =ROUND(L9/M9, 0) | O9: =ROUND(N9*'Methodology & Assumptions'!$B$8, 0) | P9: Band n50 (1.5 GHz, 60 MHz) | Q9: =ROUNDUP(O9/'Methodology & Assumptions'!$B$9, 0) | R9: 1 | S9: 2.12 | T9: 0.63 | U9: Tier 1B (Micro Drop, 1-3 km) | V9: 59.4 | W9: 84.3 | X9: 58 | Y9: =ROUND((V9*'Methodology & Assumptions'!$B$6)+(W9*'Methodology & Assumptions'!$B$5)+(X9*'Methodology & Assumptions'!$B$7), 2)
A10: 6 | B10: 3006 | C10: 0403403006 | D10: Region IV-A (CALABARZON) | E10: Laguna | F10: City of Biñan | G10: De La Paz | H10: 14.348918 | I10: 121.08489 | J10: U | K10: Class 1-3 / Urban | L10: 32841 | M10: 4.2 | N10: =ROUND(L10/M10, 0) | O10: =ROUND(N10*'Methodology & Assumptions'!$B$8, 0) | P10: Band n50 (1.5 GHz, 60 MHz) | Q10: =ROUNDUP(O10/'Methodology & Assumptions'!$B$9, 0) | R10: 1 | S10: 1.51 | T10: 1.1 | U10: Tier 1B (Micro Drop, 1-3 km) | V10: 70.5 | W10: 98.9 | X10: 28 | Y10: =ROUND((V10*'Methodology & Assumptions'!$B$6)+(W10*'Methodology & Assumptions'!$B$5)+(X10*'Methodology & Assumptions'!$B$7), 2)
A11: 7 | B11: 3007 | C11: 1003522019 | D11: Region X (Northern Mindanao) | E11: Lanao del Norte | F11: Tubod | G11: Poblacion | H11: 8.055027 | I11: 123.79188 | J11: U | K11: Class 1-3 / Urban | L11: 11060 | M11: 5.12 | N11: =ROUND(L11/M11, 0) | O11: =ROUND(N11*'Methodology & Assumptions'!$B$8, 0) | P11: Band n50 (1.5 GHz, 60 MHz) | Q11: =ROUNDUP(O11/'Methodology & Assumptions'!$B$9, 0) | R11: 1 | S11: 1.56 | T11: 1.01 | U11: Tier 1B (Micro Drop, 1-3 km) | V11: 69.4 | W11: 100 | X11: 28 | Y11: =ROUND((V11*'Methodology & Assumptions'!$B$6)+(W11*'Methodology & Assumptions'!$B$5)+(X11*'Methodology & Assumptions'!$B$7), 2)
A12: 8 | B12: 3008 | C12: 0203112036 | D12: Region II (Cagayan Valley) | E12: Isabela | F12: Echague | G12: Pangal Norte | H12: 16.610525 | I12: 121.6764 | J12: R | K12: Class 1-3 / Urban | L12: 1561 | M12: 4.3 | N12: =ROUND(L12/M12, 0) | O12: =ROUND(N12*'Methodology & Assumptions'!$B$8, 0) | P12: Band n50 (1.5 GHz, 60 MHz) | Q12: =ROUNDUP(O12/'Methodology & Assumptions'!$B$9, 0) | R12: 1 | S12: 0.3 | T12: 10.01 | U12: Tier 1A (Direct Coloc, <1 km) | V12: 90.6 | W12: 53.1 | X12: 58 | Y12: =ROUND((V12*'Methodology & Assumptions'!$B$6)+(W12*'Methodology & Assumptions'!$B$5)+(X12*'Methodology & Assumptions'!$B$7), 2)
A13: 9 | B13: 3009 | C13: 1206511004 | D13: Region XII (SOCCSKSARGEN) | E13: Sultan Kudarat | F13: City of Tacurong | G13: Carmen | H13: 6.671111 | I13: 124.68278 | J13: U | K13: Class 1-3 / Urban | L13: 4092 | M13: 4.1 | N13: =ROUND(L13/M13, 0) | O13: =ROUND(N13*'Methodology & Assumptions'!$B$8, 0) | P13: Band n50 (1.5 GHz, 60 MHz) | Q13: =ROUNDUP(O13/'Methodology & Assumptions'!$B$9, 0) | R13: 1 | S13: 2.3 | T13: 0.32 | U13: Tier 1B (Micro Drop, 1-3 km) | V13: 56.5 | W13: 100 | X13: 43 | Y13: =ROUND((V13*'Methodology & Assumptions'!$B$6)+(W13*'Methodology & Assumptions'!$B$5)+(X13*'Methodology & Assumptions'!$B$7), 2)
A14: 10 | B14: 3010 | C14: 0301420011 | D14: Region III (Central Luzon) | E14: Bulacan | F14: City of San Jose Del Monte | G14: Tungkong Mangga | H14: 14.783939 | I14: 121.07212 | J14: U | K14: Class 1-3 / Urban | L14: 16324 | M14: 4.1 | N14: =ROUND(L14/M14, 0) | O14: =ROUND(N14*'Methodology & Assumptions'!$B$8, 0) | P14: Band n50 (1.5 GHz, 60 MHz) | Q14: =ROUNDUP(O14/'Methodology & Assumptions'!$B$9, 0) | R14: 1 | S14: 1.57 | T14: 0.28 | U14: Tier 1B (Micro Drop, 1-3 km) | V14: 69.3 | W14: 100 | X14: 28 | Y14: =ROUND((V14*'Methodology & Assumptions'!$B$6)+(W14*'Methodology & Assumptions'!$B$5)+(X14*'Methodology & Assumptions'!$B$7), 2)
A15: 11 | B15: 3011 | C15: 0501724032 | D15: Region V (Bicol Region) | E15: Camarines Sur | F15: City of Naga | G15: Triangulo | H15: 13.618484 | I15: 123.18644 | J15: U | K15: Class 1-3 / Urban | L15: 8702 | M15: 4.9 | N15: =ROUND(L15/M15, 0) | O15: =ROUND(N15*'Methodology & Assumptions'!$B$8, 0) | P15: Band n50 (1.5 GHz, 60 MHz) | Q15: =ROUNDUP(O15/'Methodology & Assumptions'!$B$9, 0) | R15: 1 | S15: 1.57 | T15: 0.42 | U15: Tier 1B (Micro Drop, 1-3 km) | V15: 69.3 | W15: 100 | X15: 28 | Y15: =ROUND((V15*'Methodology & Assumptions'!$B$6)+(W15*'Methodology & Assumptions'!$B$5)+(X15*'Methodology & Assumptions'!$B$7), 2)
A16: 12 | B16: 3012 | C16: 0201522003 | D16: Region II (Cagayan Valley) | E16: Cagayan | F16: Sanchez-Mira | G16: Centro I | H16: 18.5597 | I16: 121.2347 | J16: U | K16: Class 1-3 / Urban | L16: 2484 | M16: 4.38 | N16: =ROUND(L16/M16, 0) | O16: =ROUND(N16*'Methodology & Assumptions'!$B$8, 0) | P16: Band n50 (1.5 GHz, 60 MHz) | Q16: =ROUNDUP(O16/'Methodology & Assumptions'!$B$9, 0) | R16: 1 | S16: 0.22 | T16: 0.01 | U16: Tier 1A (Direct Coloc, <1 km) | V16: 100 | W16: 69.3 | X16: 28 | Y16: =ROUND((V16*'Methodology & Assumptions'!$B$6)+(W16*'Methodology & Assumptions'!$B$5)+(X16*'Methodology & Assumptions'!$B$7), 2)
... A2004: 1000 | B2004: 5000 | C2004: 0102914001 | D2004: Region I (Ilocos Region) | E2004: Ilocos Sur | F2004: Narvacan | G2004: Abuor | H2004: 17.430598 | I2004: 120.47682 | J2004: R | K2004: Class 1-3 / Urban | L2004: 1150 | M2004: 4.56 | N2004: =ROUND(L2004/M2004, 0) | O2004: =ROUND(N2004*'Methodology & Assumptions'!$B$8, 0) | P2004: Band n50 (1.5 GHz, 60 MHz) | Q2004: =ROUNDUP(O2004/'Methodology & Assumptions'!$B$9, 0) | R2004: 1 | S2004: 0.78 | T2004: 0.48 | U2004: Tier 1A (Direct Coloc, <1 km) | V2004: 87.2 | W2004: 44.3 | X2004: 58 | Y2004: =ROUND((V2004*'Methodology & Assumptions'!$B$6)+(W2004*'Methodology & Assumptions'!$B$5)+(X2004*'Methodology & Assumptions'!$B$7), 2)

Sheet Provincial Summary
A1: Provincial Distribution across Rollout Batches & n50 BTS Capacity
A2: Breakdown of barangay counts and total n50 BTS capacity (@ 1,000 subs/BTS) by Province across Batches 1 to 5.
A4: Region | B4: Province | C4: Batch 1 (1-1k) | D4: Batch 2 (1-2k) | E4: Batch 3 (2-3k) | F4: Batch 4 (3-4k) | G4: Batch 5 (4-5k) | H4: Total Barangays (5k) | I4: Total n50 BTS Capacity | J4: Total Pop (5k) | K4: Total Subs @ 30%
A5: Region IV-A (CALABARZON) | B5: Cavite | C5: 56 | D5: 71 | E5: 94 | F5: 50 | G5: 70 | H5: 341 | I5: 377 | J5: 2183065 | K5: 146028
A6: Region IV-A (CALABARZON) | B6: Laguna | C6: 69 | D6: 62 | E6: 63 | F6: 55 | G6: 60 | H6: 309 | I6: 376 | J6: 2246290 | K6: 160466
A7: Region III (Central Luzon) | B7: Bulacan | C7: 50 | D7: 57 | E7: 60 | F7: 68 | G7: 57 | H7: 292 | I7: 338 | J7: 2236858 | K7: 163671
A8: Region VII (Central Visayas) | B8: Cebu | C8: 62 | D8: 60 | E8: 54 | F8: 61 | G8: 46 | H8: 283 | I8: 348 | J8: 2552007 | K8: 173344
A9: Region III (Central Luzon) | B9: Nueva Ecija | C9: 66 | D9: 36 | E9: 41 | F9: 45 | G9: 50 | H9: 238 | I9: 239 | J9: 924097 | K9: 64290
A10: Region IV-A (CALABARZON) | B10: Batangas | C10: 32 | D10: 53 | E10: 39 | F10: 57 | G10: 54 | H10: 235 | I10: 240 | J10: 1009326 | K10: 65552
A11: Region I (Ilocos Region) | B11: Pangasinan | C11: 35 | D11: 39 | E11: 42 | F11: 50 | G11: 46 | H11: 212 | I11: 213 | J11: 800108 | K11: 54638
A12: Region IV-A (CALABARZON) | B12: Quezon | C12: 40 | D12: 35 | E12: 48 | F12: 44 | G12: 39 | H12: 206 | I12: 211 | J12: 827198 | K12: 55731
A13: Region V (Bicol Region) | B13: Camarines Sur | C13: 31 | D13: 40 | E13: 40 | F13: 40 | G13: 38 | H13: 189 | I13: 191 | J13: 674239 | K13: 41314
A14: Region III (Central Luzon) | B14: Pampanga | C14: 37 | D14: 30 | E14: 46 | F14: 38 | G14: 33 | H14: 184 | I14: 212 | J14: 1534038 | K14: 99394
A15: Region VI (Western Visayas) | B15: Iloilo | C15: 18 | D15: 23 | E15: 40 | F15: 37 | G15: 30 | H15: 148 | I15: 149 | J15: 469208 | K15: 32172
A16: Region V (Bicol Region) | B16: Albay | C16: 20 | D16: 31 | E16: 21 | F16: 30 | G16: 37 | H16: 139 | I16: 139 | J16: 458754 | K16: 29462
... A66: MIMAROPA Region | B66: Occidental Mindoro | C66: 2 | D66: 1 | E66: 0 | F66: 0 | G66: 0 | H66: 3 | I66: 4 | J66: 37403 | K66: 2777
