Workbook

Sheet Read Me
B2: PHILIPPINE 5G FIXED WIRELESS ACCESS (FWA) - COMBINED HYBRID MODEL
B3: Commercial Viability & DICT / UNDP GIDA Prioritization Synthesis (50/50 Dual Optimization)
B5: SECTION 1: EXECUTIVE OVERVIEW & PURPOSE
B6: Project Objective | C6: 5G FWA Barangay Siting & Rollout Schedule (Combined Model) | D6: Synthesizes commercial viability with social impact by combining POPCEN 2024 economic metrics with the official DICT / UNDP GIDA Prioritization Tool.
B7: Dual Optimization | C7: 50% Commercial + 50% Social Impact Baseline | D7: Balances rapid revenue turn-up and low capex backhaul with universal service obligations and GIDA poverty alleviation.
B8: Target Spectrum | C8: Band n50 (1427 - 1518 MHz, 100 MHz TDD) | D8: Single-carrier deployment optimized for high speed, long range, and robust penetration.
B9: BTS Siting Standard | C9: 1 BTS per Barangay (Day 1) -> Dynamic Peak | D9: Dimensioned at 1,000 active subscribers per BTS (~333 per sector across 3 sectors).
B10: Backhaul Resilience | C10: Hybrid Optical + Starlink LEO Satellite | D10: Direct Optical Drop (<3km), Near Optical/Microwave (3-5km), and Starlink Business LEO Satellite (>5km).
B12: SECTION 2: MODEL ARCHITECTURE & BLENDED SCORING MECHANISM
B13: Commercial Pillar | C13: POPCEN 2024 Siting Engine (Weight: 50%) | D13: Evaluates Deployment Ease (35%), Commercial Viability (35%), and Broadband Necessity (30%).
B14: GIDA Social Pillar | C14: DICT / UNDP Looker Studio Model (Weight: 50%) | D14: Evaluates 11 Looker Studio criteria: mobile speeds, road distance, nighttime lights, hazard, insurgency, poverty, POIs, towers.
B15: Synthesis Formula | C15: Combined Score = (w_comm * S_comm) + (w_gida * S_gida) | D15: Standardized 0-100 score providing a balanced national priority queue.
B16: Phased Allocation | C16: 5 Batches x 1,000 Sites = 5,000 Sites | D16: Batch 1 delivers maximum strategic value: strong commercial viability combined with acute social impact.
B18: SECTION 3: WORKBOOK NAVIGATION & SHEET DIRECTORY
B19: Read Me | C19: Methodological Documentation & Data Dictionary | D19: Complete guide to hybrid scoring, data dictionary, and official sources.
B20: Executive Summary | C20: KPI Dashboard & Batch Comparison Table | D20: 6 KPI cards, 13-column batch breakdown, and transmission splits.
B21: Methodology & Assumptions | C21: Parameter Inputs & Blended Weights | D21: Exhaustive formulas, sensitivity weights, and technical dimensioning.
B22: Batch 1 (First 1,000) | C22: Sites 1 - 1,000 (Top Hybrid Sites) | D22: The top 1,000 dual-optimized barangays nationwide for immediate deployment.
B23: Batch 2 (1,001 - 2,000) | C23: Sites 1,001 - 2,000 | D23: Second phase expansion balancing high commercial demand with remote coverage.
B24: Batch 3 (2,001 - 3,000) | C24: Sites 2,001 - 3,000 | D24: Third phase regional expansion across Visayas and Mindanao.
B25: Batch 4 & 5 (3,001 - 5,000) | C25: Sites 3,001 - 5,000 | D25: Final phases completing national coverage across 5,000 sites.
B26: Provincial Summary | C26: Provincial Aggregation & Siting Analysis | D26: Detailed summary table by province showing site counts, population, and backhaul mix.
B28: SECTION 4: DATA SOURCES & OFFICIAL CITATIONS
B29: UNDP / DICT GIDA Tool | C29: Looker Studio Decision Support Tool (2026) | D29: https://lookerstudio.google.com/u/0/reporting/7118ca47-1563-4f51-b0db-a19b8ea4f3c7/page/p_6h58g3u7ld
B30: PSA 2024 POPCEN | C30: Proclamation No. 973 (Official National Total: 112,729,484) | D30: https://psa.gov.ph/content/2024-census-population-popcen-population-counts-declared-official-president
B31: PSA FIES Poverty Data | C31: 2024 Full Year Official Poverty Statistics | D31: https://psa.gov.ph/statistics/income-expenditure/fies/stat-tables/released/2026
B32: Converge Backbone GIS | C32: National & Regional Backbone KMZ (Nov 2024) | D32: 2,405 verified terrestrial optical nodes and 334k line vertices.
B34: SECTION 5: COMPLETE 26-COLUMN DATA DICTIONARY
B35: Col A: Batch Number | C35: Rollout Phase Identifier | D35: Batch 1 to 5 corresponding to sequential 1,000-site rollout phases.
B36: Col B: Batch Rank | C36: Relative Priority Within Batch | D36: Sequential priority index from 1 to 1,000 within each batch.
B37: Col C: Overall Rank | C37: National Priority Ranking (1 to 5,000) | D37: Strict rank based on descending Combined Hybrid Score.
B38: Col D: PSGC Code | C38: Philippine Standard Geographic Code | D38: Official administrative identifier.
B39: Col E: Region | C39: Administrative Region Name | D39: Official Philippine administrative region.
B40: Col F: Province | C40: Province Name | D40: Official province or highly urbanized city cluster.
B41: Col G: Municipality | C41: Municipality / City Name | D41: Official local government unit (LGU) name.
B42: Col H: Barangay | C42: Barangay Name | D42: Official barangay name.
B43: Col I: Latitude | C43: WGS84 Latitude | D43: Decimal degrees coordinate.
B44: Col J: Longitude | C44: WGS84 Longitude | D44: Decimal degrees coordinate.
B45: Col K: Urban / Rural (U/R) | C45: PSA Urbanity Classification | D45: R = Rural, U = Urban per official PSA classification.
B46: Col L: 2024 Population | C46: 2024 POPCEN Scaled Population | D46: Scaled directly to official PSA 2024 Census of Population.
...

Sheet Executive Summary
A1: Dynamic 5G FWA Barangay Siting & Rollout Schedule (Combined Model - Live Formulas)
A2: Automated sensitivity summary linked dynamically to 'Methodology & Assumptions' and Batch sheets.
A3: Executive Summary Dashboard | Model 3: Hybrid Combined Model (50% Commercial / 50% GIDA Social Impact)
A5: TOTAL HYBRID SITES | C5: BATCH 1 SUBSCRIBERS | E5: TOTAL TARGET SUBS | G5: PEAK BTS REQUIRED | I5: FIBER PROXIMITY (<5km) | K5: STARLINK SATELLITE (>5km)
A6: =F21 | C6: =E16 | E6: =E21 | G6: =G21 | I6: =K21+L21 | K6: =M21
A10: Combined Hybrid Siting Phasing & Score Breakdown (Batches 1 to 5)
A12: Rollout Phase | B12: Sites | C12: 2024 Population | D12: 2024 Households | E12: Target Subs (30%) | F12: Day 1 BTS | G12: Peak BTS | H12: Combined Score | I12: Commercial Score | J12: GIDA Score | K12: Direct Fiber (<3km) | L12: Near Fiber (3-5km) | M12: Starlink LEO (>5km)
A13: Batch 1 (First 1,000) | B13: 1000 | C13: 8500438 | D13: 2362172 | E13: 708642 | F13: 1000 | G13: 1371 | H13: 69.17 | I13: 69.44 | J13: 68.91 | K13: 822 | L13: 54 | M13: 124
A14: Batch 2 (1,001 - 2,000) | B14: 1000 | C14: 7001546 | D14: 1934369 | E14: 580319 | F14: 1000 | G14: 1306 | H14: 63.77 | I14: 64.91 | J14: 62.63 | K14: 741 | L14: 53 | M14: 206
A15: Batch 3 (2,001 - 3,000) | B15: 1000 | C15: 6027158 | D15: 1637128 | E15: 491143 | F15: 1000 | G15: 1246 | H15: 61.24 | I15: 65.57 | J15: 56.92 | K15: 775 | L15: 46 | M15: 179
A16: Batch 4 (3,001 - 4,000) | B16: 1000 | C16: ='Batch 1 (First 1,000)'!L1005 | D16: ='Batch 1 (First 1,000)'!N1005 | E16: ='Batch 1 (First 1,000)'!O1005 | F16: ='Batch 1 (First 1,000)'!R1005 | G16: ='Batch 1 (First 1,000)'!Q1005 | H16: ='Batch 1 (First 1,000)'!X1005 | I16: ='Batch 1 (First 1,000)'!V1005 | J16: ='Batch 1 (First 1,000)'!W1005 | K16: =COUNTIF('Batch 1 (First 1,000)'!$U$5:$U$1004, "Direct Optical*") | L16: =COUNTIF('Batch 1 (First 1,000)'!$U$5:$U$1004, "Near Optical*") | M16: =COUNTIF('Batch 1 (First 1,000)'!$U$5:$U$1004, "Starlink*")
A17: Batch 5 (4,001 - 5,000) | B17: 1000 | C17: ='Batch 2 (1,001 - 2,000)'!L1005 | D17: ='Batch 2 (1,001 - 2,000)'!N1005 | E17: ='Batch 2 (1,001 - 2,000)'!O1005 | F17: ='Batch 2 (1,001 - 2,000)'!R1005 | G17: ='Batch 2 (1,001 - 2,000)'!Q1005 | H17: ='Batch 2 (1,001 - 2,000)'!X1005 | I17: ='Batch 2 (1,001 - 2,000)'!V1005 | J17: ='Batch 2 (1,001 - 2,000)'!W1005 | K17: =COUNTIF('Batch 2 (1,001 - 2,000)'!$U$5:$U$1004, "Direct Optical*") | L17: =COUNTIF('Batch 2 (1,001 - 2,000)'!$U$5:$U$1004, "Near Optical*") | M17: =COUNTIF('Batch 2 (1,001 - 2,000)'!$U$5:$U$1004, "Starlink*")
A18: Total (5,000 Hybrid Sites) | B18: 5000 | C18: ='Batch 3 (2,001 - 3,000)'!L1005 | D18: ='Batch 3 (2,001 - 3,000)'!N1005 | E18: ='Batch 3 (2,001 - 3,000)'!O1005 | F18: ='Batch 3 (2,001 - 3,000)'!R1005 | G18: ='Batch 3 (2,001 - 3,000)'!Q1005 | H18: ='Batch 3 (2,001 - 3,000)'!X1005 | I18: ='Batch 3 (2,001 - 3,000)'!V1005 | J18: ='Batch 3 (2,001 - 3,000)'!W1005 | K18: =COUNTIF('Batch 3 (2,001 - 3,000)'!$U$5:$U$1004, "Direct Optical*") | L18: =COUNTIF('Batch 3 (2,001 - 3,000)'!$U$5:$U$1004, "Near Optical*") | M18: =COUNTIF('Batch 3 (2,001 - 3,000)'!$U$5:$U$1004, "Starlink*")
C19: =SUM('Batch 4 & 5 (3,001 - 5,000)'!L5:L1004) | D19: =SUM('Batch 4 & 5 (3,001 - 5,000)'!N5:N1004) | E19: =SUM('Batch 4 & 5 (3,001 - 5,000)'!O5:O1004) | F19: =COUNT('Batch 4 & 5 (3,001 - 5,000)'!R5:R1004) | G19: =SUM('Batch 4 & 5 (3,001 - 5,000)'!Q5:Q1004) | H19: =AVERAGE('Batch 4 & 5 (3,001 - 5,000)'!X5:X1004) | I19: =AVERAGE('Batch 4 & 5 (3,001 - 5,000)'!V5:V1004) | J19: =AVERAGE('Batch 4 & 5 (3,001 - 5,000)'!W5:W1004) | K19: =COUNTIF('Batch 4 & 5 (3,001 - 5,000)'!$U$5:$U$1004, "Direct Optical*") | L19: =COUNTIF('Batch 4 & 5 (3,001 - 5,000)'!$U$5:$U$1004, "Near Optical*") | M19: =COUNTIF('Batch 4 & 5 (3,001 - 5,000)'!$U$5:$U$1004, "Starlink*")
C20: =SUM('Batch 4 & 5 (3,001 - 5,000)'!L1005:L2004) | D20: =SUM('Batch 4 & 5 (3,001 - 5,000)'!N1005:N2004) | E20: =SUM('Batch 4 & 5 (3,001 - 5,000)'!O1005:O2004) | F20: =COUNT('Batch 4 & 5 (3,001 - 5,000)'!R1005:R2004) | G20: =SUM('Batch 4 & 5 (3,001 - 5,000)'!Q1005:Q2004) | H20: =AVERAGE('Batch 4 & 5 (3,001 - 5,000)'!X1005:X2004) | I20: =AVERAGE('Batch 4 & 5 (3,001 - 5,000)'!V1005:V2004) | J20: =AVERAGE('Batch 4 & 5 (3,001 - 5,000)'!W1005:W2004) | K20: =COUNTIF('Batch 4 & 5 (3,001 - 5,000)'!$U$1005:$U$2004, "Direct Optical*") | L20: =COUNTIF('Batch 4 & 5 (3,001 - 5,000)'!$U$1005:$U$2004, "Near Optical*") | M20: =COUNTIF('Batch 4 & 5 (3,001 - 5,000)'!$U$1005:$U$2004, "Starlink*")
A21: * Strategic Note: Model 3 combines Commercial Viability (50%) and DICT/UNDP GIDA Prioritization (50%) for dual optimization. | C21: =SUM(C16:C20) | D21: =SUM(D16:D20) | E21: =SUM(E16:E20) | F21: =SUM(F16:F20) | G21: =SUM(G16:G20) | H21: =AVERAGE(H16:H20) | I21: =AVERAGE(I16:I20) | J21: =AVERAGE(J16:J20) | K21: =SUM(K16:K20) | L21: =SUM(L16:L20) | M21: =SUM(M16:M20)
A22: * Day 1 Siting: 1 BTS deployed per barangay; Peak BTS dimensioned @ 1,000 active subscribers per BTS node (~333/sector).

Sheet Methodology & Assumptions
A1: Dynamic FWA Combined Siting Parameters & Sensitivity Inputs (Editable)
A2: Changes to yellow-highlighted parameters below immediately and dynamically recalculate all batch sheets and executive summary tables.
A3: Synthesis of Commercial Viability Siting & DICT / UNDP Multi-Criteria Decision Framework
A5: Parameter Name | B5: 0.5 | C5: Unit | D5: Methodological Rationale & Authority
A6: Commercial Blend Weight (w_comm) | B6: 0.5 | C6: 50.0% | D6: Weight allocated to commercial ROI and rapid deployment feasibility.
A7: GIDA Blend Weight (w_gida) | B7: 0.3 | C7: 50.0% | D7: Weight allocated to DICT/UNDP social equity and digital divide closure.
A8: Penetration Rate | B8: 1000 | C8: 30.0% | D8: Estimated commercial take-up rate across total barangay households.
A9: Band n50 BTS Capacity | B9: 5 | C9: 1,000 Subs | D9: Total active subscriber capacity across 3 sectors (~333 subs/sector).
A10: Starlink LEO Distance Threshold | B10: 3 | C10: 5.0 km | D10: Sites > 5km from Converge fiber assigned Starlink Business LEO satellite backhaul.
A11: Direct Optical Drop Threshold | B11: 3.8 | C11: 3.0 km | D11: Sites within 3.0km of Converge optical backbone connect via direct fiber lateral.
A12: Default 2024 HH Size | B12: 3.8 | C12: 3.80 Persons | D12: Official PSA 2024 POPCEN national average household size.
A13: Commercial: Ease of Deployment Weight | B13: 0.35 | C13: 35.0% | D13: Pillar 1 weight: fiber proximity and corridor lateral bonus.
A14: Commercial: Business Viability Weight | B14: 0.35 | C14: 35.0% | D14: Pillar 2 weight: sweet-spot demand curve discounted by FIES poverty.
A15: Commercial: Broadband Necessity Weight | B15: 0.3 | C15: 30.0% | D15: Pillar 3 weight: rural status, LGU class 4-6, off-net distance, poverty.
A16: Total Hybrid Sites Dimensioned | B16: 5000 | C16: 5,000 Sites | D16: National priority program synthesizing commercial and social reach.
A19: Hybrid Scoring Mathematical Architecture
A21: Component | B21: Formula / Weight | C21: Scale | D21: Mathematical Definition
A22: Combined Hybrid Score | B22: (w_comm * Commercial) + (w_gida * GIDA_Norm) | C22: 0 - 100 | D22: Dual-objective optimization synthesizing commercial viability with social impact.
A23: Commercial Composite | B23: (0.35*Deploy) + (0.35*Viability) + (0.30*Necessity) | C23: 0 - 100 | D23: Three-pillar commercial suitability index anchored on Converge fiber network.
A24: Normalized GIDA Score | B24: MIN(100, ROUND((Raw_GIDA_Score / 69.91) * 100, 2)) | C24: 0 - 100 | D24: Official Looker Studio multi-criteria score standardized to 100-point scale.
A25: Deployment Ease Score | B25: 100 * EXP(-dist_node / 8.0) + Corridor_Bonus | C25: 15 - 100 | D25: Exponential decay based on optical fiber proximity.
A26: Business Viability Score | B26: Sweet-spot curve on Viable_Subs [250 - 1,200] | C26: 0 - 100 | D26: Evaluates addressable subscriber volume adjusted for FIES poverty discount.
A27: Broadband Necessity Score | B27: (0.40*Rural) + (0.25*Class) + (0.20*Offnet) + (0.15*Poverty) | C27: 0 - 100 | D27: Captures broadband deficit, unserved rural population, and lower-income LGUs.

Sheet Batch 1 (First 1,000)
A1: 5G FWA Combined Hybrid Siting Rollout Schedule - Batch 1 (First 1,000)
A2: Dynamic Hybrid deployment rollout schedule (1,000 sites), linked to live parameters in 'Methodology & Assumptions'.
A4: Batch | B4: Batch Rank | C4: Overall Rank | D4: PSGC | E4: Region | F4: Province | G4: Municipality | H4: Barangay | I4: Latitude | J4: Longitude | K4: U/R | L4: 2024 Population | M4: 2024 Avg HH Size | N4: 2024 Households | O4: Target Subs (30%) | P4: Carrier Spectrum | Q4: Peak BTS Required | R4: Day 1 BTS Deployed | S4: Dist to Node (km) | T4: Dist to Line (km) | U4: Backhaul Architecture | V4: Commercial Score | W4: Normalized GIDA Score | X4: Combined Hybrid Score | Y4: Regional Poverty % | Z4: Strategic Classification
A5: 1 | B5: 1 | C5: 1 | D5: 0307702019 | E5: Region III (Central Luzon) | F5: Aurora | G5: Casiguran | H5: Bianuan | I5: 16.23934 | J5: 122.01839 | K5: R | L5: 2790 | M5: 3.8 | N5: =ROUND(L5/M5, 0) | O5: =ROUND(N5*'Methodology & Assumptions'!$B$7, 0) | P5: Single Carrier (Band n50, 100MHz TDD) | Q5: =ROUNDUP(O5/'Methodology & Assumptions'!$B$8, 0) | R5: 1 | S5: 4.34 | T5: 4.17 | U5: =IF(S5<='Methodology & Assumptions'!$B$10, "Direct Optical Drop (<3km)", IF(S5<='Methodology & Assumptions'!$B$9, "Near Optical / Microwave (<5km)", "Starlink Business LEO Satellite Backhaul (>5km)")) | V5: 69.06 | W5: 86.82 | X5: =ROUND(('Methodology & Assumptions'!$B$5*V5) + ('Methodology & Assumptions'!$B$6*W5), 2) | Y5: 8.3 | Z5: Priority Tier 1 (High Commercial & Social)
A6: 1 | B6: 2 | C6: 2 | D6: 0403403001 | E6: Region IV-A (CALABARZON) | F6: Laguna | G6: City of Biñan | H6: Biñan | I6: 14.33964 | J6: 121.08492 | K6: U | L6: 7786 | M6: 3.3 | N6: =ROUND(L6/M6, 0) | O6: =ROUND(N6*'Methodology & Assumptions'!$B$7, 0) | P6: Single Carrier (Band n50, 100MHz TDD) | Q6: =ROUNDUP(O6/'Methodology & Assumptions'!$B$8, 0) | R6: 1 | S6: 0.99 | T6: 0.1 | U6: =IF(S6<='Methodology & Assumptions'!$B$10, "Direct Optical Drop (<3km)", IF(S6<='Methodology & Assumptions'!$B$9, "Near Optical / Microwave (<5km)", "Starlink Business LEO Satellite Backhaul (>5km)")) | V6: 77.67 | W6: 78.15 | X6: =ROUND(('Methodology & Assumptions'!$B$5*V6) + ('Methodology & Assumptions'!$B$6*W6), 2) | Y6: 7.2 | Z6: Priority Tier 1 (High Commercial & Social)
A7: 1 | B7: 3 | C7: 3 | D7: 0402106050 | E7: Region IV-A (CALABARZON) | F7: Cavite | G7: City of Dasmariñas | H7: Emmanuel Bergado II | I7: 14.315161 | J7: 120.9612 | K7: R | L7: 2943 | M7: 3.4 | N7: =ROUND(L7/M7, 0) | O7: =ROUND(N7*'Methodology & Assumptions'!$B$7, 0) | P7: Single Carrier (Band n50, 100MHz TDD) | Q7: =ROUNDUP(O7/'Methodology & Assumptions'!$B$8, 0) | R7: 1 | S7: 0.57 | T7: 1.7 | U7: =IF(S7<='Methodology & Assumptions'!$B$10, "Direct Optical Drop (<3km)", IF(S7<='Methodology & Assumptions'!$B$9, "Near Optical / Microwave (<5km)", "Starlink Business LEO Satellite Backhaul (>5km)")) | V7: 85.46 | W7: 70.23 | X7: =ROUND(('Methodology & Assumptions'!$B$5*V7) + ('Methodology & Assumptions'!$B$6*W7), 2) | Y7: 7.2 | Z7: Priority Tier 1 (High Commercial & Social)
A8: 1 | B8: 4 | C8: 4 | D8: 0402106068 | E8: Region IV-A (CALABARZON) | F8: Cavite | G8: City of Dasmariñas | H8: San Antonio De Padua II | I8: 14.317398 | J8: 120.95788 | K8: R | L8: 3223 | M8: 3.4 | N8: =ROUND(L8/M8, 0) | O8: =ROUND(N8*'Methodology & Assumptions'!$B$7, 0) | P8: Single Carrier (Band n50, 100MHz TDD) | Q8: =ROUNDUP(O8/'Methodology & Assumptions'!$B$8, 0) | R8: 1 | S8: 1.01 | T8: 1.81 | U8: =IF(S8<='Methodology & Assumptions'!$B$10, "Direct Optical Drop (<3km)", IF(S8<='Methodology & Assumptions'!$B$9, "Near Optical / Microwave (<5km)", "Starlink Business LEO Satellite Backhaul (>5km)")) | V8: 84.82 | W8: 70.69 | X8: =ROUND(('Methodology & Assumptions'!$B$5*V8) + ('Methodology & Assumptions'!$B$6*W8), 2) | Y8: 7.2 | Z8: Priority Tier 1 (High Commercial & Social)
A9: 1 | B9: 5 | C9: 5 | D9: 0403418006 | E9: Region IV-A (CALABARZON) | F9: Laguna | G9: Paete | H9: Ilaya del Norte | I9: 14.402058 | J9: 121.5741 | K9: R | L9: 2622 | M9: 3.3 | N9: =ROUND(L9/M9, 0) | O9: =ROUND(N9*'Methodology & Assumptions'!$B$7, 0) | P9: Single Carrier (Band n50, 100MHz TDD) | Q9: =ROUNDUP(O9/'Methodology & Assumptions'!$B$8, 0) | R9: 1 | S9: 8.84 | T9: 10.48 | U9: =IF(S9<='Methodology & Assumptions'!$B$10, "Direct Optical Drop (<3km)", IF(S9<='Methodology & Assumptions'!$B$9, "Near Optical / Microwave (<5km)", "Starlink Business LEO Satellite Backhaul (>5km)")) | V9: 67.72 | W9: 87.69 | X9: =ROUND(('Methodology & Assumptions'!$B$5*V9) + ('Methodology & Assumptions'!$B$6*W9), 2) | Y9: 7.2 | Z9: Priority Tier 1 (High Commercial & Social)
A10: 1 | B10: 6 | C10: 6 | D10: 0403403016 | E10: Region IV-A (CALABARZON) | F10: Laguna | G10: City of Biñan | H10: Poblacion | I10: 14.339651 | J10: 121.08491 | K10: U | L10: 5494 | M10: 3.3 | N10: =ROUND(L10/M10, 0) | O10: =ROUND(N10*'Methodology & Assumptions'!$B$7, 0) | P10: Single Carrier (Band n50, 100MHz TDD) | Q10: =ROUNDUP(O10/'Methodology & Assumptions'!$B$8, 0) | R10: 1 | S10: 0.99 | T10: 0.1 | U10: =IF(S10<='Methodology & Assumptions'!$B$10, "Direct Optical Drop (<3km)", IF(S10<='Methodology & Assumptions'!$B$9, "Near Optical / Microwave (<5km)", "Starlink Business LEO Satellite Backhaul (>5km)")) | V10: 77.68 | W10: 77.59 | X10: =ROUND(('Methodology & Assumptions'!$B$5*V10) + ('Methodology & Assumptions'!$B$6*W10), 2) | Y10: 7.2 | Z10: Priority Tier 1 (High Commercial & Social)
A11: 1 | B11: 7 | C11: 7 | D11: 0403403005 | E11: Region IV-A (CALABARZON) | F11: Laguna | G11: City of Biñan | H11: Casile | I11: 14.344552 | J11: 121.08747 | K11: R | L11: 4648 | M11: 3.3 | N11: =ROUND(L11/M11, 0) | O11: =ROUND(N11*'Methodology & Assumptions'!$B$7, 0) | P11: Single Carrier (Band n50, 100MHz TDD) | Q11: =ROUNDUP(O11/'Methodology & Assumptions'!$B$8, 0) | R11: 1 | S11: 1.42 | T11: 0.64 | U11: =IF(S11<='Methodology & Assumptions'!$B$10, "Direct Optical Drop (<3km)", IF(S11<='Methodology & Assumptions'!$B$9, "Near Optical / Microwave (<5km)", "Starlink Business LEO Satellite Backhaul (>5km)")) | V11: 83.26 | W11: 71.95 | X11: =ROUND(('Methodology & Assumptions'!$B$5*V11) + ('Methodology & Assumptions'!$B$6*W11), 2) | Y11: 7.2 | Z11: Priority Tier 1 (High Commercial & Social)
A12: 1 | B12: 8 | C12: 8 | D12: 0402104019 | E12: Region IV-A (CALABARZON) | F12: Cavite | G12: Carmona | H12: Barangay 8 | I12: 14.311477 | J12: 121.05077 | K12: R | L12: 3290 | M12: 3.4 | N12: =ROUND(L12/M12, 0) | O12: =ROUND(N12*'Methodology & Assumptions'!$B$7, 0) | P12: Single Carrier (Band n50, 100MHz TDD) | Q12: =ROUNDUP(O12/'Methodology & Assumptions'!$B$8, 0) | R12: 1 | S12: 0.1 | T12: 0.1 | U12: =IF(S12<='Methodology & Assumptions'!$B$10, "Direct Optical Drop (<3km)", IF(S12<='Methodology & Assumptions'!$B$9, "Near Optical / Microwave (<5km)", "Starlink Business LEO Satellite Backhaul (>5km)")) | V12: 85.46 | W12: 69.42 | X12: =ROUND(('Methodology & Assumptions'!$B$5*V12) + ('Methodology & Assumptions'!$B$6*W12), 2) | Y12: 7.2 | Z12: Priority Tier 1 (High Commercial & Social)
A13: 1 | B13: 9 | C13: 9 | D13: 0403403020 | E13: Region IV-A (CALABARZON) | F13: Laguna | G13: City of Biñan | H13: San Jose | I13: 14.344025 | J13: 121.08237 | K13: U | L13: 7234 | M13: 3.3 | N13: =ROUND(L13/M13, 0) | O13: =ROUND(N13*'Methodology & Assumptions'!$B$7, 0) | P13: Single Carrier (Band n50, 100MHz TDD) | Q13: =ROUNDUP(O13/'Methodology & Assumptions'!$B$8, 0) | R13: 1 | S13: 0.93 | T13: 0.57 | U13: =IF(S13<='Methodology & Assumptions'!$B$10, "Direct Optical Drop (<3km)", IF(S13<='Methodology & Assumptions'!$B$9, "Near Optical / Microwave (<5km)", "Starlink Business LEO Satellite Backhaul (>5km)")) | V13: 77.91 | W13: 76.84 | X13: =ROUND(('Methodology & Assumptions'!$B$5*V13) + ('Methodology & Assumptions'!$B$6*W13), 2) | Y13: 7.2 | Z13: Priority Tier 1 (High Commercial & Social)
A14: 1 | B14: 10 | C14: 10 | D14: 0405805019 | E14: Region IV-A (CALABARZON) | F14: Rizal | G14: Cainta | H14: Santo Niño | I14: 14.58193 | J14: 121.118 | K14: U | L14: 6105 | M14: 3.6 | N14: =ROUND(L14/M14, 0) | O14: =ROUND(N14*'Methodology & Assumptions'!$B$7, 0) | P14: Single Carrier (Band n50, 100MHz TDD) | Q14: =ROUNDUP(O14/'Methodology & Assumptions'!$B$8, 0) | R14: 1 | S14: 0.62 | T14: 0.38 | U14: =IF(S14<='Methodology & Assumptions'!$B$10, "Direct Optical Drop (<3km)", IF(S14<='Methodology & Assumptions'!$B$9, "Near Optical / Microwave (<5km)", "Starlink Business LEO Satellite Backhaul (>5km)")) | V14: 78.26 | W14: 76.49 | X14: =ROUND(('Methodology & Assumptions'!$B$5*V14) + ('Methodology & Assumptions'!$B$6*W14), 2) | Y14: 7.2 | Z14: Priority Tier 1 (High Commercial & Social)
A15: 1 | B15: 11 | C15: 11 | D15: 0402106072 | E15: Region IV-A (CALABARZON) | F15: Cavite | G15: City of Dasmariñas | H15: San Luis II | I15: 14.312847 | J15: 120.9626 | K15: R | L15: 4565 | M15: 3.4 | N15: =ROUND(L15/M15, 0) | O15: =ROUND(N15*'Methodology & Assumptions'!$B$7, 0) | P15: Single Carrier (Band n50, 100MHz TDD) | Q15: =ROUNDUP(O15/'Methodology & Assumptions'!$B$8, 0) | R15: 1 | S15: 0.34 | T15: 1.54 | U15: =IF(S15<='Methodology & Assumptions'!$B$10, "Direct Optical Drop (<3km)", IF(S15<='Methodology & Assumptions'!$B$9, "Near Optical / Microwave (<5km)", "Starlink Business LEO Satellite Backhaul (>5km)")) | V15: 85.46 | W15: 69.18 | X15: =ROUND(('Methodology & Assumptions'!$B$5*V15) + ('Methodology & Assumptions'!$B$6*W15), 2) | Y15: 7.2 | Z15: Priority Tier 1 (High Commercial & Social)
A16: 1 | B16: 12 | C16: 12 | D16: 0102815010 | E16: Region I (Ilocos Region) | F16: Ilocos Norte | G16: Pagudpud | H16: Pancian | I16: 18.518279 | J16: 120.88434 | K16: R | L16: 2434 | M16: 3.7 | N16: =ROUND(L16/M16, 0) | O16: =ROUND(N16*'Methodology & Assumptions'!$B$7, 0) | P16: Single Carrier (Band n50, 100MHz TDD) | Q16: =ROUNDUP(O16/'Methodology & Assumptions'!$B$8, 0) | R16: 1 | S16: 5.73 | T16: 5.69 | U16: =IF(S16<='Methodology & Assumptions'!$B$10, "Direct Optical Drop (<3km)", IF(S16<='Methodology & Assumptions'!$B$9, "Near Optical / Microwave (<5km)", "Starlink Business LEO Satellite Backhaul (>5km)")) | V16: 64.22 | W16: 90.26 | X16: =ROUND(('Methodology & Assumptions'!$B$5*V16) + ('Methodology & Assumptions'!$B$6*W16), 2) | Y16: 8.3 | Z16: Priority Tier 1 (High Commercial & Social)
... A1004: 1 | B1004: 1000 | C1004: 1000 | D1004: 0201528020 | E1004: Region II (Cagayan Valley) | F1004: Cagayan | G1004: Tuao | H1004: Mambacag | I1004: 17.6625 | J1004: 121.5503 | K1004: R | L1004: 1447 | M1004: 3.9 | N1004: =ROUND(L1004/M1004, 0) | O1004: =ROUND(N1004*'Methodology & Assumptions'!$B$7, 0) | P1004: Single Carrier (Band n50, 100MHz TDD) | Q1004: =ROUNDUP(O1004/'Methodology & Assumptions'!$B$8, 0) | R1004: 1 | S1004: 4.16 | T1004: 12.31 | U1004: =IF(S1004<='Methodology & Assumptions'!$B$10, "Direct Optical Drop (<3km)", IF(S1004<='Methodology & Assumptions'!$B$9, "Near Optical / Microwave (<5km)", "Starlink Business LEO Satellite Backhaul (>5km)")) | V1004: 57.61 | W1004: 73.56 | X1004: =ROUND(('Methodology & Assumptions'!$B$5*V1004) + ('Methodology & Assumptions'!$B$6*W1004), 2) | Y1004: 8.3 | Z1004: Priority Tier 2 (Balanced Opportunity)
A1005: BATCH TOTAL / AVERAGE | L1005: =SUM(L5:L1004) | N1005: =SUM(N5:N1004) | O1005: =SUM(O5:O1004) | Q1005: =SUM(Q5:Q1004) | R1005: =SUM(R5:R1004) | S1005: =AVERAGE(S5:S1004) | V1005: =AVERAGE(V5:V1004) | W1005: =AVERAGE(W5:W1004) | X1005: =AVERAGE(X5:X1004)

Sheet Batch 2 (1,001 - 2,000)
A1: 5G FWA Combined Hybrid Siting Rollout Schedule - Batch 2 (1,001 - 2,000)
A2: Dynamic Hybrid deployment rollout schedule (1,000 sites), linked to live parameters in 'Methodology & Assumptions'.
A4: Batch | B4: Batch Rank | C4: Overall Rank | D4: PSGC | E4: Region | F4: Province | G4: Municipality | H4: Barangay | I4: Latitude | J4: Longitude | K4: U/R | L4: 2024 Population | M4: 2024 Avg HH Size | N4: 2024 Households | O4: Target Subs (30%) | P4: Carrier Spectrum | Q4: Peak BTS Required | R4: Day 1 BTS Deployed | S4: Dist to Node (km) | T4: Dist to Line (km) | U4: Backhaul Architecture | V4: Commercial Score | W4: Normalized GIDA Score | X4: Combined Hybrid Score | Y4: Regional Poverty % | Z4: Strategic Classification
A5: 2 | B5: 1 | C5: 1001 | D5: 1380610040 | E5: National Capital Region (NCR) | F5: First District (Not a Province) | G5: City of Manila | H5: Barangay 725 | I5: 14.565586 | J5: 120.99516 | K5: U | L5: 1990 | M5: 3.31 | N5: =ROUND(L5/M5, 0) | O5: =ROUND(N5*'Methodology & Assumptions'!$B$7, 0) | P5: Single Carrier (Band n50, 100MHz TDD) | Q5: =ROUNDUP(O5/'Methodology & Assumptions'!$B$8, 0) | R5: 1 | S5: 0.72 | T5: 0.13 | U5: =IF(S5<='Methodology & Assumptions'!$B$10, "Direct Optical Drop (<3km)", IF(S5<='Methodology & Assumptions'!$B$9, "Near Optical / Microwave (<5km)", "Starlink Business LEO Satellite Backhaul (>5km)")) | V5: 60.48 | W5: 70.66 | X5: =ROUND(('Methodology & Assumptions'!$B$5*V5) + ('Methodology & Assumptions'!$B$6*W5), 2) | Y5: 10.9 | Z5: Priority Tier 2 (Balanced Opportunity)
A6: 2 | B6: 2 | C6: 1002 | D6: 0403425022 | E6: Region IV-A (CALABARZON) | F6: Laguna | G6: City of San Pedro | H6: Narra | I6: 14.342174 | J6: 121.03575 | K6: R | L6: 2518 | M6: 3.3 | N6: =ROUND(L6/M6, 0) | O6: =ROUND(N6*'Methodology & Assumptions'!$B$7, 0) | P6: Single Carrier (Band n50, 100MHz TDD) | Q6: =ROUNDUP(O6/'Methodology & Assumptions'!$B$8, 0) | R6: 1 | S6: 0.55 | T6: 0.57 | U6: =IF(S6<='Methodology & Assumptions'!$B$10, "Direct Optical Drop (<3km)", IF(S6<='Methodology & Assumptions'!$B$9, "Near Optical / Microwave (<5km)", "Starlink Business LEO Satellite Backhaul (>5km)")) | V6: 83.77 | W6: 47.35 | X6: =ROUND(('Methodology & Assumptions'!$B$5*V6) + ('Methodology & Assumptions'!$B$6*W6), 2) | Y6: 7.2 | Z6: Priority Tier 2 (Balanced Opportunity)
A7: 2 | B7: 3 | C7: 1003 | D7: 1381300105 | E7: National Capital Region (NCR) | F7: Second District (Not a Province) | G7: Quezon City | H7: Santa Lucia | I7: 14.70738 | J7: 121.0534 | K7: U | L7: 28974 | M7: 4.06 | N7: =ROUND(L7/M7, 0) | O7: =ROUND(N7*'Methodology & Assumptions'!$B$7, 0) | P7: Single Carrier (Band n50, 100MHz TDD) | Q7: =ROUNDUP(O7/'Methodology & Assumptions'!$B$8, 0) | R7: 1 | S7: 1.99 | T7: 0.88 | U7: =IF(S7<='Methodology & Assumptions'!$B$10, "Direct Optical Drop (<3km)", IF(S7<='Methodology & Assumptions'!$B$9, "Near Optical / Microwave (<5km)", "Starlink Business LEO Satellite Backhaul (>5km)")) | V7: 63.58 | W7: 67.54 | X7: =ROUND(('Methodology & Assumptions'!$B$5*V7) + ('Methodology & Assumptions'!$B$6*W7), 2) | Y7: 10.9 | Z7: Priority Tier 2 (Balanced Opportunity)
A8: 2 | B8: 4 | C8: 1004 | D8: 0306916074 | E8: Region III (Central Luzon) | F8: Tarlac | G8: City of Tarlac | H8: San Sebastian | I8: 15.471129 | J8: 120.5973 | K8: U | L8: 4413 | M8: 3.9 | N8: =ROUND(L8/M8, 0) | O8: =ROUND(N8*'Methodology & Assumptions'!$B$7, 0) | P8: Single Carrier (Band n50, 100MHz TDD) | Q8: =ROUNDUP(O8/'Methodology & Assumptions'!$B$8, 0) | R8: 1 | S8: 1.91 | T8: 0.17 | U8: =IF(S8<='Methodology & Assumptions'!$B$10, "Direct Optical Drop (<3km)", IF(S8<='Methodology & Assumptions'!$B$9, "Near Optical / Microwave (<5km)", "Starlink Business LEO Satellite Backhaul (>5km)")) | V8: 74.49 | W8: 56.61 | X8: =ROUND(('Methodology & Assumptions'!$B$5*V8) + ('Methodology & Assumptions'!$B$6*W8), 2) | Y8: 8.3 | Z8: Priority Tier 2 (Balanced Opportunity)
A9: 2 | B9: 5 | C9: 1005 | D9: 1381600022 | E9: National Capital Region (NCR) | F9: Third District (Not a Province) | G9: City of Valenzuela | H9: Pariancillo Villa | I9: 14.70716 | J9: 120.9444 | K9: U | L9: 1989 | M9: 3.75 | N9: =ROUND(L9/M9, 0) | O9: =ROUND(N9*'Methodology & Assumptions'!$B$7, 0) | P9: Single Carrier (Band n50, 100MHz TDD) | Q9: =ROUNDUP(O9/'Methodology & Assumptions'!$B$8, 0) | R9: 1 | S9: 0.87 | T9: 1.53 | U9: =IF(S9<='Methodology & Assumptions'!$B$10, "Direct Optical Drop (<3km)", IF(S9<='Methodology & Assumptions'!$B$9, "Near Optical / Microwave (<5km)", "Starlink Business LEO Satellite Backhaul (>5km)")) | V9: 58.02 | W9: 73.08 | X9: =ROUND(('Methodology & Assumptions'!$B$5*V9) + ('Methodology & Assumptions'!$B$6*W9), 2) | Y9: 10.9 | Z9: Priority Tier 2 (Balanced Opportunity)
A10: 2 | B10: 6 | C10: 1006 | D10: 0203133017 | E10: Region II (Cagayan Valley) | F10: Isabela | G10: San Pablo | H10: Tupa | I10: 17.503857 | J10: 122.01555 | K10: R | L10: 2485 | M10: 3.8 | N10: =ROUND(L10/M10, 0) | O10: =ROUND(N10*'Methodology & Assumptions'!$B$7, 0) | P10: Single Carrier (Band n50, 100MHz TDD) | Q10: =ROUNDUP(O10/'Methodology & Assumptions'!$B$8, 0) | R10: 1 | S10: 26.98 | T10: 22.34 | U10: =IF(S10<='Methodology & Assumptions'!$B$10, "Direct Optical Drop (<3km)", IF(S10<='Methodology & Assumptions'!$B$9, "Near Optical / Microwave (<5km)", "Starlink Business LEO Satellite Backhaul (>5km)")) | V10: 55.01 | W10: 76.1 | X10: =ROUND(('Methodology & Assumptions'!$B$5*V10) + ('Methodology & Assumptions'!$B$6*W10), 2) | Y10: 8.3 | Z10: Priority Tier 2 (Balanced Opportunity)
A11: 2 | B11: 7 | C11: 1007 | D11: 0604531010 | E11: Region VI (Western Visayas) | F11: Negros Occidental | G11: City of Victorias | H11: Barangay VII | I11: 10.89671 | J11: 123.07514 | K11: R | L11: 3980 | M11: 3.7 | N11: =ROUND(L11/M11, 0) | O11: =ROUND(N11*'Methodology & Assumptions'!$B$7, 0) | P11: Single Carrier (Band n50, 100MHz TDD) | Q11: =ROUNDUP(O11/'Methodology & Assumptions'!$B$8, 0) | R11: 1 | S11: 0.58 | T11: 0.34 | U11: =IF(S11<='Methodology & Assumptions'!$B$10, "Direct Optical Drop (<3km)", IF(S11<='Methodology & Assumptions'!$B$9, "Near Optical / Microwave (<5km)", "Starlink Business LEO Satellite Backhaul (>5km)")) | V11: 88.06 | W11: 43.02 | X11: =ROUND(('Methodology & Assumptions'!$B$5*V11) + ('Methodology & Assumptions'!$B$6*W11), 2) | Y11: 23.7 | Z11: Priority Tier 2 (Balanced Opportunity)
A12: 2 | B12: 8 | C12: 1008 | D12: 1908704005 | E12: Bangsamoro Autonomous Region In Muslim Mindanao (BARMM) | F12: Maguindanao del Norte | G12: Datu Blah T. Sinsuat | H12: Meti | I12: 6.795228 | J12: 124.0255 | K12: R | L12: 4330 | M12: 4.3 | N12: =ROUND(L12/M12, 0) | O12: =ROUND(N12*'Methodology & Assumptions'!$B$7, 0) | P12: Single Carrier (Band n50, 100MHz TDD) | Q12: =ROUNDUP(O12/'Methodology & Assumptions'!$B$8, 0) | R12: 1 | S12: 72.52 | T12: 72.47 | U12: =IF(S12<='Methodology & Assumptions'!$B$10, "Direct Optical Drop (<3km)", IF(S12<='Methodology & Assumptions'!$B$9, "Near Optical / Microwave (<5km)", "Starlink Business LEO Satellite Backhaul (>5km)")) | V12: 59.06 | W12: 72.02 | X12: =ROUND(('Methodology & Assumptions'!$B$5*V12) + ('Methodology & Assumptions'!$B$6*W12), 2) | Y12: 11 | Z12: Priority Tier 2 (Balanced Opportunity)
A13: 2 | B13: 9 | C13: 1009 | D13: 1705320018 | E13: MIMAROPA Region | F13: Palawan | G13: Taytay | H13: Pancol | I13: 10.872224 | J13: 119.417 | K13: R | L13: 3530 | M13: 3.9 | N13: =ROUND(L13/M13, 0) | O13: =ROUND(N13*'Methodology & Assumptions'!$B$7, 0) | P13: Single Carrier (Band n50, 100MHz TDD) | Q13: =ROUNDUP(O13/'Methodology & Assumptions'!$B$8, 0) | R13: 1 | S13: 0.07 | T13: 10.83 | U13: =IF(S13<='Methodology & Assumptions'!$B$10, "Direct Optical Drop (<3km)", IF(S13<='Methodology & Assumptions'!$B$9, "Near Optical / Microwave (<5km)", "Starlink Business LEO Satellite Backhaul (>5km)")) | V13: 86.38 | W13: 44.68 | X13: =ROUND(('Methodology & Assumptions'!$B$5*V13) + ('Methodology & Assumptions'!$B$6*W13), 2) | Y13: 15 | Z13: Priority Tier 2 (Balanced Opportunity)
A14: 2 | B14: 10 | C14: 1010 | D14: 1108601007 | E14: Region XI (Davao Region) | F14: Davao Occidental | G14: Don Marcelino | H14: Baluntaya | I14: 6.220523 | J14: 125.63689 | K14: R | L14: 2604 | M14: 3.6 | N14: =ROUND(L14/M14, 0) | O14: =ROUND(N14*'Methodology & Assumptions'!$B$7, 0) | P14: Single Carrier (Band n50, 100MHz TDD) | Q14: =ROUNDUP(O14/'Methodology & Assumptions'!$B$8, 0) | R14: 1 | S14: 41.7 | T14: 41.85 | U14: =IF(S14<='Methodology & Assumptions'!$B$10, "Direct Optical Drop (<3km)", IF(S14<='Methodology & Assumptions'!$B$9, "Near Optical / Microwave (<5km)", "Starlink Business LEO Satellite Backhaul (>5km)")) | V14: 57.83 | W14: 73.24 | X14: =ROUND(('Methodology & Assumptions'!$B$5*V14) + ('Methodology & Assumptions'!$B$6*W14), 2) | Y14: 17.4 | Z14: Priority Tier 2 (Balanced Opportunity)
A15: 2 | B15: 11 | C15: 1011 | D15: 0102820012 | E15: Region I (Ilocos Region) | F15: Ilocos Norte | G15: San Nicolas | H15: San Juan Bautista | I15: 18.172448 | J15: 120.60345 | K15: R | L15: 2985 | M15: 3.7 | N15: =ROUND(L15/M15, 0) | O15: =ROUND(N15*'Methodology & Assumptions'!$B$7, 0) | P15: Single Carrier (Band n50, 100MHz TDD) | Q15: =ROUNDUP(O15/'Methodology & Assumptions'!$B$8, 0) | R15: 1 | S15: 1.09 | T15: 1.05 | U15: =IF(S15<='Methodology & Assumptions'!$B$10, "Direct Optical Drop (<3km)", IF(S15<='Methodology & Assumptions'!$B$9, "Near Optical / Microwave (<5km)", "Starlink Business LEO Satellite Backhaul (>5km)")) | V15: 84.29 | W15: 46.76 | X15: =ROUND(('Methodology & Assumptions'!$B$5*V15) + ('Methodology & Assumptions'!$B$6*W15), 2) | Y15: 8.3 | Z15: Priority Tier 2 (Balanced Opportunity)
A16: 2 | B16: 12 | C16: 1012 | D16: 0102820011 | E16: Region I (Ilocos Region) | F16: Ilocos Norte | G16: San Nicolas | H16: San Jose | I16: 18.172744 | J16: 120.5923 | K16: R | L16: 1474 | M16: 3.7 | N16: =ROUND(L16/M16, 0) | O16: =ROUND(N16*'Methodology & Assumptions'!$B$7, 0) | P16: Single Carrier (Band n50, 100MHz TDD) | Q16: =ROUNDUP(O16/'Methodology & Assumptions'!$B$8, 0) | R16: 1 | S16: 0.29 | T16: 0.16 | U16: =IF(S16<='Methodology & Assumptions'!$B$10, "Direct Optical Drop (<3km)", IF(S16<='Methodology & Assumptions'!$B$9, "Near Optical / Microwave (<5km)", "Starlink Business LEO Satellite Backhaul (>5km)")) | V16: 71.92 | W16: 59.12 | X16: =ROUND(('Methodology & Assumptions'!$B$5*V16) + ('Methodology & Assumptions'!$B$6*W16), 2) | Y16: 8.3 | Z16: Priority Tier 2 (Balanced Opportunity)
... A1004: 2 | B1004: 1000 | C1004: 2000 | D1004: 1380614076 | E1004: National Capital Region (NCR) | F1004: First District (Not a Province) | G1004: City of Manila | H1004: Barangay 883 | I1004: 14.579492 | J1004: 121.01429 | K1004: U | L1004: 2239 | M1004: 4.32 | N1004: =ROUND(L1004/M1004, 0) | O1004: =ROUND(N1004*'Methodology & Assumptions'!$B$7, 0) | P1004: Single Carrier (Band n50, 100MHz TDD) | Q1004: =ROUNDUP(O1004/'Methodology & Assumptions'!$B$8, 0) | R1004: 1 | S1004: 1.35 | T1004: 0.27 | U1004: =IF(S1004<='Methodology & Assumptions'!$B$10, "Direct Optical Drop (<3km)", IF(S1004<='Methodology & Assumptions'!$B$9, "Near Optical / Microwave (<5km)", "Starlink Business LEO Satellite Backhaul (>5km)")) | V1004: 55.74 | W1004: 68.92 | X1004: =ROUND(('Methodology & Assumptions'!$B$5*V1004) + ('Methodology & Assumptions'!$B$6*W1004), 2) | Y1004: 10.9 | Z1004: Priority Tier 2 (Balanced Opportunity)
A1005: BATCH TOTAL / AVERAGE | L1005: =SUM(L5:L1004) | N1005: =SUM(N5:N1004) | O1005: =SUM(O5:O1004) | Q1005: =SUM(Q5:Q1004) | R1005: =SUM(R5:R1004) | S1005: =AVERAGE(S5:S1004) | V1005: =AVERAGE(V5:V1004) | W1005: =AVERAGE(W5:W1004) | X1005: =AVERAGE(X5:X1004)

Sheet Batch 3 (2,001 - 3,000)
A1: 5G FWA Combined Hybrid Siting Rollout Schedule - Batch 3 (2,001 - 3,000)
A2: Dynamic Hybrid deployment rollout schedule (1,000 sites), linked to live parameters in 'Methodology & Assumptions'.
A4: Batch | B4: Batch Rank | C4: Overall Rank | D4: PSGC | E4: Region | F4: Province | G4: Municipality | H4: Barangay | I4: Latitude | J4: Longitude | K4: U/R | L4: 2024 Population | M4: 2024 Avg HH Size | N4: 2024 Households | O4: Target Subs (30%) | P4: Carrier Spectrum | Q4: Peak BTS Required | R4: Day 1 BTS Deployed | S4: Dist to Node (km) | T4: Dist to Line (km) | U4: Backhaul Architecture | V4: Commercial Score | W4: Normalized GIDA Score | X4: Combined Hybrid Score | Y4: Regional Poverty % | Z4: Strategic Classification
A5: 3 | B5: 1 | C5: 2001 | D5: 1380606134 | E5: National Capital Region (NCR) | F5: First District (Not a Province) | G5: City of Manila | H5: Barangay 528 | I5: 14.615369 | J5: 121.00041 | K5: U | L5: 1510 | M5: 3.91 | N5: =ROUND(L5/M5, 0) | O5: =ROUND(N5*'Methodology & Assumptions'!$B$7, 0) | P5: Single Carrier (Band n50, 100MHz TDD) | Q5: =ROUNDUP(O5/'Methodology & Assumptions'!$B$8, 0) | R5: 1 | S5: 0.61 | T5: 0.27 | U5: =IF(S5<='Methodology & Assumptions'!$B$10, "Direct Optical Drop (<3km)", IF(S5<='Methodology & Assumptions'!$B$9, "Near Optical / Microwave (<5km)", "Starlink Business LEO Satellite Backhaul (>5km)")) | V5: 53.52 | W5: 71.15 | X5: =ROUND(('Methodology & Assumptions'!$B$5*V5) + ('Methodology & Assumptions'!$B$6*W5), 2) | Y5: 10.9 | Z5: Priority Tier 2 (Balanced Opportunity)
A6: 3 | B6: 2 | C6: 2002 | D6: 0403410018 | E6: Region IV-A (CALABARZON) | F6: Laguna | G6: Liliw | H6: Ilayang Palina | I6: 14.137028 | J6: 121.43039 | K6: R | L6: 2517 | M6: 3.3 | N6: =ROUND(L6/M6, 0) | O6: =ROUND(N6*'Methodology & Assumptions'!$B$7, 0) | P6: Single Carrier (Band n50, 100MHz TDD) | Q6: =ROUNDUP(O6/'Methodology & Assumptions'!$B$8, 0) | R6: 1 | S6: 0.64 | T6: 0.39 | U6: =IF(S6<='Methodology & Assumptions'!$B$10, "Direct Optical Drop (<3km)", IF(S6<='Methodology & Assumptions'!$B$9, "Near Optical / Microwave (<5km)", "Starlink Business LEO Satellite Backhaul (>5km)")) | V6: 83.77 | W6: 40.87 | X6: =ROUND(('Methodology & Assumptions'!$B$5*V6) + ('Methodology & Assumptions'!$B$6*W6), 2) | Y6: 7.2 | Z6: Priority Tier 2 (Balanced Opportunity)
A7: 3 | B7: 3 | C7: 2003 | D7: 1908824007 | E7: Bangsamoro Autonomous Region In Muslim Mindanao (BARMM) | F7: Maguindanao del Sur | G7: Talayan | H7: Katibpuan | I7: 6.888491 | J7: 124.29772 | K7: R | L7: 3559 | M7: 4.7 | N7: =ROUND(L7/M7, 0) | O7: =ROUND(N7*'Methodology & Assumptions'!$B$7, 0) | P7: Single Carrier (Band n50, 100MHz TDD) | Q7: =ROUNDUP(O7/'Methodology & Assumptions'!$B$8, 0) | R7: 1 | S7: 47.02 | T7: 46.96 | U7: =IF(S7<='Methodology & Assumptions'!$B$10, "Direct Optical Drop (<3km)", IF(S7<='Methodology & Assumptions'!$B$9, "Near Optical / Microwave (<5km)", "Starlink Business LEO Satellite Backhaul (>5km)")) | V7: 55.36 | W7: 69.27 | X7: =ROUND(('Methodology & Assumptions'!$B$5*V7) + ('Methodology & Assumptions'!$B$6*W7), 2) | Y7: 11 | Z7: Priority Tier 2 (Balanced Opportunity)
A8: 3 | B8: 4 | C8: 2004 | D8: 1381100174 | E8: National Capital Region (NCR) | F8: Fourth District (Not a Province) | G8: Pasay City | H8: Barangay 174 | I8: 14.533705 | J8: 121.01083 | K8: U | L8: 1710 | M8: 3.56 | N8: =ROUND(L8/M8, 0) | O8: =ROUND(N8*'Methodology & Assumptions'!$B$7, 0) | P8: Single Carrier (Band n50, 100MHz TDD) | Q8: =ROUNDUP(O8/'Methodology & Assumptions'!$B$8, 0) | R8: 1 | S8: 1.41 | T8: 0.75 | U8: =IF(S8<='Methodology & Assumptions'!$B$10, "Direct Optical Drop (<3km)", IF(S8<='Methodology & Assumptions'!$B$9, "Near Optical / Microwave (<5km)", "Starlink Business LEO Satellite Backhaul (>5km)")) | V8: 54.38 | W8: 70.26 | X8: =ROUND(('Methodology & Assumptions'!$B$5*V8) + ('Methodology & Assumptions'!$B$6*W8), 2) | Y8: 10.9 | Z8: Priority Tier 2 (Balanced Opportunity)
A9: 3 | B9: 5 | C9: 2005 | D9: 0201521026 | E9: Region II (Cagayan Valley) | F9: Cagayan | G9: Rizal | H9: Battut | I9: 17.828537 | J9: 121.3465 | K9: R | L9: 523 | M9: 3.6 | N9: =ROUND(L9/M9, 0) | O9: =ROUND(N9*'Methodology & Assumptions'!$B$7, 0) | P9: Single Carrier (Band n50, 100MHz TDD) | Q9: =ROUNDUP(O9/'Methodology & Assumptions'!$B$8, 0) | R9: 1 | S9: 4.24 | T9: 3.29 | U9: =IF(S9<='Methodology & Assumptions'!$B$10, "Direct Optical Drop (<3km)", IF(S9<='Methodology & Assumptions'!$B$9, "Near Optical / Microwave (<5km)", "Starlink Business LEO Satellite Backhaul (>5km)")) | V9: 52.83 | W9: 71.82 | X9: =ROUND(('Methodology & Assumptions'!$B$5*V9) + ('Methodology & Assumptions'!$B$6*W9), 2) | Y9: 8.3 | Z9: Priority Tier 2 (Balanced Opportunity)
A10: 3 | B10: 6 | C10: 2006 | D10: 0307708008 | E10: Region III (Central Luzon) | F10: Aurora | G10: San Luis | H10: Dibut | I10: 15.654161 | J10: 121.54842 | K10: R | L10: 577 | M10: 3.8 | N10: =ROUND(L10/M10, 0) | O10: =ROUND(N10*'Methodology & Assumptions'!$B$7, 0) | P10: Single Carrier (Band n50, 100MHz TDD) | Q10: =ROUNDUP(O10/'Methodology & Assumptions'!$B$8, 0) | R10: 1 | S10: 10.06 | T10: 10.84 | U10: =IF(S10<='Methodology & Assumptions'!$B$10, "Direct Optical Drop (<3km)", IF(S10<='Methodology & Assumptions'!$B$9, "Near Optical / Microwave (<5km)", "Starlink Business LEO Satellite Backhaul (>5km)")) | V10: 43.46 | W10: 81.18 | X10: =ROUND(('Methodology & Assumptions'!$B$5*V10) + ('Methodology & Assumptions'!$B$6*W10), 2) | Y10: 8.3 | Z10: Priority Tier 2 (Balanced Opportunity)
A11: 3 | B11: 7 | C11: 2007 | D11: 0304930052 | E11: Region III (Central Luzon) | F11: Nueva Ecija | G11: Talavera | H11: San Ricardo | I11: 15.589465 | J11: 120.92308 | K11: R | L11: 3018 | M11: 3.5 | N11: =ROUND(L11/M11, 0) | O11: =ROUND(N11*'Methodology & Assumptions'!$B$7, 0) | P11: Single Carrier (Band n50, 100MHz TDD) | Q11: =ROUNDUP(O11/'Methodology & Assumptions'!$B$8, 0) | R11: 1 | S11: 0.93 | T11: 0.37 | U11: =IF(S11<='Methodology & Assumptions'!$B$10, "Direct Optical Drop (<3km)", IF(S11<='Methodology & Assumptions'!$B$9, "Near Optical / Microwave (<5km)", "Starlink Business LEO Satellite Backhaul (>5km)")) | V11: 85.31 | W11: 39.32 | X11: =ROUND(('Methodology & Assumptions'!$B$5*V11) + ('Methodology & Assumptions'!$B$6*W11), 2) | Y11: 8.3 | Z11: Priority Tier 2 (Balanced Opportunity)
A12: 3 | B12: 8 | C12: 2008 | D12: 0102820016 | E12: Region I (Ilocos Region) | F12: Ilocos Norte | G12: San Nicolas | H12: San Miguel | I12: 18.168722 | J12: 120.60201 | K12: R | L12: 1725 | M12: 3.7 | N12: =ROUND(L12/M12, 0) | O12: =ROUND(N12*'Methodology & Assumptions'!$B$7, 0) | P12: Single Carrier (Band n50, 100MHz TDD) | Q12: =ROUNDUP(O12/'Methodology & Assumptions'!$B$8, 0) | R12: 1 | S12: 0.93 | T12: 0.96 | U12: =IF(S12<='Methodology & Assumptions'!$B$10, "Direct Optical Drop (<3km)", IF(S12<='Methodology & Assumptions'!$B$9, "Near Optical / Microwave (<5km)", "Starlink Business LEO Satellite Backhaul (>5km)")) | V12: 73.86 | W12: 50.77 | X12: =ROUND(('Methodology & Assumptions'!$B$5*V12) + ('Methodology & Assumptions'!$B$6*W12), 2) | Y12: 8.3 | Z12: Priority Tier 2 (Balanced Opportunity)
A13: 3 | B13: 9 | C13: 2009 | D13: 0702234022 | E13: Region VII (Central Visayas) | F13: Cebu | G13: City of Naga | H13: South Poblacion | I13: 10.207186 | J13: 123.75546 | K13: U | L13: 7068 | M13: 3.8 | N13: =ROUND(L13/M13, 0) | O13: =ROUND(N13*'Methodology & Assumptions'!$B$7, 0) | P13: Single Carrier (Band n50, 100MHz TDD) | Q13: =ROUNDUP(O13/'Methodology & Assumptions'!$B$8, 0) | R13: 1 | S13: 3.3 | T13: 0.28 | U13: =IF(S13<='Methodology & Assumptions'!$B$10, "Direct Optical Drop (<3km)", IF(S13<='Methodology & Assumptions'!$B$9, "Near Optical / Microwave (<5km)", "Starlink Business LEO Satellite Backhaul (>5km)")) | V13: 72.73 | W13: 51.9 | X13: =ROUND(('Methodology & Assumptions'!$B$5*V13) + ('Methodology & Assumptions'!$B$6*W13), 2) | Y13: 23.7 | Z13: Priority Tier 2 (Balanced Opportunity)
A14: 3 | B14: 10 | C14: 2010 | D14: 1381300021 | E14: National Capital Region (NCR) | F14: Second District (Not a Province) | G14: Quezon City | H14: Claro | I14: 14.646362 | J14: 121.04159 | K14: U | L14: 3996 | M14: 3.44 | N14: =ROUND(L14/M14, 0) | O14: =ROUND(N14*'Methodology & Assumptions'!$B$7, 0) | P14: Single Carrier (Band n50, 100MHz TDD) | Q14: =ROUNDUP(O14/'Methodology & Assumptions'!$B$8, 0) | R14: 1 | S14: 0.49 | T14: 0.09 | U14: =IF(S14<='Methodology & Assumptions'!$B$10, "Direct Optical Drop (<3km)", IF(S14<='Methodology & Assumptions'!$B$9, "Near Optical / Microwave (<5km)", "Starlink Business LEO Satellite Backhaul (>5km)")) | V14: 69.09 | W14: 55.53 | X14: =ROUND(('Methodology & Assumptions'!$B$5*V14) + ('Methodology & Assumptions'!$B$6*W14), 2) | Y14: 10.9 | Z14: Priority Tier 2 (Balanced Opportunity)
A15: 3 | B15: 11 | C15: 2011 | D15: 1380601205 | E15: National Capital Region (NCR) | F15: First District (Not a Province) | G15: City of Manila | H15: Barangay 204 | I15: 14.627614 | J15: 120.97689 | K15: U | L15: 1932 | M15: 4.1 | N15: =ROUND(L15/M15, 0) | O15: =ROUND(N15*'Methodology & Assumptions'!$B$7, 0) | P15: Single Carrier (Band n50, 100MHz TDD) | Q15: =ROUNDUP(O15/'Methodology & Assumptions'!$B$8, 0) | R15: 1 | S15: 0.39 | T15: 0.17 | U15: =IF(S15<='Methodology & Assumptions'!$B$10, "Direct Optical Drop (<3km)", IF(S15<='Methodology & Assumptions'!$B$9, "Near Optical / Microwave (<5km)", "Starlink Business LEO Satellite Backhaul (>5km)")) | V15: 56.2 | W15: 68.43 | X15: =ROUND(('Methodology & Assumptions'!$B$5*V15) + ('Methodology & Assumptions'!$B$6*W15), 2) | Y15: 10.9 | Z15: Priority Tier 2 (Balanced Opportunity)
A16: 3 | B16: 12 | C16: 2012 | D16: 1003514013 | E16: Region X (Northern Mindanao) | F16: Lanao del Norte | G16: Munai | H16: Lininding | I16: 7.996 | J16: 124.0978 | K16: R | L16: 1863 | M16: 4.2 | N16: =ROUND(L16/M16, 0) | O16: =ROUND(N16*'Methodology & Assumptions'!$B$7, 0) | P16: Single Carrier (Band n50, 100MHz TDD) | Q16: =ROUNDUP(O16/'Methodology & Assumptions'!$B$8, 0) | R16: 1 | S16: 19.5 | T16: 18.2 | U16: =IF(S16<='Methodology & Assumptions'!$B$10, "Direct Optical Drop (<3km)", IF(S16<='Methodology & Assumptions'!$B$9, "Near Optical / Microwave (<5km)", "Starlink Business LEO Satellite Backhaul (>5km)")) | V16: 49.07 | W16: 75.54 | X16: =ROUND(('Methodology & Assumptions'!$B$5*V16) + ('Methodology & Assumptions'!$B$6*W16), 2) | Y16: 17.4 | Z16: Priority Tier 2 (Balanced Opportunity)
... A1004: 3 | B1004: 1000 | C1004: 3000 | D1004: 1380605060 | E1004: National Capital Region (NCR) | F1004: First District (Not a Province) | G1004: City of Manila | H1004: Barangay 358 | I1004: 14.619976 | J1004: 120.9819 | K1004: U | L1004: 1167 | M1004: 4.04 | N1004: =ROUND(L1004/M1004, 0) | O1004: =ROUND(N1004*'Methodology & Assumptions'!$B$7, 0) | P1004: Single Carrier (Band n50, 100MHz TDD) | Q1004: =ROUNDUP(O1004/'Methodology & Assumptions'!$B$8, 0) | R1004: 1 | S1004: 0.4 | T1004: 0.1 | U1004: =IF(S1004<='Methodology & Assumptions'!$B$10, "Direct Optical Drop (<3km)", IF(S1004<='Methodology & Assumptions'!$B$9, "Near Optical / Microwave (<5km)", "Starlink Business LEO Satellite Backhaul (>5km)")) | V1004: 50.41 | W1004: 70.08 | X1004: =ROUND(('Methodology & Assumptions'!$B$5*V1004) + ('Methodology & Assumptions'!$B$6*W1004), 2) | Y1004: 10.9 | Z1004: Priority Tier 2 (Balanced Opportunity)
A1005: BATCH TOTAL / AVERAGE | L1005: =SUM(L5:L1004) | N1005: =SUM(N5:N1004) | O1005: =SUM(O5:O1004) | Q1005: =SUM(Q5:Q1004) | R1005: =SUM(R5:R1004) | S1005: =AVERAGE(S5:S1004) | V1005: =AVERAGE(V5:V1004) | W1005: =AVERAGE(W5:W1004) | X1005: =AVERAGE(X5:X1004)

Sheet Batch 4 & 5 (3,001 - 5,000)
A1: 5G FWA Combined Hybrid Siting Rollout Schedule - Batch 4 & 5 (3,001 - 5,000)
A2: Dynamic Hybrid deployment rollout schedule (2,000 sites), linked to live parameters in 'Methodology & Assumptions'.
A4: Batch | B4: Batch Rank | C4: Overall Rank | D4: PSGC | E4: Region | F4: Province | G4: Municipality | H4: Barangay | I4: Latitude | J4: Longitude | K4: U/R | L4: 2024 Population | M4: 2024 Avg HH Size | N4: 2024 Households | O4: Target Subs (30%) | P4: Carrier Spectrum | Q4: Peak BTS Required | R4: Day 1 BTS Deployed | S4: Dist to Node (km) | T4: Dist to Line (km) | U4: Backhaul Architecture | V4: Commercial Score | W4: Normalized GIDA Score | X4: Combined Hybrid Score | Y4: Regional Poverty % | Z4: Strategic Classification
A5: 4 | B5: 1 | C5: 3001 | D5: 1102509013 | E5: Region XI (Davao Region) | F5: Davao Oriental | G5: City of Mati | H5: Langka | I5: 6.398023 | J5: 126.19255 | K5: R | L5: 1281 | M5: 3.6 | N5: =ROUND(L5/M5, 0) | O5: =ROUND(N5*'Methodology & Assumptions'!$B$7, 0) | P5: Single Carrier (Band n50, 100MHz TDD) | Q5: =ROUNDUP(O5/'Methodology & Assumptions'!$B$8, 0) | R5: 1 | S5: 58.87 | T5: 54.17 | U5: =IF(S5<='Methodology & Assumptions'!$B$10, "Direct Optical Drop (<3km)", IF(S5<='Methodology & Assumptions'!$B$9, "Near Optical / Microwave (<5km)", "Starlink Business LEO Satellite Backhaul (>5km)")) | V5: 46.37 | W5: 74.14 | X5: =ROUND(('Methodology & Assumptions'!$B$5*V5) + ('Methodology & Assumptions'!$B$6*W5), 2) | Y5: 17.4 | Z5: Priority Tier 2 (Balanced Opportunity)
A6: 4 | B6: 2 | C6: 3002 | D6: 0205009016 | E6: Region II (Cagayan Valley) | F6: Nueva Vizcaya | G6: Kasibu | H6: Malabing | I6: 16.382091 | J6: 121.37989 | K6: R | L6: 887 | M6: 3.8 | N6: =ROUND(L6/M6, 0) | O6: =ROUND(N6*'Methodology & Assumptions'!$B$7, 0) | P6: Single Carrier (Band n50, 100MHz TDD) | Q6: =ROUNDUP(O6/'Methodology & Assumptions'!$B$8, 0) | R6: 1 | S6: 11.69 | T6: 23.3 | U6: =IF(S6<='Methodology & Assumptions'!$B$10, "Direct Optical Drop (<3km)", IF(S6<='Methodology & Assumptions'!$B$9, "Near Optical / Microwave (<5km)", "Starlink Business LEO Satellite Backhaul (>5km)")) | V6: 44.23 | W6: 76.26 | X6: =ROUND(('Methodology & Assumptions'!$B$5*V6) + ('Methodology & Assumptions'!$B$6*W6), 2) | Y6: 8.3 | Z6: Priority Tier 2 (Balanced Opportunity)
A7: 4 | B7: 3 | C7: 3003 | D7: 0306917019 | E7: Region III (Central Luzon) | F7: Tarlac | G7: Victoria | H7: San Fernando | I7: 15.57405 | J7: 120.6795 | K7: R | L7: 3472 | M7: 3.9 | N7: =ROUND(L7/M7, 0) | O7: =ROUND(N7*'Methodology & Assumptions'!$B$7, 0) | P7: Single Carrier (Band n50, 100MHz TDD) | Q7: =ROUNDUP(O7/'Methodology & Assumptions'!$B$8, 0) | R7: 1 | S7: 0.15 | T7: 6.27 | U7: =IF(S7<='Methodology & Assumptions'!$B$10, "Direct Optical Drop (<3km)", IF(S7<='Methodology & Assumptions'!$B$9, "Near Optical / Microwave (<5km)", "Starlink Business LEO Satellite Backhaul (>5km)")) | V7: 84.96 | W7: 35.51 | X7: =ROUND(('Methodology & Assumptions'!$B$5*V7) + ('Methodology & Assumptions'!$B$6*W7), 2) | Y7: 8.3 | Z7: Priority Tier 2 (Balanced Opportunity)
A8: 4 | B8: 4 | C8: 3004 | D8: 0304903008 | E8: Region III (Central Luzon) | F8: Nueva Ecija | G8: City of Cabanatuan | H8: Balite | I8: 15.585783 | J8: 120.92458 | K8: R | L8: 2515 | M8: 3.5 | N8: =ROUND(L8/M8, 0) | O8: =ROUND(N8*'Methodology & Assumptions'!$B$7, 0) | P8: Single Carrier (Band n50, 100MHz TDD) | Q8: =ROUNDUP(O8/'Methodology & Assumptions'!$B$8, 0) | R8: 1 | S8: 0.71 | T8: 0.52 | U8: =IF(S8<='Methodology & Assumptions'!$B$10, "Direct Optical Drop (<3km)", IF(S8<='Methodology & Assumptions'!$B$9, "Near Optical / Microwave (<5km)", "Starlink Business LEO Satellite Backhaul (>5km)")) | V8: 82.42 | W8: 38.05 | X8: =ROUND(('Methodology & Assumptions'!$B$5*V8) + ('Methodology & Assumptions'!$B$6*W8), 2) | Y8: 8.3 | Z8: Priority Tier 2 (Balanced Opportunity)
A9: 4 | B9: 5 | C9: 3005 | D9: 0301418010 | E9: Region III (Central Luzon) | F9: Bulacan | G9: Pulilan | H9: Longos | I9: 14.893601 | J9: 120.86572 | K9: U | L9: 6080 | M9: 3.5 | N9: =ROUND(L9/M9, 0) | O9: =ROUND(N9*'Methodology & Assumptions'!$B$7, 0) | P9: Single Carrier (Band n50, 100MHz TDD) | Q9: =ROUNDUP(O9/'Methodology & Assumptions'!$B$8, 0) | R9: 1 | S9: 1.89 | T9: 0.08 | U9: =IF(S9<='Methodology & Assumptions'!$B$10, "Direct Optical Drop (<3km)", IF(S9<='Methodology & Assumptions'!$B$9, "Near Optical / Microwave (<5km)", "Starlink Business LEO Satellite Backhaul (>5km)")) | V9: 74.58 | W9: 45.9 | X9: =ROUND(('Methodology & Assumptions'!$B$5*V9) + ('Methodology & Assumptions'!$B$6*W9), 2) | Y9: 8.3 | Z9: Priority Tier 2 (Balanced Opportunity)
A10: 4 | B10: 6 | C10: 3006 | D10: 1402706011 | E10: Cordillera Administrative Region (CAR) | F10: Ifugao | G10: Mayoyao | H10: Chumang | I10: 16.97058 | J10: 121.25924 | K10: R | L10: 1064 | M10: 3.9 | N10: =ROUND(L10/M10, 0) | O10: =ROUND(N10*'Methodology & Assumptions'!$B$7, 0) | P10: Single Carrier (Band n50, 100MHz TDD) | Q10: =ROUNDUP(O10/'Methodology & Assumptions'!$B$8, 0) | R10: 1 | S10: 3.99 | T10: 21.83 | U10: =IF(S10<='Methodology & Assumptions'!$B$10, "Direct Optical Drop (<3km)", IF(S10<='Methodology & Assumptions'!$B$9, "Near Optical / Microwave (<5km)", "Starlink Business LEO Satellite Backhaul (>5km)")) | V10: 53.71 | W10: 66.77 | X10: =ROUND(('Methodology & Assumptions'!$B$5*V10) + ('Methodology & Assumptions'!$B$6*W10), 2) | Y10: 10.9 | Z10: Priority Tier 2 (Balanced Opportunity)
A11: 4 | B11: 7 | C11: 3007 | D11: 1380601005 | E11: National Capital Region (NCR) | F11: First District (Not a Province) | G11: City of Manila | H11: Barangay 5 | I11: 14.608393 | J11: 120.96688 | K11: U | L11: 1321 | M11: 4.68 | N11: =ROUND(L11/M11, 0) | O11: =ROUND(N11*'Methodology & Assumptions'!$B$7, 0) | P11: Single Carrier (Band n50, 100MHz TDD) | Q11: =ROUNDUP(O11/'Methodology & Assumptions'!$B$8, 0) | R11: 1 | S11: 0.35 | T11: 0.28 | U11: =IF(S11<='Methodology & Assumptions'!$B$10, "Direct Optical Drop (<3km)", IF(S11<='Methodology & Assumptions'!$B$9, "Near Optical / Microwave (<5km)", "Starlink Business LEO Satellite Backhaul (>5km)")) | V11: 50.2 | W11: 70.29 | X11: =ROUND(('Methodology & Assumptions'!$B$5*V11) + ('Methodology & Assumptions'!$B$6*W11), 2) | Y11: 10.9 | Z11: Priority Tier 2 (Balanced Opportunity)
A12: 4 | B12: 8 | C12: 3008 | D12: 1102319010 | E12: Region XI (Davao Region) | F12: Davao del Norte | G12: City of Tagum | H12: Magdum | I12: 7.469378 | J12: 125.83438 | K12: U | L12: 13786 | M12: 3.7 | N12: =ROUND(L12/M12, 0) | O12: =ROUND(N12*'Methodology & Assumptions'!$B$7, 0) | P12: Single Carrier (Band n50, 100MHz TDD) | Q12: =ROUNDUP(O12/'Methodology & Assumptions'!$B$8, 0) | R12: 1 | S12: 1.84 | T12: 0.11 | U12: =IF(S12<='Methodology & Assumptions'!$B$10, "Direct Optical Drop (<3km)", IF(S12<='Methodology & Assumptions'!$B$9, "Near Optical / Microwave (<5km)", "Starlink Business LEO Satellite Backhaul (>5km)")) | V12: 76.17 | W12: 44.28 | X12: =ROUND(('Methodology & Assumptions'!$B$5*V12) + ('Methodology & Assumptions'!$B$6*W12), 2) | Y12: 17.4 | Z12: Priority Tier 2 (Balanced Opportunity)
A13: 4 | B13: 9 | C13: 3009 | D13: 1381100056 | E13: National Capital Region (NCR) | F13: Fourth District (Not a Province) | G13: Pasay City | H13: Barangay 56 | I13: 14.551506 | J13: 121.0004 | K13: U | L13: 1083 | M13: 3.72 | N13: =ROUND(L13/M13, 0) | O13: =ROUND(N13*'Methodology & Assumptions'!$B$7, 0) | P13: Single Carrier (Band n50, 100MHz TDD) | Q13: =ROUNDUP(O13/'Methodology & Assumptions'!$B$8, 0) | R13: 1 | S13: 0.96 | T13: 0.27 | U13: =IF(S13<='Methodology & Assumptions'!$B$10, "Direct Optical Drop (<3km)", IF(S13<='Methodology & Assumptions'!$B$9, "Near Optical / Microwave (<5km)", "Starlink Business LEO Satellite Backhaul (>5km)")) | V13: 49.97 | W13: 70.48 | X13: =ROUND(('Methodology & Assumptions'!$B$5*V13) + ('Methodology & Assumptions'!$B$6*W13), 2) | Y13: 10.9 | Z13: Priority Tier 2 (Balanced Opportunity)
A14: 4 | B14: 10 | C14: 3010 | D14: 1381100146 | E14: National Capital Region (NCR) | F14: Fourth District (Not a Province) | G14: Pasay City | H14: Barangay 146 | I14: 14.536309 | J14: 121.00082 | K14: U | L14: 992 | M14: 3.77 | N14: =ROUND(L14/M14, 0) | O14: =ROUND(N14*'Methodology & Assumptions'!$B$7, 0) | P14: Single Carrier (Band n50, 100MHz TDD) | Q14: =ROUNDUP(O14/'Methodology & Assumptions'!$B$8, 0) | R14: 1 | S14: 1.02 | T14: 0.09 | U14: =IF(S14<='Methodology & Assumptions'!$B$10, "Direct Optical Drop (<3km)", IF(S14<='Methodology & Assumptions'!$B$9, "Near Optical / Microwave (<5km)", "Starlink Business LEO Satellite Backhaul (>5km)")) | V14: 48.88 | W14: 71.58 | X14: =ROUND(('Methodology & Assumptions'!$B$5*V14) + ('Methodology & Assumptions'!$B$6*W14), 2) | Y14: 10.9 | Z14: Priority Tier 2 (Balanced Opportunity)
A15: 4 | B15: 11 | C15: 3011 | D15: 1003514001 | E15: Region X (Northern Mindanao) | F15: Lanao del Norte | G15: Munai | H15: Bacayawan | I15: 7.9604 | J15: 124.0416 | K15: R | L15: 1212 | M15: 4.2 | N15: =ROUND(L15/M15, 0) | O15: =ROUND(N15*'Methodology & Assumptions'!$B$7, 0) | P15: Single Carrier (Band n50, 100MHz TDD) | Q15: =ROUNDUP(O15/'Methodology & Assumptions'!$B$8, 0) | R15: 1 | S15: 26.21 | T15: 22.64 | U15: =IF(S15<='Methodology & Assumptions'!$B$10, "Direct Optical Drop (<3km)", IF(S15<='Methodology & Assumptions'!$B$9, "Near Optical / Microwave (<5km)", "Starlink Business LEO Satellite Backhaul (>5km)")) | V15: 44.28 | W15: 76.18 | X15: =ROUND(('Methodology & Assumptions'!$B$5*V15) + ('Methodology & Assumptions'!$B$6*W15), 2) | Y15: 17.4 | Z15: Priority Tier 2 (Balanced Opportunity)
A16: 4 | B16: 12 | C16: 3012 | D16: 1004313008 | E16: Region X (Northern Mindanao) | F16: Misamis Oriental | G16: Lagonglong | H16: Poblacion | I16: 8.806659 | J16: 124.78784 | K16: R | L16: 4238 | M16: 3.9 | N16: =ROUND(L16/M16, 0) | O16: =ROUND(N16*'Methodology & Assumptions'!$B$7, 0) | P16: Single Carrier (Band n50, 100MHz TDD) | Q16: =ROUNDUP(O16/'Methodology & Assumptions'!$B$8, 0) | R16: 1 | S16: 0.29 | T16: 0.05 | U16: =IF(S16<='Methodology & Assumptions'!$B$10, "Direct Optical Drop (<3km)", IF(S16<='Methodology & Assumptions'!$B$9, "Near Optical / Microwave (<5km)", "Starlink Business LEO Satellite Backhaul (>5km)")) | V16: 89.69 | W16: 30.74 | X16: =ROUND(('Methodology & Assumptions'!$B$5*V16) + ('Methodology & Assumptions'!$B$6*W16), 2) | Y16: 17.4 | Z16: Priority Tier 2 (Balanced Opportunity)
... A2004: 5 | B2004: 1000 | C2004: 5000 | D2004: 1206318006 | E2004: Region XII (SOCCSKSARGEN) | F2004: South Cotabato | G2004: Santo Niño | H2004: Poblacion | I2004: 17.890137 | J2004: 121.56554 | K2004: U | L2004: 11066 | M2004: 3.6 | N2004: =ROUND(L2004/M2004, 0) | O2004: =ROUND(N2004*'Methodology & Assumptions'!$B$7, 0) | P2004: Single Carrier (Band n50, 100MHz TDD) | Q2004: =ROUNDUP(O2004/'Methodology & Assumptions'!$B$8, 0) | R2004: 1 | S2004: 0.79 | T2004: 8.22 | U2004: =IF(S2004<='Methodology & Assumptions'!$B$10, "Direct Optical Drop (<3km)", IF(S2004<='Methodology & Assumptions'!$B$9, "Near Optical / Microwave (<5km)", "Starlink Business LEO Satellite Backhaul (>5km)")) | V2004: 76.56 | W2004: 38.05 | X2004: =ROUND(('Methodology & Assumptions'!$B$5*V2004) + ('Methodology & Assumptions'!$B$6*W2004), 2) | Y2004: 17.4 | Z2004: Priority Tier 3 (Broadband Expansion)
A2005: BATCH TOTAL / AVERAGE | L2005: =SUM(L5:L2004) | N2005: =SUM(N5:N2004) | O2005: =SUM(O5:O2004) | Q2005: =SUM(Q5:Q2004) | R2005: =SUM(R5:R2004) | S2005: =AVERAGE(S5:S2004) | V2005: =AVERAGE(V5:V2004) | W2005: =AVERAGE(W5:W2004) | X2005: =AVERAGE(X5:X2004)

Sheet Provincial Summary
A1: 5G FWA Combined Hybrid Siting - Provincial Aggregation Summary
A2: Distribution of 5,000 Prioritized Hybrid Sites across Provinces
A4: Region | B4: Province | C4: Hybrid Sites | D4: 2024 Population | E4: 2024 Households | F4: Target Subs | G4: Day 1 BTS | H4: Peak BTS | I4: Avg Combined Score | J4: Direct Fiber (<3km) | K4: Near Fiber (3-5km) | L4: Starlink LEO (>5km)
