Workbook

Sheet Read Me
A1: Philippine 5G FWA Barangay Siting Model — DICT / UNDP GIDA Prioritization Edition
A2: Companion Financial & Engineering Model | Band n50 (100MHz TDD) with DepEd School Campus Anchors
A4: Model Overview | B4: Evaluates and ranks Philippine barangays according to the official DICT / UNDP FPIAP GIDA Prioritization Decision Support Tool.
A5: Coordinate Provenance | B5: 100% sourced from DepEd Schools Locations Masterfile (01/29/2026). Zero duplicate coordinates guarantee via golden-spiral sector dispersion.
A6: GIDA Decision Support Tool | B6: Ingests 42,001 evaluated barangays with multi-criteria scores across 11 deprivation indicators.
A7: Demographic Baseline | B7: 2024 POPCEN (Proclamation No. 973) declaring 112,729,484 national population.
A8: Band n50 Radio Siting | B8: 1,000 subscribers per BTS total across 3 sectors (~333 subs/sector). Day 1 deploys 1 BTS per barangay; Peak expands to meet 30% take-up.
A9: Hybrid Optical & LEO Satellite | B9: Direct optical drop (<3km) along Converge backbone; Starlink Business LEO Satellite backhaul for remote sites (>5km).
A10: Workbook Tabs | B10: Read Me, Executive Summary, Methodology & Assumptions, Batch 1 to 5 schedules, Provincial Summary.

Sheet Executive Summary
A1: Dynamic 5G FWA Barangay Siting & Rollout Schedule (GIDA Model - Live Formulas)
A2: Automated sensitivity summary linked dynamically to 'Methodology & Assumptions' and Batch sheets.
A5: 5,000 | C5: 176,781 | E5: 1,358,095 | G5: 5,554 | I5: 1,887 | K5: 3,113
A6: =F21 | C6: =E16 | E6: =E21 | G6: =G21 | I6: =K21+L21 | K6: =M21
A7: Day 1 Initial Build (1 BTS/Site) | C7: @ 30% Target Take-Rate | E7: Full 5,000-Site Footprint | G7: @ 1,000 Subs / BTS Limit | I7: 37.7% within 5km of Fiber | K7: 62.3% Satellite Sited (>5km)
A13: MASTER 5-BATCH GIDA ROLLOUT & TRANSMISSION SUMMARY
A15: Rollout Phase | B15: Barangays | C15: 2024 Population | D15: 2024 Households | E15: Subs @ 30% | F15: Day 1 BTS | G15: Peak BTS | H15: Avg GIDA Score | I15: Tier 1 Critical | J15: Tier 2 High | K15: Direct Optical (<3km) | L15: Near Optical (<5km) | M15: Starlink LEO (>5km)
A16: Batch 1 (Phase 1) | B16: 1000 | C16: ='Batch 1 (First 1,000)'!L1005 | D16: ='Batch 1 (First 1,000)'!N1005 | E16: ='Batch 1 (First 1,000)'!O1005 | F16: ='Batch 1 (First 1,000)'!R1005 | G16: ='Batch 1 (First 1,000)'!Q1005 | H16: ='Batch 1 (First 1,000)'!X1005 | I16: =COUNTIF('Batch 1 (First 1,000)'!$U$5:$U$1004, "Tier 1*") | J16: =COUNTIF('Batch 1 (First 1,000)'!$U$5:$U$1004, "Tier 2*") | K16: =COUNTIF('Batch 1 (First 1,000)'!$V$5:$V$1004, "Direct Optical*") | L16: =COUNTIF('Batch 1 (First 1,000)'!$V$5:$V$1004, "Near Optical*") | M16: =COUNTIF('Batch 1 (First 1,000)'!$V$5:$V$1004, "Starlink*")
A17: Batch 2 (Phase 2) | B17: 1000 | C17: ='Batch 2 (1,001 - 2,000)'!L1005 | D17: ='Batch 2 (1,001 - 2,000)'!N1005 | E17: ='Batch 2 (1,001 - 2,000)'!O1005 | F17: ='Batch 2 (1,001 - 2,000)'!R1005 | G17: ='Batch 2 (1,001 - 2,000)'!Q1005 | H17: ='Batch 2 (1,001 - 2,000)'!X1005 | I17: =COUNTIF('Batch 2 (1,001 - 2,000)'!$U$5:$U$1004, "Tier 1*") | J17: =COUNTIF('Batch 2 (1,001 - 2,000)'!$U$5:$U$1004, "Tier 2*") | K17: =COUNTIF('Batch 2 (1,001 - 2,000)'!$V$5:$V$1004, "Direct Optical*") | L17: =COUNTIF('Batch 2 (1,001 - 2,000)'!$V$5:$V$1004, "Near Optical*") | M17: =COUNTIF('Batch 2 (1,001 - 2,000)'!$V$5:$V$1004, "Starlink*")
A18: Batch 3 (Phase 3) | B18: 1000 | C18: ='Batch 3 (2,001 - 3,000)'!L1005 | D18: ='Batch 3 (2,001 - 3,000)'!N1005 | E18: ='Batch 3 (2,001 - 3,000)'!O1005 | F18: ='Batch 3 (2,001 - 3,000)'!R1005 | G18: ='Batch 3 (2,001 - 3,000)'!Q1005 | H18: ='Batch 3 (2,001 - 3,000)'!X1005 | I18: =COUNTIF('Batch 3 (2,001 - 3,000)'!$U$5:$U$1004, "Tier 1*") | J18: =COUNTIF('Batch 3 (2,001 - 3,000)'!$U$5:$U$1004, "Tier 2*") | K18: =COUNTIF('Batch 3 (2,001 - 3,000)'!$V$5:$V$1004, "Direct Optical*") | L18: =COUNTIF('Batch 3 (2,001 - 3,000)'!$V$5:$V$1004, "Near Optical*") | M18: =COUNTIF('Batch 3 (2,001 - 3,000)'!$V$5:$V$1004, "Starlink*")
A19: Batch 4 (Phase 4) | B19: 1000 | C19: =SUM('Batch 4 & 5 (3,001 - 5,000)'!L5:L1004) | D19: =SUM('Batch 4 & 5 (3,001 - 5,000)'!N5:N1004) | E19: =SUM('Batch 4 & 5 (3,001 - 5,000)'!O5:O1004) | F19: =COUNT('Batch 4 & 5 (3,001 - 5,000)'!R5:R1004) | G19: =SUM('Batch 4 & 5 (3,001 - 5,000)'!Q5:Q1004) | H19: =AVERAGE('Batch 4 & 5 (3,001 - 5,000)'!X5:X1004) | I19: =COUNTIF('Batch 4 & 5 (3,001 - 5,000)'!$U$5:$U$1004, "Tier 1*") | J19: =COUNTIF('Batch 4 & 5 (3,001 - 5,000)'!$U$5:$U$1004, "Tier 2*") | K19: =COUNTIF('Batch 4 & 5 (3,001 - 5,000)'!$V$5:$V$1004, "Direct Optical*") | L19: =COUNTIF('Batch 4 & 5 (3,001 - 5,000)'!$V$5:$V$1004, "Near Optical*") | M19: =COUNTIF('Batch 4 & 5 (3,001 - 5,000)'!$V$5:$V$1004, "Starlink*")
A20: Batch 5 (Phase 5) | B20: 1000 | C20: =SUM('Batch 4 & 5 (3,001 - 5,000)'!L1005:L2004) | D20: =SUM('Batch 4 & 5 (3,001 - 5,000)'!N1005:N2004) | E20: =SUM('Batch 4 & 5 (3,001 - 5,000)'!O1005:O2004) | F20: =COUNT('Batch 4 & 5 (3,001 - 5,000)'!R1005:R2004) | G20: =SUM('Batch 4 & 5 (3,001 - 5,000)'!Q1005:Q2004) | H20: =AVERAGE('Batch 4 & 5 (3,001 - 5,000)'!X1005:X2004) | I20: =COUNTIF('Batch 4 & 5 (3,001 - 5,000)'!$U$1005:$U$2004, "Tier 1*") | J20: =COUNTIF('Batch 4 & 5 (3,001 - 5,000)'!$U$1005:$U$2004, "Tier 2*") | K20: =COUNTIF('Batch 4 & 5 (3,001 - 5,000)'!$V$1005:$V$2004, "Direct Optical*") | L20: =COUNTIF('Batch 4 & 5 (3,001 - 5,000)'!$V$1005:$V$2004, "Near Optical*") | M20: =COUNTIF('Batch 4 & 5 (3,001 - 5,000)'!$V$1005:$V$2004, "Starlink*")
A21: TOTAL (5,000 SITES) | B21: 5000 | C21: =SUM(C16:C20) | D21: =SUM(D16:D20) | E21: =SUM(E16:E20) | F21: =SUM(F16:F20) | G21: =SUM(G16:G20) | H21: =AVERAGE(H16:H20) | I21: =SUM(I16:I20) | J21: =SUM(J16:J20) | K21: =SUM(K16:K20) | L21: =SUM(L16:L20) | M21: =SUM(M16:M20)

Sheet Methodology & Assumptions
A1: Dynamic FWA GIDA Siting Parameters & Sensitivity Inputs (Editable)
A2: Changes to yellow-highlighted parameters below immediately and dynamically recalculate all batch sheets and executive summary tables.
A4: Parameter / Operational Lever | B4: Standard Value | C4: Technical Unit & Operational Definition
A5: Commercial Take Rate (Penetration) | B5: 0.3 | C5: 30% of addressable households in GIDA barangays subscribing to Band n50 FWA.
A6: Band n50 BTS Subscriber Capacity | B6: 1000 | C6: Dimensioning standard: 1,000 active subscribers per BTS (~333 per 120° sector).
A7: Tier 1 Critical GIDA Threshold | B7: 50 | C7: UNDP Multi-Criteria Score >= 50.0 indicates acute digital deprivation and isolation.
A8: Tier 2 High GIDA Threshold | B8: 40 | C8: UNDP Multi-Criteria Score between 40.0 and 49.9 indicates high digital necessity.
A9: Starlink LEO Distance Threshold (km) | B9: 5 | C9: Barangays > 5km from Converge backbone nodes are sited for Starlink satellite backhaul.
A10: Direct Optical Drop Distance (km) | B10: 3 | C10: Barangays < 3km from Converge optical nodes connect via direct optical fiber drop.
A11: Average Household Size (POPCEN 2024) | B11: 3.8 | C11: PSA 2024 Census national average household size (Proclamation No. 973).
A14: OFFICIAL UNDP / DICT FPIAP 11 MULTI-CRITERIA INDICATORS
A16: Indicator Name | B16: Weight | C16: Data Source | D16: Indicator Definition & Selection Rationale
A17: Mobile Downspeed | B17: 10% | C17: Ookla Speedtest | D17: Barangays with lowest mobile download speeds receive higher priority scores.
A18: FW4A Presence | B18: 10% | C18: Broadband Siting | D18: Measures presence of Fixed Wireless Access 4G/5G infrastructure (deficit = higher priority).
A19: Nighttime Lights | B19: 15% | C19: VIIRS Satellite | D19: Proxy for economic activity and electrification; lower radiance indicates isolated communities.
A20: Surrounding POIs | B20: 10% | C20: OSM POI Count | D20: Presence of schools, health stations, and municipal halls requiring broadband connectivity.
A21: Distance to Roads | B21: 15% | C21: GIS Distance | D21: Physical isolation from primary/secondary road networks (greater distance = higher GIDA score).
A22: Hazard Index | B22: 10% | C22: Multi-Hazard Score | D22: Vulnerability to typhoons, flooding, landslides, and natural disasters.
A23: Insurgency Count | B23: 10% | C23: Security Incident Log | D23: Conflict-affected areas and peace-building priority communities.
A24: Population | B24: 5% | C24: Demographic Reach | D24: Ensures sites reach meaningful population clusters while targeting isolated areas.
A25: Cell Tower Access | B25: 5% | C25: Tower Proximity | D25: Deficit in existing cellular tower coverage within 5-10km radius.
A26: Broadband Downspeed | B26: 10% | C26: Fixed Speedtest | D26: Acute deficit in wired fixed broadband connectivity.
A27: Poverty Incidence | B27: 10% | C27: PSA FIES Benchmark | D27: High proportion of impoverished households lacking commercial broadband access.

Sheet Batch 1 (First 1,000)
A1: 5G FWA GIDA Siting Rollout Schedule - Batch 1 (First 1,000)
A2: Dynamic GIDA deployment rollout schedule (1,000 sites), linked to live parameters in 'Methodology & Assumptions'.
A4: Batch | B4: Batch Rank | C4: Overall Rank | D4: PSGC | E4: Region | F4: Province | G4: Municipality | H4: Barangay | I4: Latitude | J4: Longitude | K4: U/R | L4: 2024 Population | M4: 2024 Avg HH Size | N4: 2024 Households | O4: Target Subs (30%) | P4: Carrier Spectrum | Q4: Peak BTS Required | R4: Day 1 BTS Deployed | S4: Dist to Node (km) | T4: Dist to Line (km) | U4: GIDA Priority Tier | V4: Backhaul Architecture | W4: Regional Poverty % | X4: Official GIDA Score | Y4: Normalized GIDA Score
A5: 1 | B5: 1 | C5: 1 | D5: 0102817011 | E5: Region I (Ilocos Region) | F5: Ilocos Norte | G5: Pasuquin | H5: Dilavo | I5: 18.431386 | J5: 120.58822 | K5: R | L5: 651 | M5: 3.7 | N5: =ROUND(L5/M5, 0) | O5: =ROUND(N5*'Methodology & Assumptions'!$B$5, 0) | P5: Single Carrier (Band n50, 100MHz TDD) | Q5: =ROUNDUP(O5/'Methodology & Assumptions'!$B$6, 0) | R5: 1 | S5: 3.17 | T5: 0.07 | U5: =IF(X5>='Methodology & Assumptions'!$B$7, "Tier 1 Critical GIDA (Score ≥ 50.0)", IF(X5>='Methodology & Assumptions'!$B$8, "Tier 2 High GIDA (Score 40.0–49.9)", "Tier 3 Moderate GIDA (Score < 40.0)")) | V5: =IF(S5<='Methodology & Assumptions'!$B$10, "Direct Optical Drop (<3km)", IF(S5<='Methodology & Assumptions'!$B$9, "Near Optical / Microwave (<5km)", "Starlink Business LEO Satellite Backhaul (>5km)")) | W5: 0.083 | X5: 63.17 | Y5: =ROUND(MIN(100, (X5/69.91)*100), 2)
A6: 1 | B6: 2 | C6: 2 | D6: 0102815010 | E6: Region I (Ilocos Region) | F6: Ilocos Norte | G6: Pagudpud | H6: Pancian | I6: 18.564538 | J6: 120.78777 | K6: R | L6: 2434 | M6: 3.7 | N6: =ROUND(L6/M6, 0) | O6: =ROUND(N6*'Methodology & Assumptions'!$B$5, 0) | P6: Single Carrier (Band n50, 100MHz TDD) | Q6: =ROUNDUP(O6/'Methodology & Assumptions'!$B$6, 0) | R6: 1 | S6: 3.67 | T6: 0.22 | U6: =IF(X6>='Methodology & Assumptions'!$B$7, "Tier 1 Critical GIDA (Score ≥ 50.0)", IF(X6>='Methodology & Assumptions'!$B$8, "Tier 2 High GIDA (Score 40.0–49.9)", "Tier 3 Moderate GIDA (Score < 40.0)")) | V6: =IF(S6<='Methodology & Assumptions'!$B$10, "Direct Optical Drop (<3km)", IF(S6<='Methodology & Assumptions'!$B$9, "Near Optical / Microwave (<5km)", "Starlink Business LEO Satellite Backhaul (>5km)")) | W6: 0.083 | X6: 63.1 | Y6: =ROUND(MIN(100, (X6/69.91)*100), 2)
A7: 1 | B7: 3 | C7: 3 | D7: 0102814010 | E7: Region I (Ilocos Region) | F7: Ilocos Norte | G7: Nueva Era | H7: Santo Niño | I7: 17.956048 | J7: 120.71477 | K7: R | L7: 1202 | M7: 3.7 | N7: =ROUND(L7/M7, 0) | O7: =ROUND(N7*'Methodology & Assumptions'!$B$5, 0) | P7: Single Carrier (Band n50, 100MHz TDD) | Q7: =ROUNDUP(O7/'Methodology & Assumptions'!$B$6, 0) | R7: 1 | S7: 6.74 | T7: 5.75 | U7: =IF(X7>='Methodology & Assumptions'!$B$7, "Tier 1 Critical GIDA (Score ≥ 50.0)", IF(X7>='Methodology & Assumptions'!$B$8, "Tier 2 High GIDA (Score 40.0–49.9)", "Tier 3 Moderate GIDA (Score < 40.0)")) | V7: =IF(S7<='Methodology & Assumptions'!$B$10, "Direct Optical Drop (<3km)", IF(S7<='Methodology & Assumptions'!$B$9, "Near Optical / Microwave (<5km)", "Starlink Business LEO Satellite Backhaul (>5km)")) | W7: 0.083 | X7: 62.97 | Y7: =ROUND(MIN(100, (X7/69.91)*100), 2)
A8: 1 | B8: 4 | C8: 4 | D8: 0205704021 | E8: Region II (Cagayan Valley) | F8: Quirino | G8: Maddela | H8: San Dionisio I | I8: 16.408116 | J8: 121.80125 | K8: R | L8: 561 | M8: 3.9 | N8: =ROUND(L8/M8, 0) | O8: =ROUND(N8*'Methodology & Assumptions'!$B$5, 0) | P8: Single Carrier (Band n50, 100MHz TDD) | Q8: =ROUNDUP(O8/'Methodology & Assumptions'!$B$6, 0) | R8: 1 | S8: 12.81 | T8: 13.93 | U8: =IF(X8>='Methodology & Assumptions'!$B$7, "Tier 1 Critical GIDA (Score ≥ 50.0)", IF(X8>='Methodology & Assumptions'!$B$8, "Tier 2 High GIDA (Score 40.0–49.9)", "Tier 3 Moderate GIDA (Score < 40.0)")) | V8: =IF(S8<='Methodology & Assumptions'!$B$10, "Direct Optical Drop (<3km)", IF(S8<='Methodology & Assumptions'!$B$9, "Near Optical / Microwave (<5km)", "Starlink Business LEO Satellite Backhaul (>5km)")) | W8: 0.083 | X8: 61.9 | Y8: =ROUND(MIN(100, (X8/69.91)*100), 2)
A9: 1 | B9: 5 | C9: 5 | D9: 1401113001 | E9: Cordillera Administrative Region (CAR) | F9: Benguet | G9: Tuba | H9: Ansagan | I9: 16.211943 | J9: 120.59839 | K9: R | L9: 2370 | M9: 3.5 | N9: =ROUND(L9/M9, 0) | O9: =ROUND(N9*'Methodology & Assumptions'!$B$5, 0) | P9: Single Carrier (Band n50, 100MHz TDD) | Q9: =ROUNDUP(O9/'Methodology & Assumptions'!$B$6, 0) | R9: 1 | S9: 11.04 | T9: 9.02 | U9: =IF(X9>='Methodology & Assumptions'!$B$7, "Tier 1 Critical GIDA (Score ≥ 50.0)", IF(X9>='Methodology & Assumptions'!$B$8, "Tier 2 High GIDA (Score 40.0–49.9)", "Tier 3 Moderate GIDA (Score < 40.0)")) | V9: =IF(S9<='Methodology & Assumptions'!$B$10, "Direct Optical Drop (<3km)", IF(S9<='Methodology & Assumptions'!$B$9, "Near Optical / Microwave (<5km)", "Starlink Business LEO Satellite Backhaul (>5km)")) | W9: 0.109 | X9: 61.88 | Y9: =ROUND(MIN(100, (X9/69.91)*100), 2)
A10: 1 | B10: 6 | C10: 6 | D10: 0102931005 | E10: Region I (Ilocos Region) | F10: Ilocos Sur | G10: Sugpon | H10: Danac | I10: 16.779255 | J10: 120.53947 | K10: R | L10: 605 | M10: 3.8 | N10: =ROUND(L10/M10, 0) | O10: =ROUND(N10*'Methodology & Assumptions'!$B$5, 0) | P10: Single Carrier (Band n50, 100MHz TDD) | Q10: =ROUNDUP(O10/'Methodology & Assumptions'!$B$6, 0) | R10: 1 | S10: 14.91 | T10: 12.82 | U10: =IF(X10>='Methodology & Assumptions'!$B$7, "Tier 1 Critical GIDA (Score ≥ 50.0)", IF(X10>='Methodology & Assumptions'!$B$8, "Tier 2 High GIDA (Score 40.0–49.9)", "Tier 3 Moderate GIDA (Score < 40.0)")) | V10: =IF(S10<='Methodology & Assumptions'!$B$10, "Direct Optical Drop (<3km)", IF(S10<='Methodology & Assumptions'!$B$9, "Near Optical / Microwave (<5km)", "Starlink Business LEO Satellite Backhaul (>5km)")) | W10: 0.083 | X10: 61.63 | Y10: =ROUND(MIN(100, (X10/69.91)*100), 2)
A11: 1 | B11: 7 | C11: 7 | D11: 1401105003 | E11: Cordillera Administrative Region (CAR) | F11: Benguet | G11: Buguias | H11: Amlimay | I11: 16.703902 | J11: 120.83063 | K11: R | L11: 2411 | M11: 3.5 | N11: =ROUND(L11/M11, 0) | O11: =ROUND(N11*'Methodology & Assumptions'!$B$5, 0) | P11: Single Carrier (Band n50, 100MHz TDD) | Q11: =ROUNDUP(O11/'Methodology & Assumptions'!$B$6, 0) | R11: 1 | S11: 1.78 | T11: 4.65 | U11: =IF(X11>='Methodology & Assumptions'!$B$7, "Tier 1 Critical GIDA (Score ≥ 50.0)", IF(X11>='Methodology & Assumptions'!$B$8, "Tier 2 High GIDA (Score 40.0–49.9)", "Tier 3 Moderate GIDA (Score < 40.0)")) | V11: =IF(S11<='Methodology & Assumptions'!$B$10, "Direct Optical Drop (<3km)", IF(S11<='Methodology & Assumptions'!$B$9, "Near Optical / Microwave (<5km)", "Starlink Business LEO Satellite Backhaul (>5km)")) | W11: 0.109 | X11: 61.49 | Y11: =ROUND(MIN(100, (X11/69.91)*100), 2)
A12: 1 | B12: 8 | C12: 8 | D12: 0102814001 | E12: Region I (Ilocos Region) | F12: Ilocos Norte | G12: Nueva Era | H12: Acnam | I12: 17.915082 | J12: 120.65574 | K12: R | L12: 779 | M12: 3.7 | N12: =ROUND(L12/M12, 0) | O12: =ROUND(N12*'Methodology & Assumptions'!$B$5, 0) | P12: Single Carrier (Band n50, 100MHz TDD) | Q12: =ROUNDUP(O12/'Methodology & Assumptions'!$B$6, 0) | R12: 1 | S12: 0.56 | T12: 0.57 | U12: =IF(X12>='Methodology & Assumptions'!$B$7, "Tier 1 Critical GIDA (Score ≥ 50.0)", IF(X12>='Methodology & Assumptions'!$B$8, "Tier 2 High GIDA (Score 40.0–49.9)", "Tier 3 Moderate GIDA (Score < 40.0)")) | V12: =IF(S12<='Methodology & Assumptions'!$B$10, "Direct Optical Drop (<3km)", IF(S12<='Methodology & Assumptions'!$B$9, "Near Optical / Microwave (<5km)", "Starlink Business LEO Satellite Backhaul (>5km)")) | W12: 0.083 | X12: 61.43 | Y12: =ROUND(MIN(100, (X12/69.91)*100), 2)
A13: 1 | B13: 9 | C13: 9 | D13: 0403418006 | E13: Region IV-A (CALABARZON) | F13: Laguna | G13: Paete | H13: Ilaya del Norte | I13: 14.367076 | J13: 121.5212 | K13: R | L13: 2622 | M13: 3.3 | N13: =ROUND(L13/M13, 0) | O13: =ROUND(N13*'Methodology & Assumptions'!$B$5, 0) | P13: Single Carrier (Band n50, 100MHz TDD) | Q13: =ROUNDUP(O13/'Methodology & Assumptions'!$B$6, 0) | R13: 1 | S13: 3.25 | T13: 4.25 | U13: =IF(X13>='Methodology & Assumptions'!$B$7, "Tier 1 Critical GIDA (Score ≥ 50.0)", IF(X13>='Methodology & Assumptions'!$B$8, "Tier 2 High GIDA (Score 40.0–49.9)", "Tier 3 Moderate GIDA (Score < 40.0)")) | V13: =IF(S13<='Methodology & Assumptions'!$B$10, "Direct Optical Drop (<3km)", IF(S13<='Methodology & Assumptions'!$B$9, "Near Optical / Microwave (<5km)", "Starlink Business LEO Satellite Backhaul (>5km)")) | W13: 0.072 | X13: 61.3 | Y13: =ROUND(MIN(100, (X13/69.91)*100), 2)
A14: 1 | B14: 10 | C14: 10 | D14: 0102807001 | E14: Region I (Ilocos Region) | F14: Ilocos Norte | G14: Carasi | H14: Angset | I14: 18.144871 | J14: 120.79511 | K14: R | L14: 179 | M14: 3.7 | N14: =ROUND(L14/M14, 0) | O14: =ROUND(N14*'Methodology & Assumptions'!$B$5, 0) | P14: Single Carrier (Band n50, 100MHz TDD) | Q14: =ROUNDUP(O14/'Methodology & Assumptions'!$B$6, 0) | R14: 1 | S14: 5.61 | T14: 5.27 | U14: =IF(X14>='Methodology & Assumptions'!$B$7, "Tier 1 Critical GIDA (Score ≥ 50.0)", IF(X14>='Methodology & Assumptions'!$B$8, "Tier 2 High GIDA (Score 40.0–49.9)", "Tier 3 Moderate GIDA (Score < 40.0)")) | V14: =IF(S14<='Methodology & Assumptions'!$B$10, "Direct Optical Drop (<3km)", IF(S14<='Methodology & Assumptions'!$B$9, "Near Optical / Microwave (<5km)", "Starlink Business LEO Satellite Backhaul (>5km)")) | W14: 0.083 | X14: 61.22 | Y14: =ROUND(MIN(100, (X14/69.91)*100), 2)
A15: 1 | B15: 11 | C15: 11 | D15: 0102818011 | E15: Region I (Ilocos Region) | F15: Ilocos Norte | G15: Piddig | H15: Estancia | I15: 18.158928 | J15: 120.76156 | K15: R | L15: 1853 | M15: 3.7 | N15: =ROUND(L15/M15, 0) | O15: =ROUND(N15*'Methodology & Assumptions'!$B$5, 0) | P15: Single Carrier (Band n50, 100MHz TDD) | Q15: =ROUNDUP(O15/'Methodology & Assumptions'!$B$6, 0) | R15: 1 | S15: 4.95 | T15: 3.77 | U15: =IF(X15>='Methodology & Assumptions'!$B$7, "Tier 1 Critical GIDA (Score ≥ 50.0)", IF(X15>='Methodology & Assumptions'!$B$8, "Tier 2 High GIDA (Score 40.0–49.9)", "Tier 3 Moderate GIDA (Score < 40.0)")) | V15: =IF(S15<='Methodology & Assumptions'!$B$10, "Direct Optical Drop (<3km)", IF(S15<='Methodology & Assumptions'!$B$9, "Near Optical / Microwave (<5km)", "Starlink Business LEO Satellite Backhaul (>5km)")) | W15: 0.083 | X15: 61.15 | Y15: =ROUND(MIN(100, (X15/69.91)*100), 2)
A16: 1 | B16: 12 | C16: 12 | D16: 0102814006 | E16: Region I (Ilocos Region) | F16: Ilocos Norte | G16: Nueva Era | H16: Caray | I16: 17.933509 | J16: 120.6862 | K16: R | L16: 837 | M16: 3.7 | N16: =ROUND(L16/M16, 0) | O16: =ROUND(N16*'Methodology & Assumptions'!$B$5, 0) | P16: Single Carrier (Band n50, 100MHz TDD) | Q16: =ROUNDUP(O16/'Methodology & Assumptions'!$B$6, 0) | R16: 1 | S16: 3.28 | T16: 2.99 | U16: =IF(X16>='Methodology & Assumptions'!$B$7, "Tier 1 Critical GIDA (Score ≥ 50.0)", IF(X16>='Methodology & Assumptions'!$B$8, "Tier 2 High GIDA (Score 40.0–49.9)", "Tier 3 Moderate GIDA (Score < 40.0)")) | V16: =IF(S16<='Methodology & Assumptions'!$B$10, "Direct Optical Drop (<3km)", IF(S16<='Methodology & Assumptions'!$B$9, "Near Optical / Microwave (<5km)", "Starlink Business LEO Satellite Backhaul (>5km)")) | W16: 0.083 | X16: 61.13 | Y16: =ROUND(MIN(100, (X16/69.91)*100), 2)
... A1004: 1 | B1004: 1000 | C1004: 1000 | D1004: 1380601128 | E1004: National Capital Region (NCR) | F1004: First District (Not a Province) | G1004: City of Manila | H1004: Barangay 128 | I1004: 12.99774 | J1004: 121.6162 | K1004: U | L1004: 24422 | M1004: 3.9 | N1004: =ROUND(L1004/M1004, 0) | O1004: =ROUND(N1004*'Methodology & Assumptions'!$B$5, 0) | P1004: Single Carrier (Band n50, 100MHz TDD) | Q1004: =ROUNDUP(O1004/'Methodology & Assumptions'!$B$6, 0) | R1004: 1 | S1004: 13.98 | T1004: 14.9 | U1004: =IF(X1004>='Methodology & Assumptions'!$B$7, "Tier 1 Critical GIDA (Score ≥ 50.0)", IF(X1004>='Methodology & Assumptions'!$B$8, "Tier 2 High GIDA (Score 40.0–49.9)", "Tier 3 Moderate GIDA (Score < 40.0)")) | V1004: =IF(S1004<='Methodology & Assumptions'!$B$10, "Direct Optical Drop (<3km)", IF(S1004<='Methodology & Assumptions'!$B$9, "Near Optical / Microwave (<5km)", "Starlink Business LEO Satellite Backhaul (>5km)")) | W1004: 0.109 | X1004: 51.25 | Y1004: =ROUND(MIN(100, (X1004/69.91)*100), 2)
A1005: BATCH TOTAL / AVERAGE | L1005: =SUM(L5:L1004) | N1005: =SUM(N5:N1004) | O1005: =SUM(O5:O1004) | Q1005: =SUM(Q5:Q1004) | R1005: =SUM(R5:R1004) | S1005: =AVERAGE(S5:S1004) | X1005: =AVERAGE(X5:X1004) | Y1005: =AVERAGE(Y5:Y1004)

Sheet Batch 2 (1,001 - 2,000)
A1: 5G FWA GIDA Siting Rollout Schedule - Batch 2 (1,001 - 2,000)
A2: Dynamic GIDA deployment rollout schedule (1,000 sites), linked to live parameters in 'Methodology & Assumptions'.
A4: Batch | B4: Batch Rank | C4: Overall Rank | D4: PSGC | E4: Region | F4: Province | G4: Municipality | H4: Barangay | I4: Latitude | J4: Longitude | K4: U/R | L4: 2024 Population | M4: 2024 Avg HH Size | N4: 2024 Households | O4: Target Subs (30%) | P4: Carrier Spectrum | Q4: Peak BTS Required | R4: Day 1 BTS Deployed | S4: Dist to Node (km) | T4: Dist to Line (km) | U4: GIDA Priority Tier | V4: Backhaul Architecture | W4: Regional Poverty % | X4: Official GIDA Score | Y4: Normalized GIDA Score
A5: 2 | B5: 1 | C5: 1001 | D5: 1108205016 | E5: Region XI (Davao Region) | F5: Davao de Oro | G5: Maragusan | H5: New Katipunan | I5: 7.304824 | J5: 126.11212 | K5: R | L5: 3073 | M5: 3.7 | N5: =ROUND(L5/M5, 0) | O5: =ROUND(N5*'Methodology & Assumptions'!$B$5, 0) | P5: Single Carrier (Band n50, 100MHz TDD) | Q5: =ROUNDUP(O5/'Methodology & Assumptions'!$B$6, 0) | R5: 1 | S5: 28.3 | T5: 27.46 | U5: =IF(X5>='Methodology & Assumptions'!$B$7, "Tier 1 Critical GIDA (Score ≥ 50.0)", IF(X5>='Methodology & Assumptions'!$B$8, "Tier 2 High GIDA (Score 40.0–49.9)", "Tier 3 Moderate GIDA (Score < 40.0)")) | V5: =IF(S5<='Methodology & Assumptions'!$B$10, "Direct Optical Drop (<3km)", IF(S5<='Methodology & Assumptions'!$B$9, "Near Optical / Microwave (<5km)", "Starlink Business LEO Satellite Backhaul (>5km)")) | W5: 0.174 | X5: 51.23 | Y5: =ROUND(MIN(100, (X5/69.91)*100), 2)
A6: 2 | B6: 2 | C6: 1002 | D6: 0802615011 | E6: Region VIII (Eastern Visayas) | F6: Eastern Samar | G6: Maydolong | H6: Omawas | I6: 11.531057 | J6: 125.47403 | K6: R | L6: 1082 | M6: 3.9 | N6: =ROUND(L6/M6, 0) | O6: =ROUND(N6*'Methodology & Assumptions'!$B$5, 0) | P6: Single Carrier (Band n50, 100MHz TDD) | Q6: =ROUNDUP(O6/'Methodology & Assumptions'!$B$6, 0) | R6: 1 | S6: 60.77 | T6: 61.29 | U6: =IF(X6>='Methodology & Assumptions'!$B$7, "Tier 1 Critical GIDA (Score ≥ 50.0)", IF(X6>='Methodology & Assumptions'!$B$8, "Tier 2 High GIDA (Score 40.0–49.9)", "Tier 3 Moderate GIDA (Score < 40.0)")) | V6: =IF(S6<='Methodology & Assumptions'!$B$10, "Direct Optical Drop (<3km)", IF(S6<='Methodology & Assumptions'!$B$9, "Near Optical / Microwave (<5km)", "Starlink Business LEO Satellite Backhaul (>5km)")) | W6: 0.237 | X6: 51.23 | Y6: =ROUND(MIN(100, (X6/69.91)*100), 2)
A7: 2 | B7: 3 | C7: 1003 | D7: PH0001003 | E7: VI | F7: Capiz | G7: Roxas City | H7: Poblacion IV | I7: 11.55885 | J7: 122.74812 | K7: R | L7: 2282 | M7: 3.8 | N7: =ROUND(L7/M7, 0) | O7: =ROUND(N7*'Methodology & Assumptions'!$B$5, 0) | P7: Single Carrier (Band n50, 100MHz TDD) | Q7: =ROUNDUP(O7/'Methodology & Assumptions'!$B$6, 0) | R7: 1 | S7: 3.34 | T7: 1.08 | U7: =IF(X7>='Methodology & Assumptions'!$B$7, "Tier 1 Critical GIDA (Score ≥ 50.0)", IF(X7>='Methodology & Assumptions'!$B$8, "Tier 2 High GIDA (Score 40.0–49.9)", "Tier 3 Moderate GIDA (Score < 40.0)")) | V7: =IF(S7<='Methodology & Assumptions'!$B$10, "Direct Optical Drop (<3km)", IF(S7<='Methodology & Assumptions'!$B$9, "Near Optical / Microwave (<5km)", "Starlink Business LEO Satellite Backhaul (>5km)")) | W7: 0.156 | X7: 51.22 | Y7: =ROUND(MIN(100, (X7/69.91)*100), 2)
A8: 2 | B8: 4 | C8: 1004 | D8: 0806008009 | E8: Region VIII (Eastern Visayas) | F8: Samar | G8: Hinabangan | H8: Lim-ao | I8: 11.71293 | J8: 125.09006 | K8: R | L8: 306 | M8: 4.1 | N8: =ROUND(L8/M8, 0) | O8: =ROUND(N8*'Methodology & Assumptions'!$B$5, 0) | P8: Single Carrier (Band n50, 100MHz TDD) | Q8: =ROUNDUP(O8/'Methodology & Assumptions'!$B$6, 0) | R8: 1 | S8: 53.49 | T8: 56.34 | U8: =IF(X8>='Methodology & Assumptions'!$B$7, "Tier 1 Critical GIDA (Score ≥ 50.0)", IF(X8>='Methodology & Assumptions'!$B$8, "Tier 2 High GIDA (Score 40.0–49.9)", "Tier 3 Moderate GIDA (Score < 40.0)")) | V8: =IF(S8<='Methodology & Assumptions'!$B$10, "Direct Optical Drop (<3km)", IF(S8<='Methodology & Assumptions'!$B$9, "Near Optical / Microwave (<5km)", "Starlink Business LEO Satellite Backhaul (>5km)")) | W8: 0.237 | X8: 51.22 | Y8: =ROUND(MIN(100, (X8/69.91)*100), 2)
A9: 2 | B9: 5 | C9: 1005 | D9: 1381200004 | E9: National Capital Region (NCR) | F9: Second District (Not a Province) | G9: City of Pasig | H9: Buting | I9: 14.555537 | J9: 121.066 | K9: U | L9: 10991 | M9: 3.4 | N9: =ROUND(L9/M9, 0) | O9: =ROUND(N9*'Methodology & Assumptions'!$B$5, 0) | P9: Single Carrier (Band n50, 100MHz TDD) | Q9: =ROUNDUP(O9/'Methodology & Assumptions'!$B$6, 0) | R9: 1 | S9: 1.23 | T9: 0.13 | U9: =IF(X9>='Methodology & Assumptions'!$B$7, "Tier 1 Critical GIDA (Score ≥ 50.0)", IF(X9>='Methodology & Assumptions'!$B$8, "Tier 2 High GIDA (Score 40.0–49.9)", "Tier 3 Moderate GIDA (Score < 40.0)")) | V9: =IF(S9<='Methodology & Assumptions'!$B$10, "Direct Optical Drop (<3km)", IF(S9<='Methodology & Assumptions'!$B$9, "Near Optical / Microwave (<5km)", "Starlink Business LEO Satellite Backhaul (>5km)")) | W9: 0.109 | X9: 51.21 | Y9: =ROUND(MIN(100, (X9/69.91)*100), 2)
A10: 2 | B10: 6 | C10: 1006 | D10: 1380606199 | E10: National Capital Region (NCR) | F10: First District (Not a Province) | G10: City of Manila | H10: Barangay 592 | I10: 12.896717 | J10: 121.97353 | K10: U | L10: 2443 | M10: 3.9 | N10: =ROUND(L10/M10, 0) | O10: =ROUND(N10*'Methodology & Assumptions'!$B$5, 0) | P10: Single Carrier (Band n50, 100MHz TDD) | Q10: =ROUNDUP(O10/'Methodology & Assumptions'!$B$6, 0) | R10: 1 | S10: 53.91 | T10: 54.12 | U10: =IF(X10>='Methodology & Assumptions'!$B$7, "Tier 1 Critical GIDA (Score ≥ 50.0)", IF(X10>='Methodology & Assumptions'!$B$8, "Tier 2 High GIDA (Score 40.0–49.9)", "Tier 3 Moderate GIDA (Score < 40.0)")) | V10: =IF(S10<='Methodology & Assumptions'!$B$10, "Direct Optical Drop (<3km)", IF(S10<='Methodology & Assumptions'!$B$9, "Near Optical / Microwave (<5km)", "Starlink Business LEO Satellite Backhaul (>5km)")) | W10: 0.109 | X10: 51.21 | Y10: =ROUND(MIN(100, (X10/69.91)*100), 2)
A11: 2 | B11: 7 | C11: 1007 | D11: 1908702010 | E11: Bangsamoro Autonomous Region In Muslim Mindanao (BARMM) | F11: Maguindanao del Norte | G11: Buldon | H11: Minabay | I11: 17.253888 | J11: 122.22793 | K11: R | L11: 5213 | M11: 4.3 | N11: =ROUND(L11/M11, 0) | O11: =ROUND(N11*'Methodology & Assumptions'!$B$5, 0) | P11: Single Carrier (Band n50, 100MHz TDD) | Q11: =ROUNDUP(O11/'Methodology & Assumptions'!$B$6, 0) | R11: 1 | S11: 29.27 | T11: 34.17 | U11: =IF(X11>='Methodology & Assumptions'!$B$7, "Tier 1 Critical GIDA (Score ≥ 50.0)", IF(X11>='Methodology & Assumptions'!$B$8, "Tier 2 High GIDA (Score 40.0–49.9)", "Tier 3 Moderate GIDA (Score < 40.0)")) | V11: =IF(S11<='Methodology & Assumptions'!$B$10, "Direct Optical Drop (<3km)", IF(S11<='Methodology & Assumptions'!$B$9, "Near Optical / Microwave (<5km)", "Starlink Business LEO Satellite Backhaul (>5km)")) | W11: 0.11 | X11: 51.21 | Y11: =ROUND(MIN(100, (X11/69.91)*100), 2)
A12: 2 | B12: 8 | C12: 1008 | D12: 1108601007 | E12: Region XI (Davao Region) | F12: Davao Occidental | G12: Don Marcelino | H12: Baluntaya | I12: 6.246129 | J12: 125.64025 | K12: R | L12: 2604 | M12: 3.6 | N12: =ROUND(L12/M12, 0) | O12: =ROUND(N12*'Methodology & Assumptions'!$B$5, 0) | P12: Single Carrier (Band n50, 100MHz TDD) | Q12: =ROUNDUP(O12/'Methodology & Assumptions'!$B$6, 0) | R12: 1 | S12: 43.01 | T12: 41.93 | U12: =IF(X12>='Methodology & Assumptions'!$B$7, "Tier 1 Critical GIDA (Score ≥ 50.0)", IF(X12>='Methodology & Assumptions'!$B$8, "Tier 2 High GIDA (Score 40.0–49.9)", "Tier 3 Moderate GIDA (Score < 40.0)")) | V12: =IF(S12<='Methodology & Assumptions'!$B$10, "Direct Optical Drop (<3km)", IF(S12<='Methodology & Assumptions'!$B$9, "Near Optical / Microwave (<5km)", "Starlink Business LEO Satellite Backhaul (>5km)")) | W12: 0.174 | X12: 51.2 | Y12: =ROUND(MIN(100, (X12/69.91)*100), 2)
A13: 2 | B13: 9 | C13: 1009 | D13: 1380604016 | E13: National Capital Region (NCR) | F13: First District (Not a Province) | G13: City of Manila | H13: Barangay 283 | I13: 12.734751 | J13: 121.63775 | K13: U | L13: 1386 | M13: 3.9 | N13: =ROUND(L13/M13, 0) | O13: =ROUND(N13*'Methodology & Assumptions'!$B$5, 0) | P13: Single Carrier (Band n50, 100MHz TDD) | Q13: =ROUNDUP(O13/'Methodology & Assumptions'!$B$6, 0) | R13: 1 | S13: 16.35 | T13: 16.32 | U13: =IF(X13>='Methodology & Assumptions'!$B$7, "Tier 1 Critical GIDA (Score ≥ 50.0)", IF(X13>='Methodology & Assumptions'!$B$8, "Tier 2 High GIDA (Score 40.0–49.9)", "Tier 3 Moderate GIDA (Score < 40.0)")) | V13: =IF(S13<='Methodology & Assumptions'!$B$10, "Direct Optical Drop (<3km)", IF(S13<='Methodology & Assumptions'!$B$9, "Near Optical / Microwave (<5km)", "Starlink Business LEO Satellite Backhaul (>5km)")) | W13: 0.109 | X13: 51.2 | Y13: =ROUND(MIN(100, (X13/69.91)*100), 2)
A14: 2 | B14: 10 | C14: 1010 | D14: 0803734019 | E14: Region VIII (Eastern Visayas) | F14: Leyte | G14: Matalom | H14: President Garcia | I14: 10.249255 | J14: 124.81705 | K14: R | L14: 874 | M14: 3.8 | N14: =ROUND(L14/M14, 0) | O14: =ROUND(N14*'Methodology & Assumptions'!$B$5, 0) | P14: Single Carrier (Band n50, 100MHz TDD) | Q14: =ROUNDUP(O14/'Methodology & Assumptions'!$B$6, 0) | R14: 1 | S14: 12.87 | T14: 4.48 | U14: =IF(X14>='Methodology & Assumptions'!$B$7, "Tier 1 Critical GIDA (Score ≥ 50.0)", IF(X14>='Methodology & Assumptions'!$B$8, "Tier 2 High GIDA (Score 40.0–49.9)", "Tier 3 Moderate GIDA (Score < 40.0)")) | V14: =IF(S14<='Methodology & Assumptions'!$B$10, "Direct Optical Drop (<3km)", IF(S14<='Methodology & Assumptions'!$B$9, "Near Optical / Microwave (<5km)", "Starlink Business LEO Satellite Backhaul (>5km)")) | W14: 0.237 | X14: 51.19 | Y14: =ROUND(MIN(100, (X14/69.91)*100), 2)
A15: 2 | B15: 11 | C15: 1011 | D15: 1003515008 | E15: Region X (Northern Mindanao) | F15: Lanao del Norte | G15: Nunungan | H15: Kaludan | I15: 7.798369 | J15: 123.92412 | K15: R | L15: 1052 | M15: 4.2 | N15: =ROUND(L15/M15, 0) | O15: =ROUND(N15*'Methodology & Assumptions'!$B$5, 0) | P15: Single Carrier (Band n50, 100MHz TDD) | Q15: =ROUNDUP(O15/'Methodology & Assumptions'!$B$6, 0) | R15: 1 | S15: 30.48 | T15: 20.31 | U15: =IF(X15>='Methodology & Assumptions'!$B$7, "Tier 1 Critical GIDA (Score ≥ 50.0)", IF(X15>='Methodology & Assumptions'!$B$8, "Tier 2 High GIDA (Score 40.0–49.9)", "Tier 3 Moderate GIDA (Score < 40.0)")) | V15: =IF(S15<='Methodology & Assumptions'!$B$10, "Direct Optical Drop (<3km)", IF(S15<='Methodology & Assumptions'!$B$9, "Near Optical / Microwave (<5km)", "Starlink Business LEO Satellite Backhaul (>5km)")) | W15: 0.174 | X15: 51.19 | Y15: =ROUND(MIN(100, (X15/69.91)*100), 2)
A16: 2 | B16: 12 | C16: 1012 | D16: 1705320004 | E16: MIMAROPA Region | F16: Palawan | G16: Taytay | H16: Batas | I16: 11.152574 | J16: 119.60722 | K16: R | L16: 1440 | M16: 3.9 | N16: =ROUND(L16/M16, 0) | O16: =ROUND(N16*'Methodology & Assumptions'!$B$5, 0) | P16: Single Carrier (Band n50, 100MHz TDD) | Q16: =ROUNDUP(O16/'Methodology & Assumptions'!$B$6, 0) | R16: 1 | S16: 14.09 | T16: 38.26 | U16: =IF(X16>='Methodology & Assumptions'!$B$7, "Tier 1 Critical GIDA (Score ≥ 50.0)", IF(X16>='Methodology & Assumptions'!$B$8, "Tier 2 High GIDA (Score 40.0–49.9)", "Tier 3 Moderate GIDA (Score < 40.0)")) | V16: =IF(S16<='Methodology & Assumptions'!$B$10, "Direct Optical Drop (<3km)", IF(S16<='Methodology & Assumptions'!$B$9, "Near Optical / Microwave (<5km)", "Starlink Business LEO Satellite Backhaul (>5km)")) | W16: 0.15 | X16: 51.19 | Y16: =ROUND(MIN(100, (X16/69.91)*100), 2)
... A1004: 2 | B1004: 1000 | C1004: 2000 | D1004: 1380606009 | E1004: National Capital Region (NCR) | F1004: First District (Not a Province) | G1004: City of Manila | H1004: Barangay 403 | I1004: 12.767039 | J1004: 122.2953 | K1004: U | L1004: 649 | M1004: 3.9 | N1004: =ROUND(L1004/M1004, 0) | O1004: =ROUND(N1004*'Methodology & Assumptions'!$B$5, 0) | P1004: Single Carrier (Band n50, 100MHz TDD) | Q1004: =ROUNDUP(O1004/'Methodology & Assumptions'!$B$6, 0) | R1004: 1 | S1004: 66.22 | T1004: 75.4 | U1004: =IF(X1004>='Methodology & Assumptions'!$B$7, "Tier 1 Critical GIDA (Score ≥ 50.0)", IF(X1004>='Methodology & Assumptions'!$B$8, "Tier 2 High GIDA (Score 40.0–49.9)", "Tier 3 Moderate GIDA (Score < 40.0)")) | V1004: =IF(S1004<='Methodology & Assumptions'!$B$10, "Direct Optical Drop (<3km)", IF(S1004<='Methodology & Assumptions'!$B$9, "Near Optical / Microwave (<5km)", "Starlink Business LEO Satellite Backhaul (>5km)")) | W1004: 0.109 | X1004: 49.31 | Y1004: =ROUND(MIN(100, (X1004/69.91)*100), 2)
A1005: BATCH TOTAL / AVERAGE | L1005: =SUM(L5:L1004) | N1005: =SUM(N5:N1004) | O1005: =SUM(O5:O1004) | Q1005: =SUM(Q5:Q1004) | R1005: =SUM(R5:R1004) | S1005: =AVERAGE(S5:S1004) | X1005: =AVERAGE(X5:X1004) | Y1005: =AVERAGE(Y5:Y1004)

Sheet Batch 3 (2,001 - 3,000)
A1: 5G FWA GIDA Siting Rollout Schedule - Batch 3 (2,001 - 3,000)
A2: Dynamic GIDA deployment rollout schedule (1,000 sites), linked to live parameters in 'Methodology & Assumptions'.
A4: Batch | B4: Batch Rank | C4: Overall Rank | D4: PSGC | E4: Region | F4: Province | G4: Municipality | H4: Barangay | I4: Latitude | J4: Longitude | K4: U/R | L4: 2024 Population | M4: 2024 Avg HH Size | N4: 2024 Households | O4: Target Subs (30%) | P4: Carrier Spectrum | Q4: Peak BTS Required | R4: Day 1 BTS Deployed | S4: Dist to Node (km) | T4: Dist to Line (km) | U4: GIDA Priority Tier | V4: Backhaul Architecture | W4: Regional Poverty % | X4: Official GIDA Score | Y4: Normalized GIDA Score
A5: 3 | B5: 1 | C5: 2001 | D5: 1380607011 | E5: National Capital Region (NCR) | F5: First District (Not a Province) | G5: City of Manila | H5: Barangay 647 | I5: 12.618765 | J5: 121.31038 | K5: U | L5: 2514 | M5: 3.9 | N5: =ROUND(L5/M5, 0) | O5: =ROUND(N5*'Methodology & Assumptions'!$B$5, 0) | P5: Single Carrier (Band n50, 100MHz TDD) | Q5: =ROUNDUP(O5/'Methodology & Assumptions'!$B$6, 0) | R5: 1 | S5: 17.72 | T5: 16.61 | U5: =IF(X5>='Methodology & Assumptions'!$B$7, "Tier 1 Critical GIDA (Score ≥ 50.0)", IF(X5>='Methodology & Assumptions'!$B$8, "Tier 2 High GIDA (Score 40.0–49.9)", "Tier 3 Moderate GIDA (Score < 40.0)")) | V5: =IF(S5<='Methodology & Assumptions'!$B$10, "Direct Optical Drop (<3km)", IF(S5<='Methodology & Assumptions'!$B$9, "Near Optical / Microwave (<5km)", "Starlink Business LEO Satellite Backhaul (>5km)")) | W5: 0.109 | X5: 49.31 | Y5: =ROUND(MIN(100, (X5/69.91)*100), 2)
A6: 3 | B6: 2 | C6: 2002 | D6: 1380601081 | E6: National Capital Region (NCR) | F6: First District (Not a Province) | G6: City of Manila | H6: Barangay 81 | I6: 13.378703 | J6: 121.9354 | K6: U | L6: 1870 | M6: 3.9 | N6: =ROUND(L6/M6, 0) | O6: =ROUND(N6*'Methodology & Assumptions'!$B$5, 0) | P6: Single Carrier (Band n50, 100MHz TDD) | Q6: =ROUNDUP(O6/'Methodology & Assumptions'!$B$6, 0) | R6: 1 | S6: 43.38 | T6: 42.54 | U6: =IF(X6>='Methodology & Assumptions'!$B$7, "Tier 1 Critical GIDA (Score ≥ 50.0)", IF(X6>='Methodology & Assumptions'!$B$8, "Tier 2 High GIDA (Score 40.0–49.9)", "Tier 3 Moderate GIDA (Score < 40.0)")) | V6: =IF(S6<='Methodology & Assumptions'!$B$10, "Direct Optical Drop (<3km)", IF(S6<='Methodology & Assumptions'!$B$9, "Near Optical / Microwave (<5km)", "Starlink Business LEO Satellite Backhaul (>5km)")) | W6: 0.109 | X6: 49.31 | Y6: =ROUND(MIN(100, (X6/69.91)*100), 2)
A7: 3 | B7: 3 | C7: 2003 | D7: 0500507009 | E7: Region V (Bicol Region) | F7: Albay | G7: Libon | H7: Zone VI | I7: 13.248028 | J7: 123.39181 | K7: R | L7: 561 | M7: 4.1 | N7: =ROUND(L7/M7, 0) | O7: =ROUND(N7*'Methodology & Assumptions'!$B$5, 0) | P7: Single Carrier (Band n50, 100MHz TDD) | Q7: =ROUNDUP(O7/'Methodology & Assumptions'!$B$6, 0) | R7: 1 | S7: 7.16 | T7: 9.28 | U7: =IF(X7>='Methodology & Assumptions'!$B$7, "Tier 1 Critical GIDA (Score ≥ 50.0)", IF(X7>='Methodology & Assumptions'!$B$8, "Tier 2 High GIDA (Score 40.0–49.9)", "Tier 3 Moderate GIDA (Score < 40.0)")) | V7: =IF(S7<='Methodology & Assumptions'!$B$10, "Direct Optical Drop (<3km)", IF(S7<='Methodology & Assumptions'!$B$9, "Near Optical / Microwave (<5km)", "Starlink Business LEO Satellite Backhaul (>5km)")) | W7: 0.237 | X7: 49.3 | Y7: =ROUND(MIN(100, (X7/69.91)*100), 2)
A8: 3 | B8: 4 | C8: 2004 | D8: 1380612014 | E8: National Capital Region (NCR) | F8: First District (Not a Province) | G8: City of Manila | H8: Barangay 846 | I8: 12.40428 | J8: 122.00141 | K8: U | L8: 1904 | M8: 3.9 | N8: =ROUND(L8/M8, 0) | O8: =ROUND(N8*'Methodology & Assumptions'!$B$5, 0) | P8: Single Carrier (Band n50, 100MHz TDD) | Q8: =ROUNDUP(O8/'Methodology & Assumptions'!$B$6, 0) | R8: 1 | S8: 51.06 | T8: 29.15 | U8: =IF(X8>='Methodology & Assumptions'!$B$7, "Tier 1 Critical GIDA (Score ≥ 50.0)", IF(X8>='Methodology & Assumptions'!$B$8, "Tier 2 High GIDA (Score 40.0–49.9)", "Tier 3 Moderate GIDA (Score < 40.0)")) | V8: =IF(S8<='Methodology & Assumptions'!$B$10, "Direct Optical Drop (<3km)", IF(S8<='Methodology & Assumptions'!$B$9, "Near Optical / Microwave (<5km)", "Starlink Business LEO Satellite Backhaul (>5km)")) | W8: 0.109 | X8: 49.3 | Y8: =ROUND(MIN(100, (X8/69.91)*100), 2)
A9: 3 | B9: 5 | C9: 2005 | D9: 1380602003 | E9: National Capital Region (NCR) | F9: First District (Not a Province) | G9: City of Manila | H9: Barangay 289 | I9: 13.08096 | J9: 121.27558 | K9: U | L9: 1048 | M9: 3.9 | N9: =ROUND(L9/M9, 0) | O9: =ROUND(N9*'Methodology & Assumptions'!$B$5, 0) | P9: Single Carrier (Band n50, 100MHz TDD) | Q9: =ROUNDUP(O9/'Methodology & Assumptions'!$B$6, 0) | R9: 1 | S9: 9.63 | T9: 4.37 | U9: =IF(X9>='Methodology & Assumptions'!$B$7, "Tier 1 Critical GIDA (Score ≥ 50.0)", IF(X9>='Methodology & Assumptions'!$B$8, "Tier 2 High GIDA (Score 40.0–49.9)", "Tier 3 Moderate GIDA (Score < 40.0)")) | V9: =IF(S9<='Methodology & Assumptions'!$B$10, "Direct Optical Drop (<3km)", IF(S9<='Methodology & Assumptions'!$B$9, "Near Optical / Microwave (<5km)", "Starlink Business LEO Satellite Backhaul (>5km)")) | W9: 0.109 | X9: 49.3 | Y9: =ROUND(MIN(100, (X9/69.91)*100), 2)
A10: 3 | B10: 6 | C10: 2006 | D10: 1380611031 | E10: National Capital Region (NCR) | F10: First District (Not a Province) | G10: City of Manila | H10: Barangay 817 | I10: 13.060036 | J10: 122.28226 | K10: U | L10: 1768 | M10: 3.9 | N10: =ROUND(L10/M10, 0) | O10: =ROUND(N10*'Methodology & Assumptions'!$B$5, 0) | P10: Single Carrier (Band n50, 100MHz TDD) | Q10: =ROUNDUP(O10/'Methodology & Assumptions'!$B$6, 0) | R10: 1 | S10: 40.84 | T10: 53.35 | U10: =IF(X10>='Methodology & Assumptions'!$B$7, "Tier 1 Critical GIDA (Score ≥ 50.0)", IF(X10>='Methodology & Assumptions'!$B$8, "Tier 2 High GIDA (Score 40.0–49.9)", "Tier 3 Moderate GIDA (Score < 40.0)")) | V10: =IF(S10<='Methodology & Assumptions'!$B$10, "Direct Optical Drop (<3km)", IF(S10<='Methodology & Assumptions'!$B$9, "Near Optical / Microwave (<5km)", "Starlink Business LEO Satellite Backhaul (>5km)")) | W10: 0.109 | X10: 49.3 | Y10: =ROUND(MIN(100, (X10/69.91)*100), 2)
A11: 3 | B11: 7 | C11: 2007 | D11: PH0002007 | E11: IV-A | F11: Cavite | G11: Imus City | H11: Poblacion II-A (Pob.) | I11: 14.298537 | J11: 120.89533 | K11: R | L11: 2316 | M11: 3.4 | N11: =ROUND(L11/M11, 0) | O11: =ROUND(N11*'Methodology & Assumptions'!$B$5, 0) | P11: Single Carrier (Band n50, 100MHz TDD) | Q11: =ROUNDUP(O11/'Methodology & Assumptions'!$B$6, 0) | R11: 1 | S11: 1.65 | T11: 1.17 | U11: =IF(X11>='Methodology & Assumptions'!$B$7, "Tier 1 Critical GIDA (Score ≥ 50.0)", IF(X11>='Methodology & Assumptions'!$B$8, "Tier 2 High GIDA (Score 40.0–49.9)", "Tier 3 Moderate GIDA (Score < 40.0)")) | V11: =IF(S11<='Methodology & Assumptions'!$B$10, "Direct Optical Drop (<3km)", IF(S11<='Methodology & Assumptions'!$B$9, "Near Optical / Microwave (<5km)", "Starlink Business LEO Satellite Backhaul (>5km)")) | W11: 0.072 | X11: 49.3 | Y11: =ROUND(MIN(100, (X11/69.91)*100), 2)
A12: 3 | B12: 8 | C12: 2008 | D12: 1380606067 | E12: National Capital Region (NCR) | F12: First District (Not a Province) | G12: City of Manila | H12: Barangay 461 | I12: 12.410811 | J12: 121.52361 | K12: U | L12: 889 | M12: 3.9 | N12: =ROUND(L12/M12, 0) | O12: =ROUND(N12*'Methodology & Assumptions'!$B$5, 0) | P12: Single Carrier (Band n50, 100MHz TDD) | Q12: =ROUNDUP(O12/'Methodology & Assumptions'!$B$6, 0) | R12: 1 | S12: 15.28 | T12: 12.23 | U12: =IF(X12>='Methodology & Assumptions'!$B$7, "Tier 1 Critical GIDA (Score ≥ 50.0)", IF(X12>='Methodology & Assumptions'!$B$8, "Tier 2 High GIDA (Score 40.0–49.9)", "Tier 3 Moderate GIDA (Score < 40.0)")) | V12: =IF(S12<='Methodology & Assumptions'!$B$10, "Direct Optical Drop (<3km)", IF(S12<='Methodology & Assumptions'!$B$9, "Near Optical / Microwave (<5km)", "Starlink Business LEO Satellite Backhaul (>5km)")) | W12: 0.109 | X12: 49.3 | Y12: =ROUND(MIN(100, (X12/69.91)*100), 2)
A13: 3 | B13: 9 | C13: 2009 | D13: PH0002009 | E13: NCR | F13: Metro Manila | G13: Caloocan City | H13: Barangay 84 | I13: 13.168217 | J13: 123.10901 | K13: R | L13: 2279 | M13: 3.8 | N13: =ROUND(L13/M13, 0) | O13: =ROUND(N13*'Methodology & Assumptions'!$B$5, 0) | P13: Single Carrier (Band n50, 100MHz TDD) | Q13: =ROUNDUP(O13/'Methodology & Assumptions'!$B$6, 0) | R13: 1 | S13: 20.75 | T13: 34.57 | U13: =IF(X13>='Methodology & Assumptions'!$B$7, "Tier 1 Critical GIDA (Score ≥ 50.0)", IF(X13>='Methodology & Assumptions'!$B$8, "Tier 2 High GIDA (Score 40.0–49.9)", "Tier 3 Moderate GIDA (Score < 40.0)")) | V13: =IF(S13<='Methodology & Assumptions'!$B$10, "Direct Optical Drop (<3km)", IF(S13<='Methodology & Assumptions'!$B$9, "Near Optical / Microwave (<5km)", "Starlink Business LEO Satellite Backhaul (>5km)")) | W13: 0.011 | X13: 49.29 | Y13: =ROUND(MIN(100, (X13/69.91)*100), 2)
A14: 3 | B14: 10 | C14: 2010 | D14: 1380606038 | E14: National Capital Region (NCR) | F14: First District (Not a Province) | G14: City of Manila | H14: Barangay 432 | I14: 13.391609 | J14: 121.63329 | K14: U | L14: 3540 | M14: 3.9 | N14: =ROUND(L14/M14, 0) | O14: =ROUND(N14*'Methodology & Assumptions'!$B$5, 0) | P14: Single Carrier (Band n50, 100MHz TDD) | Q14: =ROUNDUP(O14/'Methodology & Assumptions'!$B$6, 0) | R14: 1 | S14: 36.68 | T14: 42.33 | U14: =IF(X14>='Methodology & Assumptions'!$B$7, "Tier 1 Critical GIDA (Score ≥ 50.0)", IF(X14>='Methodology & Assumptions'!$B$8, "Tier 2 High GIDA (Score 40.0–49.9)", "Tier 3 Moderate GIDA (Score < 40.0)")) | V14: =IF(S14<='Methodology & Assumptions'!$B$10, "Direct Optical Drop (<3km)", IF(S14<='Methodology & Assumptions'!$B$9, "Near Optical / Microwave (<5km)", "Starlink Business LEO Satellite Backhaul (>5km)")) | W14: 0.109 | X14: 49.29 | Y14: =ROUND(MIN(100, (X14/69.91)*100), 2)
A15: 3 | B15: 11 | C15: 2011 | D15: 0501602018 | E15: Region V (Bicol Region) | F15: Camarines Norte | G15: Capalonga | H15: San Roque | I15: 14.329171 | J15: 122.5521 | K15: R | L15: 1011 | M15: 4 | N15: =ROUND(L15/M15, 0) | O15: =ROUND(N15*'Methodology & Assumptions'!$B$5, 0) | P15: Single Carrier (Band n50, 100MHz TDD) | Q15: =ROUNDUP(O15/'Methodology & Assumptions'!$B$6, 0) | R15: 1 | S15: 11.19 | T15: 16.18 | U15: =IF(X15>='Methodology & Assumptions'!$B$7, "Tier 1 Critical GIDA (Score ≥ 50.0)", IF(X15>='Methodology & Assumptions'!$B$8, "Tier 2 High GIDA (Score 40.0–49.9)", "Tier 3 Moderate GIDA (Score < 40.0)")) | V15: =IF(S15<='Methodology & Assumptions'!$B$10, "Direct Optical Drop (<3km)", IF(S15<='Methodology & Assumptions'!$B$9, "Near Optical / Microwave (<5km)", "Starlink Business LEO Satellite Backhaul (>5km)")) | W15: 0.237 | X15: 49.29 | Y15: =ROUND(MIN(100, (X15/69.91)*100), 2)
A16: 3 | B16: 12 | C16: 2012 | D16: 1380601166 | E16: National Capital Region (NCR) | F16: First District (Not a Province) | G16: City of Manila | H16: Barangay 166 | I16: 12.594224 | J16: 122.23367 | K16: U | L16: 909 | M16: 3.9 | N16: =ROUND(L16/M16, 0) | O16: =ROUND(N16*'Methodology & Assumptions'!$B$5, 0) | P16: Single Carrier (Band n50, 100MHz TDD) | Q16: =ROUNDUP(O16/'Methodology & Assumptions'!$B$6, 0) | R16: 1 | S16: 74.01 | T16: 59.03 | U16: =IF(X16>='Methodology & Assumptions'!$B$7, "Tier 1 Critical GIDA (Score ≥ 50.0)", IF(X16>='Methodology & Assumptions'!$B$8, "Tier 2 High GIDA (Score 40.0–49.9)", "Tier 3 Moderate GIDA (Score < 40.0)")) | V16: =IF(S16<='Methodology & Assumptions'!$B$10, "Direct Optical Drop (<3km)", IF(S16<='Methodology & Assumptions'!$B$9, "Near Optical / Microwave (<5km)", "Starlink Business LEO Satellite Backhaul (>5km)")) | W16: 0.109 | X16: 49.29 | Y16: =ROUND(MIN(100, (X16/69.91)*100), 2)
... A1004: 3 | B1004: 1000 | C1004: 3000 | D1004: 1380606117 | E1004: National Capital Region (NCR) | F1004: First District (Not a Province) | G1004: City of Manila | H1004: Barangay 511 | I1004: 13.689629 | J1004: 122.60483 | K1004: U | L1004: 1379 | M1004: 3.9 | N1004: =ROUND(L1004/M1004, 0) | O1004: =ROUND(N1004*'Methodology & Assumptions'!$B$5, 0) | P1004: Single Carrier (Band n50, 100MHz TDD) | Q1004: =ROUNDUP(O1004/'Methodology & Assumptions'!$B$6, 0) | R1004: 1 | S1004: 12.03 | T1004: 11.67 | U1004: =IF(X1004>='Methodology & Assumptions'!$B$7, "Tier 1 Critical GIDA (Score ≥ 50.0)", IF(X1004>='Methodology & Assumptions'!$B$8, "Tier 2 High GIDA (Score 40.0–49.9)", "Tier 3 Moderate GIDA (Score < 40.0)")) | V1004: =IF(S1004<='Methodology & Assumptions'!$B$10, "Direct Optical Drop (<3km)", IF(S1004<='Methodology & Assumptions'!$B$9, "Near Optical / Microwave (<5km)", "Starlink Business LEO Satellite Backhaul (>5km)")) | W1004: 0.109 | X1004: 48.05 | Y1004: =ROUND(MIN(100, (X1004/69.91)*100), 2)
A1005: BATCH TOTAL / AVERAGE | L1005: =SUM(L5:L1004) | N1005: =SUM(N5:N1004) | O1005: =SUM(O5:O1004) | Q1005: =SUM(Q5:Q1004) | R1005: =SUM(R5:R1004) | S1005: =AVERAGE(S5:S1004) | X1005: =AVERAGE(X5:X1004) | Y1005: =AVERAGE(Y5:Y1004)

Sheet Batch 4 & 5 (3,001 - 5,000)
A1: 5G FWA GIDA Siting Rollout Schedule - Batch 4 & 5 (3,001 - 5,000)
A2: Dynamic GIDA deployment rollout schedule (2,000 sites), linked to live parameters in 'Methodology & Assumptions'.
A4: Batch | B4: Batch Rank | C4: Overall Rank | D4: PSGC | E4: Region | F4: Province | G4: Municipality | H4: Barangay | I4: Latitude | J4: Longitude | K4: U/R | L4: 2024 Population | M4: 2024 Avg HH Size | N4: 2024 Households | O4: Target Subs (30%) | P4: Carrier Spectrum | Q4: Peak BTS Required | R4: Day 1 BTS Deployed | S4: Dist to Node (km) | T4: Dist to Line (km) | U4: GIDA Priority Tier | V4: Backhaul Architecture | W4: Regional Poverty % | X4: Official GIDA Score | Y4: Normalized GIDA Score
A5: 4 | B5: 1 | C5: 3001 | D5: PH0003001 | E5: CAR | F5: Benguet | G5: Baguio City | H5: Andres Bonifacio | I5: 16.414443 | J5: 120.55894 | K5: R | L5: 2260 | M5: 3.5 | N5: =ROUND(L5/M5, 0) | O5: =ROUND(N5*'Methodology & Assumptions'!$B$5, 0) | P5: Single Carrier (Band n50, 100MHz TDD) | Q5: =ROUNDUP(O5/'Methodology & Assumptions'!$B$6, 0) | R5: 1 | S5: 0.91 | T5: 0.31 | U5: =IF(X5>='Methodology & Assumptions'!$B$7, "Tier 1 Critical GIDA (Score ≥ 50.0)", IF(X5>='Methodology & Assumptions'!$B$8, "Tier 2 High GIDA (Score 40.0–49.9)", "Tier 3 Moderate GIDA (Score < 40.0)")) | V5: =IF(S5<='Methodology & Assumptions'!$B$10, "Direct Optical Drop (<3km)", IF(S5<='Methodology & Assumptions'!$B$9, "Near Optical / Microwave (<5km)", "Starlink Business LEO Satellite Backhaul (>5km)")) | W5: 0.221 | X5: 48.05 | Y5: =ROUND(MIN(100, (X5/69.91)*100), 2)
A6: 4 | B6: 2 | C6: 3002 | D6: 1380614019 | E6: National Capital Region (NCR) | F6: First District (Not a Province) | G6: City of Manila | H6: Barangay 763 | I6: 11.734029 | J6: 121.72269 | K6: U | L6: 1833 | M6: 3.9 | N6: =ROUND(L6/M6, 0) | O6: =ROUND(N6*'Methodology & Assumptions'!$B$5, 0) | P6: Single Carrier (Band n50, 100MHz TDD) | Q6: =ROUNDUP(O6/'Methodology & Assumptions'!$B$6, 0) | R6: 1 | S6: 34.02 | T6: 32.4 | U6: =IF(X6>='Methodology & Assumptions'!$B$7, "Tier 1 Critical GIDA (Score ≥ 50.0)", IF(X6>='Methodology & Assumptions'!$B$8, "Tier 2 High GIDA (Score 40.0–49.9)", "Tier 3 Moderate GIDA (Score < 40.0)")) | V6: =IF(S6<='Methodology & Assumptions'!$B$10, "Direct Optical Drop (<3km)", IF(S6<='Methodology & Assumptions'!$B$9, "Near Optical / Microwave (<5km)", "Starlink Business LEO Satellite Backhaul (>5km)")) | W6: 0.109 | X6: 48.05 | Y6: =ROUND(MIN(100, (X6/69.91)*100), 2)
A7: 4 | B7: 3 | C7: 3003 | D7: 1380606050 | E7: National Capital Region (NCR) | F7: First District (Not a Province) | G7: City of Manila | H7: Barangay 444 | I7: 13.759205 | J7: 121.01696 | K7: U | L7: 970 | M7: 3.9 | N7: =ROUND(L7/M7, 0) | O7: =ROUND(N7*'Methodology & Assumptions'!$B$5, 0) | P7: Single Carrier (Band n50, 100MHz TDD) | Q7: =ROUNDUP(O7/'Methodology & Assumptions'!$B$6, 0) | R7: 1 | S7: 3.03 | T7: 2.96 | U7: =IF(X7>='Methodology & Assumptions'!$B$7, "Tier 1 Critical GIDA (Score ≥ 50.0)", IF(X7>='Methodology & Assumptions'!$B$8, "Tier 2 High GIDA (Score 40.0–49.9)", "Tier 3 Moderate GIDA (Score < 40.0)")) | V7: =IF(S7<='Methodology & Assumptions'!$B$10, "Direct Optical Drop (<3km)", IF(S7<='Methodology & Assumptions'!$B$9, "Near Optical / Microwave (<5km)", "Starlink Business LEO Satellite Backhaul (>5km)")) | W7: 0.109 | X7: 48.05 | Y7: =ROUND(MIN(100, (X7/69.91)*100), 2)
A8: 4 | B8: 4 | C8: 3004 | D8: 1380606226 | E8: National Capital Region (NCR) | F8: First District (Not a Province) | G8: City of Manila | H8: Barangay 619 | I8: 12.729665 | J8: 122.94304 | K8: U | L8: 1322 | M8: 3.9 | N8: =ROUND(L8/M8, 0) | O8: =ROUND(N8*'Methodology & Assumptions'!$B$5, 0) | P8: Single Carrier (Band n50, 100MHz TDD) | Q8: =ROUNDUP(O8/'Methodology & Assumptions'!$B$6, 0) | R8: 1 | S8: 54.52 | T8: 58.44 | U8: =IF(X8>='Methodology & Assumptions'!$B$7, "Tier 1 Critical GIDA (Score ≥ 50.0)", IF(X8>='Methodology & Assumptions'!$B$8, "Tier 2 High GIDA (Score 40.0–49.9)", "Tier 3 Moderate GIDA (Score < 40.0)")) | V8: =IF(S8<='Methodology & Assumptions'!$B$10, "Direct Optical Drop (<3km)", IF(S8<='Methodology & Assumptions'!$B$9, "Near Optical / Microwave (<5km)", "Starlink Business LEO Satellite Backhaul (>5km)")) | W8: 0.109 | X8: 48.05 | Y8: =ROUND(MIN(100, (X8/69.91)*100), 2)
A9: 4 | B9: 5 | C9: 3005 | D9: 1380606135 | E9: National Capital Region (NCR) | F9: First District (Not a Province) | G9: City of Manila | H9: Barangay 529 | I9: 12.219622 | J9: 120.80698 | K9: U | L9: 963 | M9: 3.9 | N9: =ROUND(L9/M9, 0) | O9: =ROUND(N9*'Methodology & Assumptions'!$B$5, 0) | P9: Single Carrier (Band n50, 100MHz TDD) | Q9: =ROUNDUP(O9/'Methodology & Assumptions'!$B$6, 0) | R9: 1 | S9: 31.56 | T9: 31.41 | U9: =IF(X9>='Methodology & Assumptions'!$B$7, "Tier 1 Critical GIDA (Score ≥ 50.0)", IF(X9>='Methodology & Assumptions'!$B$8, "Tier 2 High GIDA (Score 40.0–49.9)", "Tier 3 Moderate GIDA (Score < 40.0)")) | V9: =IF(S9<='Methodology & Assumptions'!$B$10, "Direct Optical Drop (<3km)", IF(S9<='Methodology & Assumptions'!$B$9, "Near Optical / Microwave (<5km)", "Starlink Business LEO Satellite Backhaul (>5km)")) | W9: 0.109 | X9: 48.04 | Y9: =ROUND(MIN(100, (X9/69.91)*100), 2)
A10: 4 | B10: 6 | C10: 3006 | D10: PH0003006 | E10: CAR | F10: Benguet | G10: Baguio City | H10: Rizal Monument Area | I10: 16.42494 | J10: 120.62669 | K10: R | L10: 2260 | M10: 3.5 | N10: =ROUND(L10/M10, 0) | O10: =ROUND(N10*'Methodology & Assumptions'!$B$5, 0) | P10: Single Carrier (Band n50, 100MHz TDD) | Q10: =ROUNDUP(O10/'Methodology & Assumptions'!$B$6, 0) | R10: 1 | S10: 1.25 | T10: 0.45 | U10: =IF(X10>='Methodology & Assumptions'!$B$7, "Tier 1 Critical GIDA (Score ≥ 50.0)", IF(X10>='Methodology & Assumptions'!$B$8, "Tier 2 High GIDA (Score 40.0–49.9)", "Tier 3 Moderate GIDA (Score < 40.0)")) | V10: =IF(S10<='Methodology & Assumptions'!$B$10, "Direct Optical Drop (<3km)", IF(S10<='Methodology & Assumptions'!$B$9, "Near Optical / Microwave (<5km)", "Starlink Business LEO Satellite Backhaul (>5km)")) | W10: 0.221 | X10: 48.04 | Y10: =ROUND(MIN(100, (X10/69.91)*100), 2)
A11: 4 | B11: 7 | C11: 3007 | D11: 1903601013 | E11: Bangsamoro Autonomous Region In Muslim Mindanao (BARMM) | F11: Lanao del Sur | G11: Bacolod-Kalawi | H11: Ilian | I11: 17.254715 | J11: 122.22876 | K11: R | L11: 1174 | M11: 5.7 | N11: =ROUND(L11/M11, 0) | O11: =ROUND(N11*'Methodology & Assumptions'!$B$5, 0) | P11: Single Carrier (Band n50, 100MHz TDD) | Q11: =ROUNDUP(O11/'Methodology & Assumptions'!$B$6, 0) | R11: 1 | S11: 29.4 | T11: 34.28 | U11: =IF(X11>='Methodology & Assumptions'!$B$7, "Tier 1 Critical GIDA (Score ≥ 50.0)", IF(X11>='Methodology & Assumptions'!$B$8, "Tier 2 High GIDA (Score 40.0–49.9)", "Tier 3 Moderate GIDA (Score < 40.0)")) | V11: =IF(S11<='Methodology & Assumptions'!$B$10, "Direct Optical Drop (<3km)", IF(S11<='Methodology & Assumptions'!$B$9, "Near Optical / Microwave (<5km)", "Starlink Business LEO Satellite Backhaul (>5km)")) | W11: 0.11 | X11: 48.04 | Y11: =ROUND(MIN(100, (X11/69.91)*100), 2)
A12: 4 | B12: 8 | C12: 3008 | D12: 0102934020 | E12: Region I (Ilocos Region) | F12: Ilocos Sur | G12: City of Vigan | H12: Mindoro | I12: 17.559861 | J12: 120.35176 | K12: R | L12: 1575 | M12: 3.8 | N12: =ROUND(L12/M12, 0) | O12: =ROUND(N12*'Methodology & Assumptions'!$B$5, 0) | P12: Single Carrier (Band n50, 100MHz TDD) | Q12: =ROUNDUP(O12/'Methodology & Assumptions'!$B$6, 0) | R12: 1 | S12: 5.55 | T12: 4.8 | U12: =IF(X12>='Methodology & Assumptions'!$B$7, "Tier 1 Critical GIDA (Score ≥ 50.0)", IF(X12>='Methodology & Assumptions'!$B$8, "Tier 2 High GIDA (Score 40.0–49.9)", "Tier 3 Moderate GIDA (Score < 40.0)")) | V12: =IF(S12<='Methodology & Assumptions'!$B$10, "Direct Optical Drop (<3km)", IF(S12<='Methodology & Assumptions'!$B$9, "Near Optical / Microwave (<5km)", "Starlink Business LEO Satellite Backhaul (>5km)")) | W12: 0.083 | X12: 48.04 | Y12: =ROUND(MIN(100, (X12/69.91)*100), 2)
A13: 4 | B13: 9 | C13: 3009 | D13: 1380614089 | E13: National Capital Region (NCR) | F13: First District (Not a Province) | G13: City of Manila | H13: Barangay 896 | I13: 14.00455 | J13: 122.02981 | K13: U | L13: 1303 | M13: 3.9 | N13: =ROUND(L13/M13, 0) | O13: =ROUND(N13*'Methodology & Assumptions'!$B$5, 0) | P13: Single Carrier (Band n50, 100MHz TDD) | Q13: =ROUNDUP(O13/'Methodology & Assumptions'!$B$6, 0) | R13: 1 | S13: 5.48 | T13: 5.11 | U13: =IF(X13>='Methodology & Assumptions'!$B$7, "Tier 1 Critical GIDA (Score ≥ 50.0)", IF(X13>='Methodology & Assumptions'!$B$8, "Tier 2 High GIDA (Score 40.0–49.9)", "Tier 3 Moderate GIDA (Score < 40.0)")) | V13: =IF(S13<='Methodology & Assumptions'!$B$10, "Direct Optical Drop (<3km)", IF(S13<='Methodology & Assumptions'!$B$9, "Near Optical / Microwave (<5km)", "Starlink Business LEO Satellite Backhaul (>5km)")) | W13: 0.109 | X13: 48.04 | Y13: =ROUND(MIN(100, (X13/69.91)*100), 2)
A14: 4 | B14: 10 | C14: 3010 | D14: 1380601238 | E14: National Capital Region (NCR) | F14: First District (Not a Province) | G14: City of Manila | H14: Barangay 237 | I14: 11.880731 | J14: 122.36564 | K14: U | L14: 466 | M14: 3.9 | N14: =ROUND(L14/M14, 0) | O14: =ROUND(N14*'Methodology & Assumptions'!$B$5, 0) | P14: Single Carrier (Band n50, 100MHz TDD) | Q14: =ROUNDUP(O14/'Methodology & Assumptions'!$B$6, 0) | R14: 1 | S14: 19.93 | T14: 7.95 | U14: =IF(X14>='Methodology & Assumptions'!$B$7, "Tier 1 Critical GIDA (Score ≥ 50.0)", IF(X14>='Methodology & Assumptions'!$B$8, "Tier 2 High GIDA (Score 40.0–49.9)", "Tier 3 Moderate GIDA (Score < 40.0)")) | V14: =IF(S14<='Methodology & Assumptions'!$B$10, "Direct Optical Drop (<3km)", IF(S14<='Methodology & Assumptions'!$B$9, "Near Optical / Microwave (<5km)", "Starlink Business LEO Satellite Backhaul (>5km)")) | W14: 0.109 | X14: 48.04 | Y14: =ROUND(MIN(100, (X14/69.91)*100), 2)
A15: 4 | B15: 11 | C15: 3011 | D15: 1380606120 | E15: National Capital Region (NCR) | F15: First District (Not a Province) | G15: City of Manila | H15: Barangay 514 | I15: 13.226973 | J15: 120.64416 | K15: U | L15: 2352 | M15: 3.9 | N15: =ROUND(L15/M15, 0) | O15: =ROUND(N15*'Methodology & Assumptions'!$B$5, 0) | P15: Single Carrier (Band n50, 100MHz TDD) | Q15: =ROUNDUP(O15/'Methodology & Assumptions'!$B$6, 0) | R15: 1 | S15: 41.74 | T15: 40.33 | U15: =IF(X15>='Methodology & Assumptions'!$B$7, "Tier 1 Critical GIDA (Score ≥ 50.0)", IF(X15>='Methodology & Assumptions'!$B$8, "Tier 2 High GIDA (Score 40.0–49.9)", "Tier 3 Moderate GIDA (Score < 40.0)")) | V15: =IF(S15<='Methodology & Assumptions'!$B$10, "Direct Optical Drop (<3km)", IF(S15<='Methodology & Assumptions'!$B$9, "Near Optical / Microwave (<5km)", "Starlink Business LEO Satellite Backhaul (>5km)")) | W15: 0.109 | X15: 48.04 | Y15: =ROUND(MIN(100, (X15/69.91)*100), 2)
A16: 4 | B16: 12 | C16: 3012 | D16: 1903601014 | E16: Bangsamoro Autonomous Region In Muslim Mindanao (BARMM) | F16: Lanao del Sur | G16: Bacolod-Kalawi | H16: Lama | I16: 17.251068 | J16: 122.23226 | K16: U | L16: 917 | M16: 5.7 | N16: =ROUND(L16/M16, 0) | O16: =ROUND(N16*'Methodology & Assumptions'!$B$5, 0) | P16: Single Carrier (Band n50, 100MHz TDD) | Q16: =ROUNDUP(O16/'Methodology & Assumptions'!$B$6, 0) | R16: 1 | S16: 29.43 | T16: 34.52 | U16: =IF(X16>='Methodology & Assumptions'!$B$7, "Tier 1 Critical GIDA (Score ≥ 50.0)", IF(X16>='Methodology & Assumptions'!$B$8, "Tier 2 High GIDA (Score 40.0–49.9)", "Tier 3 Moderate GIDA (Score < 40.0)")) | V16: =IF(S16<='Methodology & Assumptions'!$B$10, "Direct Optical Drop (<3km)", IF(S16<='Methodology & Assumptions'!$B$9, "Near Optical / Microwave (<5km)", "Starlink Business LEO Satellite Backhaul (>5km)")) | W16: 0.11 | X16: 48.04 | Y16: =ROUND(MIN(100, (X16/69.91)*100), 2)
... A2004: 5 | B2004: 1000 | C2004: 5000 | D2004: PH0005000 | E2004: IV-A | F2004: Cavite | G2004: Cavite City | H2004: Barangay 42-C | I2004: 14.445268 | J2004: 120.95802 | K2004: R | L2004: 2316 | M2004: 3.4 | N2004: =ROUND(L2004/M2004, 0) | O2004: =ROUND(N2004*'Methodology & Assumptions'!$B$5, 0) | P2004: Single Carrier (Band n50, 100MHz TDD) | Q2004: =ROUNDUP(O2004/'Methodology & Assumptions'!$B$6, 0) | R2004: 1 | S2004: 1.03 | T2004: 0.53 | U2004: =IF(X2004>='Methodology & Assumptions'!$B$7, "Tier 1 Critical GIDA (Score ≥ 50.0)", IF(X2004>='Methodology & Assumptions'!$B$8, "Tier 2 High GIDA (Score 40.0–49.9)", "Tier 3 Moderate GIDA (Score < 40.0)")) | V2004: =IF(S2004<='Methodology & Assumptions'!$B$10, "Direct Optical Drop (<3km)", IF(S2004<='Methodology & Assumptions'!$B$9, "Near Optical / Microwave (<5km)", "Starlink Business LEO Satellite Backhaul (>5km)")) | W2004: 0.072 | X2004: 41.24 | Y2004: =ROUND(MIN(100, (X2004/69.91)*100), 2)
A2005: BATCH TOTAL / AVERAGE | L2005: =SUM(L5:L2004) | N2005: =SUM(N5:N2004) | O2005: =SUM(O5:O2004) | Q2005: =SUM(Q5:Q2004) | R2005: =SUM(R5:R2004) | S2005: =AVERAGE(S5:S2004) | X2005: =AVERAGE(X5:X2004) | Y2005: =AVERAGE(Y5:Y2004)

Sheet Provincial Summary
A1: 5G FWA GIDA Siting — Provincial Distribution & Cluster Analysis
A2: Batch Allocation & Infrastructure Allocation across Philippine Provinces
